,ts_recv,ts_event,rtype,publisher_id,instrument_id,action,side,depth,price,size,flags,ts_in_delta,sequence,bid_px_00,bid_sz_00,bid_ct_00,ask_px_00,ask_sz_00,ask_ct_00,bid_px_01,bid_sz_01,bid_ct_01,ask_px_01,ask_sz_01,ask_ct_01,bid_px_02,bid_sz_02,bid_ct_02,ask_px_02,ask_sz_02,ask_ct_02,bid_px_03,bid_sz_03,bid_ct_03,ask_px_03,ask_sz_03,ask_ct_03,bid_px_04,bid_sz_04,bid_ct_04,ask_px_04,ask_sz_04,ask_ct_04,bid_px_05,bid_sz_05,bid_ct_05,ask_px_05,ask_sz_05,ask_ct_05,bid_px_06,bid_sz_06,bid_ct_06,ask_px_06,ask_sz_06,ask_ct_06,bid_px_07,bid_sz_07,bid_ct_07,ask_px_07,ask_sz_07,ask_ct_07,bid_px_08,bid_sz_08,bid_ct_08,ask_px_08,ask_sz_08,ask_ct_08,bid_px_09,bid_sz_09,bid_ct_09,ask_px_09,ask_sz_09,ask_ct_09,symbol,order_id
2252,2025-07-17T16:41:43.139245098Z,2025-07-17T16:41:43.139245098Z,10,2,1108,A,A,8,14.4,700,130,165571,311182882,13.11,100,1,13.64,2,1,12.98,200,2,13.71,100,1,12.91,2,1,13.97,100,1,12.86,100,1,14.04,100,1,12.73,100,1,14.23,100,1,12.71,100,1,14.24,100,1,12.5,700,1,14.35,200,2,12.46,100,1,14.39,200,2,12.43,700,1,14.4,700,1,12.42,700,1,14.48,1500,3,ARL,375327817
2253,2025-07-17T16:41:43.139668821Z,2025-07-17T16:41:43.139668821Z,10,2,1108,C,A,3,14.04,100,130,165374,311182892,13.11,100,1,13.64,2,1,12.98,200,2,13.71,100,1,12.91,2,1,13.97,100,1,12.86,100,1,14.23,100,1,12.73,100,1,14.24,100,1,12.71,100,1,14.35,200,2,12.5,700,1,14.39,200,2,12.46,100,1,14.4,700,1,12.43,700,1,14.48,1500,3,12.42,700,1,14.54,700,1,ARL,370638761
2254,2025-07-17T16:41:43.139683114Z,2025-07-17T16:41:43.139683114Z,10,2,1108,C,A,8,14.48,100,0,165596,311182893,13.11,100,1,13.64,2,1,12.98,200,2,13.71,100,1,12.91,2,1,13.97,100,1,12.86,100,1,14.23,100,1,12.73,100,1,14.24,100,1,12.71,100,1,14.35,200,2,12.5,700,1,14.39,200,2,12.46,100,1,14.4,700,1,12.43,700,1,14.48,1400,2,12.42,700,1,14.54,700,1,ARL,370638757
2255,2025-07-17T16:41:43.139683114Z,2025-07-17T16:41:43.139683114Z,10,2,1108,A,A,9,14.54,100,130,165596,311182893,13.11,100,1,13.64,2,1,12.98,200,2,13.71,100,1,12.91,2,1,13.97,100,1,12.86,100,1,14.23,100,1,12.73,100,1,14.24,100,1,12.71,100,1,14.35,200,2,12.5,700,1,14.39,200,2,12.46,100,1,14.4,700,1,12.43,700,1,14.48,1400,2,12.42,700,1,14.54,800,2,ARL,375327841
2256,2025-07-17T16:41:43.139975016Z,2025-07-17T16:41:43.139975016Z,10,2,1108,C,A,6,14.39,100,0,165604,311182897,13.11,100,1,13.64,2,1,12.98,200,2,13.71,100,1,12.91,2,1,13.97,100,1,12.86,100,1,14.23,100,1,12.73,100,1,14.24,100,1,12.71,100,1,14.35,200,2,12.5,700,1,14.39,100,1,12.46,100,1,14.4,700,1,12.43,700,1,14.48,1400,2,12.42,700,1,14.54,800,2,ARL,370638765
2257,2025-07-17T16:41:43.140025431Z,2025-07-17T16:41:43.140025431Z,10,2,1108,A,A,5,14.32,100,130,165422,311182898,13.11,100,1,13.64,2,1,12.98,200,2,13.71,100,1,12.91,2,1,13.97,100,1,12.86,100,1,14.23,100,1,12.73,100,1,14.24,100,1,12.71,100,1,14.32,100,1,12.5,700,1,14.35,200,2,12.46,100,1,14.39,100,1,12.43,700,1,14.4,700,1,12.42,700,1,14.48,1400,2,ARL,375327857
2258,2025-07-17T16:41:43.143238309Z,2025-07-17T16:41:43.143238309Z,10,2,1108,C,A,7,14.39,100,0,165712,311182938,13.11,100,1,13.64,2,1,12.98,200,2,13.71,100,1,12.91,2,1,13.97,100,1,12.86,100,1,14.23,100,1,12.73,100,1,14.24,100,1,12.71,100,1,14.32,100,1,12.5,700,1,14.35,200,2,12.46,100,1,14.4,700,1,12.43,700,1,14.48,1400,2,12.42,700,1,14.54,800,2,ARL,370638997
2259,2025-07-17T16:41:43.144477498Z,2025-07-17T16:41:43.144477498Z,10,2,1108,C,A,3,14.23,100,0,165721,311182962,13.11,100,1,13.64,2,1,12.98,200,2,13.71,100,1,12.91,2,1,13.97,100,1,12.86,100,1,14.24,100,1,12.73,100,1,14.32,100,1,12.71,100,1,14.35,200,2,12.5,700,1,14.4,700,1,12.46,100,1,14.48,1400,2,12.43,700,1,14.54,800,2,12.42,700,1,14.67,200,2,ARL,370638833
2260,2025-07-17T16:41:43.144477498Z,2025-07-17T16:41:43.144477498Z,10,2,1108,A,A,8,14.5,100,130,165721,311182962,13.11,100,1,13.64,2,1,12.98,200,2,13.71,100,1,12.91,2,1,13.97,100,1,12.86,100,1,14.24,100,1,12.73,100,1,14.32,100,1,12.71,100,1,14.35,200,2,12.5,700,1,14.4,700,1,12.46,100,1,14.48,1400,2,12.43,700,1,14.5,100,1,12.42,700,1,14.54,800,2,ARL,375327933
2261,2025-07-17T16:41:43.156111360Z,2025-07-17T16:41:43.156111360Z,10,2,1108,C,A,1,13.71,100,130,165467,311183103,13.11,100,1,13.64,2,1,12.98,200,2,13.97,100,1,12.91,2,1,14.24,100,1,12.86,100,1,14.32,100,1,12.73,100,1,14.35,200,2,12.71,100,1,14.4,700,1,12.5,700,1,14.48,1400,2,12.46,100,1,14.5,100,1,12.43,700,1,14.54,800,2,12.42,700,1,14.67,200,2,ARL,370638829
2262,2025-07-17T16:41:43.156143472Z,2025-07-17T16:41:43.156143472Z,10,2,1108,C,A,5,14.4,700,130,165731,311183104,13.11,100,1,13.64,2,1,12.98,200,2,13.97,100,1,12.91,2,1,14.24,100,1,12.86,100,1,14.32,100,1,12.73,100,1,14.35,200,2,12.71,100,1,14.48,1400,2,12.5,700,1,14.5,100,1,12.46,100,1,14.54,800,2,12.43,700,1,14.67,200,2,12.42,700,1,15.09,200,2,ARL,375327817
2263,2025-07-17T16:41:43.156160068Z,2025-07-17T16:41:43.156160068Z,10,2,1108,A,A,2,13.98,100,130,165475,311183105,13.11,100,1,13.64,2,1,12.98,200,2,13.97,100,1,12.91,2,1,13.98,100,1,12.86,100,1,14.24,100,1,12.73,100,1,14.32,100,1,12.71,100,1,14.35,200,2,12.5,700,1,14.48,1400,2,12.46,100,1,14.5,100,1,12.43,700,1,14.54,800,2,12.42,700,1,14.67,200,2,ARL,375328129
2264,2025-07-17T16:41:43.158515465Z,2025-07-17T16:41:43.158515465Z,10,2,1108,C,A,9,14.67,100,0,165406,311183123,13.11,100,1,13.64,2,1,12.98,200,2,13.97,100,1,12.91,2,1,13.98,100,1,12.86,100,1,14.24,100,1,12.73,100,1,14.32,100,1,12.71,100,1,14.35,200,2,12.5,700,1,14.48,1400,2,12.46,100,1,14.5,100,1,12.43,700,1,14.54,800,2,12.42,700,1,14.67,100,1,ARL,375327849
2265,2025-07-17T16:41:43.162246276Z,2025-07-17T16:41:43.162246276Z,10,2,1108,C,A,0,13.64,2,0,165711,311183140,13.11,100,1,13.97,100,1,12.98,200,2,13.98,100,1,12.91,2,1,14.24,100,1,12.86,100,1,14.32,100,1,12.73,100,1,14.35,200,2,12.71,100,1,14.48,1400,2,12.5,700,1,14.5,100,1,12.46,100,1,14.54,800,2,12.43,700,1,14.67,100,1,12.42,700,1,14.95,100,1,ARL,374709161
2266,2025-07-17T16:41:43.162246276Z,2025-07-17T16:41:43.162246276Z,10,2,1108,A,A,0,13.97,2,130,165711,311183140,13.11,100,1,13.97,102,2,12.98,200,2,13.98,100,1,12.91,2,1,14.24,100,1,12.86,100,1,14.32,100,1,12.73,100,1,14.35,200,2,12.71,100,1,14.48,1400,2,12.5,700,1,14.5,100,1,12.46,100,1,14.54,800,2,12.43,700,1,14.67,100,1,12.42,700,1,14.95,100,1,ARL,375328205
2267,2025-07-17T16:41:43.170391935Z,2025-07-17T16:41:43.170391935Z,10,2,1108,C,A,8,14.67,100,0,165424,311183283,13.11,100,1,13.97,102,2,12.98,200,2,13.98,100,1,12.91,2,1,14.24,100,1,12.86,100,1,14.32,100,1,12.73,100,1,14.35,200,2,12.71,100,1,14.48,1400,2,12.5,700,1,14.5,100,1,12.46,100,1,14.54,800,2,12.43,700,1,14.95,100,1,12.42,700,1,15.09,200,2,ARL,375327925
2268,2025-07-17T16:41:43.170391935Z,2025-07-17T16:41:43.170391935Z,10,2,1108,A,A,8,14.95,100,130,165424,311183283,13.11,100,1,13.97,102,2,12.98,200,2,13.98,100,1,12.91,2,1,14.24,100,1,12.86,100,1,14.32,100,1,12.73,100,1,14.35,200,2,12.71,100,1,14.48,1400,2,12.5,700,1,14.5,100,1,12.46,100,1,14.54,800,2,12.43,700,1,14.95,200,2,12.42,700,1,15.09,200,2,ARL,375328333
2269,2025-07-17T16:41:43.171482095Z,2025-07-17T16:41:43.171482095Z,10,2,1108,C,A,1,13.98,100,130,165582,311183345,13.11,100,1,13.97,102,2,12.98,200,2,14.24,100,1,12.91,2,1,14.32,100,1,12.86,100,1,14.35,200,2,12.73,100,1,14.48,1400,2,12.71,100,1,14.5,100,1,12.5,700,1,14.54,800,2,12.46,100,1,14.95,200,2,12.43,700,1,15.09,200,2,12.42,700,1,15.3,100,1,ARL,375328129
2270,2025-07-17T16:41:43.171531790Z,2025-07-17T16:41:43.171531790Z,10,2,1108,A,A,1,14.21,100,130,165282,311183361,13.11,100,1,13.97,102,2,12.98,200,2,14.21,100,1,12.91,2,1,14.24,100,1,12.86,100,1,14.32,100,1,12.73,100,1,14.35,200,2,12.71,100,1,14.48,1400,2,12.5,700,1,14.5,100,1,12.46,100,1,14.54,800,2,12.43,700,1,14.95,200,2,12.42,700,1,15.09,200,2,ARL,375328497
2271,2025-07-17T16:41:43.189819838Z,2025-07-17T16:41:43.189819838Z,10,2,1108,C,A,7,14.54,100,0,165529,311183848,13.11,100,1,13.97,102,2,12.98,200,2,14.21,100,1,12.91,2,1,14.24,100,1,12.86,100,1,14.32,100,1,12.73,100,1,14.35,200,2,12.71,100,1,14.48,1400,2,12.5,700,1,14.5,100,1,12.46,100,1,14.54,700,1,12.43,700,1,14.95,200,2,12.42,700,1,15.09,200,2,ARL,375327841
2272,2025-07-17T16:41:43.189819838Z,2025-07-17T16:41:43.189819838Z,10,2,1108,A,A,9,15.05,100,130,165529,311183848,13.11,100,1,13.97,102,2,12.98,200,2,14.21,100,1,12.91,2,1,14.24,100,1,12.86,100,1,14.32,100,1,12.73,100,1,14.35,200,2,12.71,100,1,14.48,1400,2,12.5,700,1,14.5,100,1,12.46,100,1,14.54,700,1,12.43,700,1,14.95,200,2,12.42,700,1,15.05,100,1,ARL,375329021
2273,2025-07-17T16:41:43.209078680Z,2025-07-17T16:41:43.209078680Z,10,2,1108,C,A,0,13.97,100,130,165725,311184224,13.11,100,1,13.97,2,1,12.98,200,2,14.21,100,1,12.91,2,1,14.24,100,1,12.86,100,1,14.32,100,1,12.73,100,1,14.35,200,2,12.71,100,1,14.48,1400,2,12.5,700,1,14.5,100,1,12.46,100,1,14.54,700,1,12.43,700,1,14.95,200,2,12.42,700,1,15.05,100,1,ARL,370648729
2274,2025-07-17T16:41:43.209079728Z,2025-07-17T16:41:43.209079728Z,10,2,1108,A,A,3,14.26,100,130,165443,311184225,13.11,100,1,13.97,2,1,12.98,200,2,14.21,100,1,12.91,2,1,14.24,100,1,12.86,100,1,14.26,100,1,12.73,100,1,14.32,100,1,12.71,100,1,14.35,200,2,12.5,700,1,14.48,1400,2,12.46,100,1,14.5,100,1,12.43,700,1,14.54,700,1,12.42,700,1,14.95,200,2,ARL,375329381
2275,2025-07-17T16:41:43.209117671Z,2025-07-17T16:41:43.209117671Z,10,2,1108,A,A,9,14.67,700,130,165343,311184226,13.11,100,1,13.97,2,1,12.98,200,2,14.21,100,1,12.91,2,1,14.24,100,1,12.86,100,1,14.26,100,1,12.73,100,1,14.32,100,1,12.71,100,1,14.35,200,2,12.5,700,1,14.48,1400,2,12.46,100,1,14.5,100,1,12.43,700,1,14.54,700,1,12.42,700,1,14.67,700,1,ARL,375329385
2276,2025-07-17T16:41:43.490718665Z,2025-07-17T16:41:43.490718665Z,10,2,1108,C,A,2,14.24,100,130,165446,311188690,13.11,100,1,13.97,2,1,12.98,200,2,14.21,100,1,12.91,2,1,14.26,100,1,12.86,100,1,14.32,100,1,12.73,100,1,14.35,200,2,12.71,100,1,14.48,1400,2,12.5,700,1,14.5,100,1,12.46,100,1,14.54,700,1,12.43,700,1,14.67,700,1,12.42,700,1,14.81,100,1,ARL,370641493
2277,2025-07-17T16:41:43.752453166Z,2025-07-17T16:41:43.752453166Z,10,2,1108,C,A,3,14.32,100,130,165059,311195553,13.11,100,1,13.97,2,1,12.98,200,2,14.21,100,1,12.91,2,1,14.26,100,1,12.86,100,1,14.35,200,2,12.73,100,1,14.48,1400,2,12.71,100,1,14.5,100,1,12.5,700,1,14.54,700,1,12.46,100,1,14.67,700,1,12.43,700,1,14.81,100,1,12.42,700,1,14.95,200,2,ARL,375327857
2278,2025-07-17T16:41:43.752800607Z,2025-07-17T16:41:43.752800607Z,10,2,1108,A,A,7,14.6,100,130,165517,311195557,13.11,100,1,13.97,2,1,12.98,200,2,14.21,100,1,12.91,2,1,14.26,100,1,12.86,100,1,14.35,200,2,12.73,100,1,14.48,1400,2,12.71,100,1,14.5,100,1,12.5,700,1,14.54,700,1,12.46,100,1,14.6,100,1,12.43,700,1,14.67,700,1,12.42,700,1,14.81,100,1,ARL,375342121
2279,2025-07-17T16:41:43.860518846Z,2025-07-17T16:41:43.860518846Z,10,2,1108,A,A,1,13.98,100,130,165440,311202685,13.11,100,1,13.97,2,1,12.98,200,2,13.98,100,1,12.91,2,1,14.21,100,1,12.86,100,1,14.26,100,1,12.73,100,1,14.35,200,2,12.71,100,1,14.48,1400,2,12.5,700,1,14.5,100,1,12.46,100,1,14.54,700,1,12.43,700,1,14.6,100,1,12.42,700,1,14.67,700,1,ARL,375348505
2280,2025-07-17T16:41:44.145986128Z,2025-07-17T16:41:44.145986128Z,10,2,1108,C,A,6,14.5,100,130,165573,311210358,13.11,100,1,13.97,2,1,12.98,200,2,13.98,100,1,12.91,2,1,14.21,100,1,12.86,100,1,14.26,100,1,12.73,100,1,14.35,200,2,12.71,100,1,14.48,1400,2,12.5,700,1,14.54,700,1,12.46,100,1,14.6,100,1,12.43,700,1,14.67,700,1,12.42,700,1,14.81,100,1,ARL,375327933
2281,2025-07-17T16:41:44.146116212Z,2025-07-17T16:41:44.146116212Z,10,2,1108,A,A,9,14.77,100,130,165473,311210359,13.11,100,1,13.97,2,1,12.98,200,2,13.98,100,1,12.91,2,1,14.21,100,1,12.86,100,1,14.26,100,1,12.73,100,1,14.35,200,2,12.71,100,1,14.48,1400,2,12.5,700,1,14.54,700,1,12.46,100,1,14.6,100,1,12.43,700,1,14.67,700,1,12.42,700,1,14.77,100,1,ARL,375358061
2282,2025-07-17T16:41:53.592475714Z,2025-07-17T16:41:53.592475714Z,10,2,1108,C,B,2,12.91,2,0,165712,311376251,13.11,100,1,13.97,2,1,12.98,200,2,13.98,100,1,12.86,100,1,14.21,100,1,12.73,100,1,14.26,100,1,12.71,100,1,14.35,200,2,12.5,700,1,14.48,1400,2,12.46,100,1,14.54,700,1,12.43,700,1,14.6,100,1,12.42,700,1,14.67,700,1,12.37,700,1,14.77,100,1,ARL,369392197
2283,2025-07-17T16:41:53.592475714Z,2025-07-17T16:41:53.592475714Z,10,2,1108,A,B,1,12.99,2,130,165712,311376251,13.11,100,1,13.97,2,1,12.99,2,1,13.98,100,1,12.98,200,2,14.21,100,1,12.86,100,1,14.26,100,1,12.73,100,1,14.35,200,2,12.71,100,1,14.48,1400,2,12.5,700,1,14.54,700,1,12.46,100,1,14.6,100,1,12.43,700,1,14.67,700,1,12.42,700,1,14.77,100,1,ARL,375577225
2284,2025-07-17T16:42:04.386385514Z,2025-07-17T16:42:04.386385514Z,10,2,1108,C,B,1,12.99,2,0,165707,311568668,13.11,100,1,13.97,2,1,12.98,200,2,13.98,100,1,12.86,100,1,14.21,100,1,12.73,100,1,14.26,100,1,12.71,100,1,14.35,200,2,12.5,700,1,14.48,1400,2,12.46,100,1,14.54,700,1,12.43,700,1,14.6,100,1,12.42,700,1,14.67,700,1,12.37,700,1,14.77,100,1,ARL,375577225
2285,2025-07-17T16:42:04.386385514Z,2025-07-17T16:42:04.386385514Z,10,2,1108,A,B,1,13.06,2,130,165707,311568668,13.11,100,1,13.97,2,1,13.06,2,1,13.98,100,1,12.98,200,2,14.21,100,1,12.86,100,1,14.26,100,1,12.73,100,1,14.35,200,2,12.71,100,1,14.48,1400,2,12.5,700,1,14.54,700,1,12.46,100,1,14.6,100,1,12.43,700,1,14.67,700,1,12.42,700,1,14.77,100,1,ARL,375823217
2286,2025-07-17T16:42:36.878663385Z,2025-07-17T16:42:36.878663385Z,10,2,1108,A,A,0,13.45,15,130,165224,312149208,13.11,100,1,13.45,15,1,13.06,2,1,13.97,2,1,12.98,200,2,13.98,100,1,12.86,100,1,14.21,100,1,12.73,100,1,14.26,100,1,12.71,100,1,14.35,200,2,12.5,700,1,14.48,1400,2,12.46,100,1,14.54,700,1,12.43,700,1,14.6,100,1,12.42,700,1,14.67,700,1,ARL,376539701
2287,2025-07-17T16:42:37.985847507Z,2025-07-17T16:42:37.985847507Z,10,2,1108,C,B,1,13.06,2,0,165498,312159909,13.11,100,1,13.45,15,1,12.98,200,2,13.97,2,1,12.86,100,1,13.98,100,1,12.73,100,1,14.21,100,1,12.71,100,1,14.26,100,1,12.5,700,1,14.35,200,2,12.46,100,1,14.48,1400,2,12.43,700,1,14.54,700,1,12.42,700,1,14.6,100,1,12.37,700,1,14.67,700,1,ARL,375823217
2288,2025-07-17T16:42:37.985847507Z,2025-07-17T16:42:37.985847507Z,10,2,1108,A,B,0,13.11,2,130,165498,312159909,13.11,102,2,13.45,15,1,12.98,200,2,13.97,2,1,12.86,100,1,13.98,100,1,12.73,100,1,14.21,100,1,12.71,100,1,14.26,100,1,12.5,700,1,14.35,200,2,12.46,100,1,14.48,1400,2,12.43,700,1,14.54,700,1,12.42,700,1,14.6,100,1,12.37,700,1,14.67,700,1,ARL,376553221
2289,2025-07-17T16:42:38.270716854Z,2025-07-17T16:42:38.270716854Z,10,2,1108,C,A,2,13.98,100,0,165560,312165198,13.11,102,2,13.45,15,1,12.98,200,2,13.97,2,1,12.86,100,1,14.21,100,1,12.73,100,1,14.26,100,1,12.71,100,1,14.35,200,2,12.5,700,1,14.48,1400,2,12.46,100,1,14.54,700,1,12.43,700,1,14.6,100,1,12.42,700,1,14.67,700,1,12.37,700,1,14.77,100,1,ARL,375348505
2290,2025-07-17T16:42:38.270716854Z,2025-07-17T16:42:38.270716854Z,10,2,1108,A,A,1,13.46,100,130,165560,312165198,13.11,102,2,13.45,15,1,12.98,200,2,13.46,100,1,12.86,100,1,13.97,2,1,12.73,100,1,14.21,100,1,12.71,100,1,14.26,100,1,12.5,700,1,14.35,200,2,12.46,100,1,14.48,1400,2,12.43,700,1,14.54,700,1,12.42,700,1,14.6,100,1,12.37,700,1,14.67,700,1,ARL,376560477
2291,2025-07-17T16:42:38.271038120Z,2025-07-17T16:42:38.271038120Z,10,2,1108,C,B,0,13.11,2,0,165377,312165204,13.11,100,1,13.45,15,1,12.98,200,2,13.46,100,1,12.86,100,1,13.97,2,1,12.73,100,1,14.21,100,1,12.71,100,1,14.26,100,1,12.5,700,1,14.35,200,2,12.46,100,1,14.48,1400,2,12.43,700,1,14.54,700,1,12.42,700,1,14.6,100,1,12.37,700,1,14.67,700,1,ARL,376553221
2292,2025-07-17T16:42:38.271038120Z,2025-07-17T16:42:38.271038120Z,10,2,1108,A,B,1,13.0,2,130,165377,312165204,13.11,100,1,13.45,15,1,13.0,2,1,13.46,100,1,12.98,200,2,13.97,2,1,12.86,100,1,14.21,100,1,12.73,100,1,14.26,100,1,12.71,100,1,14.35,200,2,12.5,700,1,14.48,1400,2,12.46,100,1,14.54,700,1,12.43,700,1,14.6,100,1,12.42,700,1,14.67,700,1,ARL,376560493
2293,2025-07-17T16:42:38.271457684Z,2025-07-17T16:42:38.271457684Z,10,2,1108,A,A,7,14.5,100,130,165408,312165206,13.11,100,1,13.45,15,1,13.0,2,1,13.46,100,1,12.98,200,2,13.97,2,1,12.86,100,1,14.21,100,1,12.73,100,1,14.26,100,1,12.71,100,1,14.35,200,2,12.5,700,1,14.48,1400,2,12.46,100,1,14.5,100,1,12.43,700,1,14.54,700,1,12.42,700,1,14.6,100,1,ARL,376560501
2294,2025-07-17T16:42:38.271462148Z,2025-07-17T16:42:38.271462148Z,10,2,1108,C,A,9,14.6,100,130,165182,312165207,13.11,100,1,13.45,15,1,13.0,2,1,13.46,100,1,12.98,200,2,13.97,2,1,12.86,100,1,14.21,100,1,12.73,100,1,14.26,100,1,12.71,100,1,14.35,200,2,12.5,700,1,14.48,1400,2,12.46,100,1,14.5,100,1,12.43,700,1,14.54,700,1,12.42,700,1,14.67,700,1,ARL,375342121
2295,2025-07-17T16:42:38.271829580Z,2025-07-17T16:42:38.271829580Z,10,2,1108,A,A,3,14.06,100,130,165439,312165213,13.11,100,1,13.45,15,1,13.0,2,1,13.46,100,1,12.98,200,2,13.97,2,1,12.86,100,1,14.06,100,1,12.73,100,1,14.21,100,1,12.71,100,1,14.26,100,1,12.5,700,1,14.35,200,2,12.46,100,1,14.48,1400,2,12.43,700,1,14.5,100,1,12.42,700,1,14.54,700,1,ARL,376560525
2296,2025-07-17T16:42:38.273091716Z,2025-07-17T16:42:38.273091716Z,10,2,1108,A,A,7,14.41,100,130,165360,312165226,13.11,100,1,13.45,15,1,13.0,2,1,13.46,100,1,12.98,200,2,13.97,2,1,12.86,100,1,14.06,100,1,12.73,100,1,14.21,100,1,12.71,100,1,14.26,100,1,12.5,700,1,14.35,200,2,12.46,100,1,14.41,100,1,12.43,700,1,14.48,1400,2,12.42,700,1,14.5,100,1,ARL,376560553
2297,2025-07-17T16:42:38.274525240Z,2025-07-17T16:42:38.274525240Z,10,2,1108,A,A,5,14.25,100,130,165987,312165251,13.11,100,1,13.45,15,1,13.0,2,1,13.46,100,1,12.98,200,2,13.97,2,1,12.86,100,1,14.06,100,1,12.73,100,1,14.21,100,1,12.71,100,1,14.25,100,1,12.5,700,1,14.26,100,1,12.46,100,1,14.35,200,2,12.43,700,1,14.41,100,1,12.42,700,1,14.48,1400,2,ARL,376560581
2298,2025-07-17T16:42:38.278789456Z,2025-07-17T16:42:38.278789456Z,10,2,1108,A,A,8,14.41,100,130,165588,312165295,13.11,100,1,13.45,15,1,13.0,2,1,13.46,100,1,12.98,200,2,13.97,2,1,12.86,100,1,14.06,100,1,12.73,100,1,14.21,100,1,12.71,100,1,14.25,100,1,12.5,700,1,14.26,100,1,12.46,100,1,14.35,200,2,12.43,700,1,14.41,200,2,12.42,700,1,14.48,1400,2,ARL,376560685
2299,2025-07-17T16:42:38.283170473Z,2025-07-17T16:42:38.283170473Z,10,2,1108,C,A,4,14.21,100,130,165353,312165435,13.11,100,1,13.45,15,1,13.0,2,1,13.46,100,1,12.98,200,2,13.97,2,1,12.86,100,1,14.06,100,1,12.73,100,1,14.25,100,1,12.71,100,1,14.26,100,1,12.5,700,1,14.35,200,2,12.46,100,1,14.41,200,2,12.43,700,1,14.48,1400,2,12.42,700,1,14.5,100,1,ARL,375328497
2300,2025-07-17T16:42:38.283220234Z,2025-07-17T16:42:38.283220234Z,10,2,1108,A,A,2,13.73,100,130,165273,312165438,13.11,100,1,13.45,15,1,13.0,2,1,13.46,100,1,12.98,200,2,13.73,100,1,12.86,100,1,13.97,2,1,12.73,100,1,14.06,100,1,12.71,100,1,14.25,100,1,12.5,700,1,14.26,100,1,12.46,100,1,14.35,200,2,12.43,700,1,14.41,200,2,12.42,700,1,14.48,1400,2,ARL,376560813
2301,2025-07-17T16:42:38.873668683Z,2025-07-17T16:42:38.873668683Z,10,2,1108,A,A,6,14.26,100,130,165526,312171488,13.11,100,1,13.45,15,1,13.0,2,1,13.46,100,1,12.98,200,2,13.73,100,1,12.86,100,1,13.97,2,1,12.73,100,1,14.06,100,1,12.71,100,1,14.25,100,1,12.5,700,1,14.26,200,2,12.46,100,1,14.35,200,2,12.43,700,1,14.41,200,2,12.42,700,1,14.48,1400,2,ARL,376569293
2302,2025-07-17T16:42:40.989690505Z,2025-07-17T16:42:40.989690505Z,10,2,1108,C,A,3,13.97,2,0,165531,312198414,13.11,100,1,13.45,15,1,13.0,2,1,13.46,100,1,12.98,200,2,13.73,100,1,12.86,100,1,14.06,100,1,12.73,100,1,14.25,100,1,12.71,100,1,14.26,200,2,12.5,700,1,14.35,200,2,12.46,100,1,14.41,200,2,12.43,700,1,14.48,1400,2,12.42,700,1,14.5,100,1,ARL,375328205
2303,2025-07-17T16:42:40.989690505Z,2025-07-17T16:42:40.989690505Z,10,2,1108,A,A,3,13.87,2,130,165531,312198414,13.11,100,1,13.45,15,1,13.0,2,1,13.46,100,1,12.98,200,2,13.73,100,1,12.86,100,1,13.87,2,1,12.73,100,1,14.06,100,1,12.71,100,1,14.25,100,1,12.5,700,1,14.26,200,2,12.46,100,1,14.35,200,2,12.43,700,1,14.41,200,2,12.42,700,1,14.48,1400,2,ARL,376604133
2304,2025-07-17T16:42:46.433709548Z,2025-07-17T16:42:46.433709548Z,10,2,1108,A,A,5,14.18,700,130,165596,312255078,13.11,100,1,13.45,15,1,13.0,2,1,13.46,100,1,12.98,200,2,13.73,100,1,12.86,100,1,13.87,2,1,12.73,100,1,14.06,100,1,12.71,100,1,14.18,700,1,12.5,700,1,14.25,100,1,12.46,100,1,14.26,200,2,12.43,700,1,14.35,200,2,12.42,700,1,14.41,200,2,ARL,376682393
2305,2025-07-17T16:42:48.190716226Z,2025-07-17T16:42:48.190716226Z,10,2,1108,C,A,3,13.87,2,0,165459,312275865,13.11,100,1,13.45,15,1,13.0,2,1,13.46,100,1,12.98,200,2,13.73,100,1,12.86,100,1,14.06,100,1,12.73,100,1,14.18,700,1,12.71,100,1,14.25,100,1,12.5,700,1,14.26,200,2,12.46,100,1,14.35,200,2,12.43,700,1,14.41,200,2,12.42,700,1,14.48,1400,2,ARL,376604133
2306,2025-07-17T16:42:48.190716226Z,2025-07-17T16:42:48.190716226Z,10,2,1108,A,A,3,13.79,2,130,165459,312275865,13.11,100,1,13.45,15,1,13.0,2,1,13.46,100,1,12.98,200,2,13.73,100,1,12.86,100,1,13.79,2,1,12.73,100,1,14.06,100,1,12.71,100,1,14.18,700,1,12.5,700,1,14.25,100,1,12.46,100,1,14.26,200,2,12.43,700,1,14.35,200,2,12.42,700,1,14.41,200,2,ARL,376710049
2307,2025-07-17T16:42:53.413840345Z,2025-07-17T16:42:53.413840345Z,10,2,1108,C,A,0,13.45,15,130,165417,312346120,13.11,100,1,13.46,100,1,13.0,2,1,13.73,100,1,12.98,200,2,13.79,2,1,12.86,100,1,14.06,100,1,12.73,100,1,14.18,700,1,12.71,100,1,14.25,100,1,12.5,700,1,14.26,200,2,12.46,100,1,14.35,200,2,12.43,700,1,14.41,200,2,12.42,700,1,14.48,1400,2,ARL,376539701
2308,2025-07-17T16:42:53.419392154Z,2025-07-17T16:42:53.419392154Z,10,2,1108,A,A,0,13.45,15,130,165478,312346353,13.11,100,1,13.45,15,1,13.0,2,1,13.46,100,1,12.98,200,2,13.73,100,1,12.86,100,1,13.79,2,1,12.73,100,1,14.06,100,1,12.71,100,1,14.18,700,1,12.5,700,1,14.25,100,1,12.46,100,1,14.26,200,2,12.43,700,1,14.35,200,2,12.42,700,1,14.41,200,2,ARL,376801517
2309,2025-07-17T16:43:01.389646878Z,2025-07-17T16:43:01.389646878Z,10,2,1108,C,A,3,13.79,2,0,165763,312450189,13.11,100,1,13.45,15,1,13.0,2,1,13.46,100,1,12.98,200,2,13.73,100,1,12.86,100,1,14.06,100,1,12.73,100,1,14.18,700,1,12.71,100,1,14.25,100,1,12.5,700,1,14.26,200,2,12.46,100,1,14.35,200,2,12.43,700,1,14.41,200,2,12.42,700,1,14.48,1400,2,ARL,376710049
2310,2025-07-17T16:43:01.389646878Z,2025-07-17T16:43:01.389646878Z,10,2,1108,A,A,2,13.72,2,130,165763,312450189,13.11,100,1,13.45,15,1,13.0,2,1,13.46,100,1,12.98,200,2,13.72,2,1,12.86,100,1,13.73,100,1,12.73,100,1,14.06,100,1,12.71,100,1,14.18,700,1,12.5,700,1,14.25,100,1,12.46,100,1,14.26,200,2,12.43,700,1,14.35,200,2,12.42,700,1,14.41,200,2,ARL,376932045
2311,2025-07-17T16:44:05.065987790Z,2025-07-17T16:44:05.065987790Z,10,2,1108,C,A,0,13.45,15,130,165510,313334368,13.11,100,1,13.46,100,1,13.0,2,1,13.72,2,1,12.98,200,2,13.73,100,1,12.86,100,1,14.06,100,1,12.73,100,1,14.18,700,1,12.71,100,1,14.25,100,1,12.5,700,1,14.26,200,2,12.46,100,1,14.35,200,2,12.43,700,1,14.41,200,2,12.42,700,1,14.48,1400,2,ARL,376801517
2312,2025-07-17T16:44:10.386132925Z,2025-07-17T16:44:10.386132925Z,10,2,1108,C,A,1,13.72,2,0,165653,313428705,13.11,100,1,13.46,100,1,13.0,2,1,13.73,100,1,12.98,200,2,14.06,100,1,12.86,100,1,14.18,700,1,12.73,100,1,14.25,100,1,12.71,100,1,14.26,200,2,12.5,700,1,14.35,200,2,12.46,100,1,14.41,200,2,12.43,700,1,14.48,1400,2,12.42,700,1,14.5,100,1,ARL,376932045
2313,2025-07-17T16:44:10.386132925Z,2025-07-17T16:44:10.386132925Z,10,2,1108,A,A,1,13.66,2,130,165653,313428705,13.11,100,1,13.46,100,1,13.0,2,1,13.66,2,1,12.98,200,2,13.73,100,1,12.86,100,1,14.06,100,1,12.73,100,1,14.18,700,1,12.71,100,1,14.25,100,1,12.5,700,1,14.26,200,2,12.46,100,1,14.35,200,2,12.43,700,1,14.41,200,2,12.42,700,1,14.48,1400,2,ARL,378209833
2314,2025-07-17T16:44:28.874556092Z,2025-07-17T16:44:28.874556092Z,10,2,1108,A,A,0,13.45,15,130,166018,313679060,13.11,100,1,13.45,15,1,13.0,2,1,13.46,100,1,12.98,200,2,13.66,2,1,12.86,100,1,13.73,100,1,12.73,100,1,14.06,100,1,12.71,100,1,14.18,700,1,12.5,700,1,14.25,100,1,12.46,100,1,14.26,200,2,12.43,700,1,14.35,200,2,12.42,700,1,14.41,200,2,ARL,378572841
2315,2025-07-17T16:44:33.445416279Z,2025-07-17T16:44:33.445416279Z,10,2,1108,C,A,0,13.45,15,128,167600,313731687,13.11,100,1,13.46,100,1,13.0,2,1,13.66,2,1,12.98,200,2,13.73,100,1,12.86,100,1,14.06,100,1,12.73,100,1,14.18,700,1,12.71,100,1,14.25,100,1,12.5,700,1,14.26,200,2,12.46,100,1,14.35,200,2,12.43,700,1,14.41,200,2,12.42,700,1,14.48,1400,2,ARL,378572841
2316,2025-07-17T16:44:43.947504113Z,2025-07-17T16:44:43.947504113Z,10,2,1108,C,A,0,13.46,100,130,165135,313928874,13.11,100,1,13.66,2,1,13.0,2,1,13.73,100,1,12.98,200,2,14.06,100,1,12.86,100,1,14.18,700,1,12.73,100,1,14.25,100,1,12.71,100,1,14.26,200,2,12.5,700,1,14.35,200,2,12.46,100,1,14.41,200,2,12.43,700,1,14.48,1400,2,12.42,700,1,14.5,100,1,ARL,376560477
2317,2025-07-17T16:44:43.947777103Z,2025-07-17T16:44:43.947777103Z,10,2,1108,C,A,3,14.18,700,130,165843,313928881,13.11,100,1,13.66,2,1,13.0,2,1,13.73,100,1,12.98,200,2,14.06,100,1,12.86,100,1,14.25,100,1,12.73,100,1,14.26,200,2,12.71,100,1,14.35,200,2,12.5,700,1,14.41,200,2,12.46,100,1,14.48,1400,2,12.43,700,1,14.5,100,1,12.42,700,1,14.54,700,1,ARL,376682393
2318,2025-07-17T16:44:43.947828206Z,2025-07-17T16:44:43.947828206Z,10,2,1108,A,A,7,14.42,700,130,165324,313928882,13.11,100,1,13.66,2,1,13.0,2,1,13.73,100,1,12.98,200,2,14.06,100,1,12.86,100,1,14.25,100,1,12.73,100,1,14.26,200,2,12.71,100,1,14.35,200,2,12.5,700,1,14.41,200,2,12.46,100,1,14.42,700,1,12.43,700,1,14.48,1400,2,12.42,700,1,14.5,100,1,ARL,378884161
2319,2025-07-17T16:44:43.948249121Z,2025-07-17T16:44:43.948249121Z,10,2,1108,C,A,2,14.06,100,130,165455,313928891,13.11,100,1,13.66,2,1,13.0,2,1,13.73,100,1,12.98,200,2,14.25,100,1,12.86,100,1,14.26,200,2,12.73,100,1,14.35,200,2,12.71,100,1,14.41,200,2,12.5,700,1,14.42,700,1,12.46,100,1,14.48,1400,2,12.43,700,1,14.5,100,1,12.42,700,1,14.54,700,1,ARL,376560525
2320,2025-07-17T16:44:43.948256940Z,2025-07-17T16:44:43.948256940Z,10,2,1108,C,A,8,14.5,100,0,165778,313928892,13.11,100,1,13.66,2,1,13.0,2,1,13.73,100,1,12.98,200,2,14.25,100,1,12.86,100,1,14.26,200,2,12.73,100,1,14.35,200,2,12.71,100,1,14.41,200,2,12.5,700,1,14.42,700,1,12.46,100,1,14.48,1400,2,12.43,700,1,14.54,700,1,12.42,700,1,14.81,200,2,ARL,376560501
2321,2025-07-17T16:44:43.948256940Z,2025-07-17T16:44:43.948256940Z,10,2,1108,A,A,9,14.56,100,130,165778,313928892,13.11,100,1,13.66,2,1,13.0,2,1,13.73,100,1,12.98,200,2,14.25,100,1,12.86,100,1,14.26,200,2,12.73,100,1,14.35,200,2,12.71,100,1,14.41,200,2,12.5,700,1,14.42,700,1,12.46,100,1,14.48,1400,2,12.43,700,1,14.54,700,1,12.42,700,1,14.56,100,1,ARL,378884201
2322,2025-07-17T16:44:43.948601956Z,2025-07-17T16:44:43.948601956Z,10,2,1108,A,A,4,14.34,100,130,165291,313928894,13.11,100,1,13.66,2,1,13.0,2,1,13.73,100,1,12.98,200,2,14.25,100,1,12.86,100,1,14.26,200,2,12.73,100,1,14.34,100,1,12.71,100,1,14.35,200,2,12.5,700,1,14.41,200,2,12.46,100,1,14.42,700,1,12.43,700,1,14.48,1400,2,12.42,700,1,14.54,700,1,ARL,378884205
2323,2025-07-17T16:44:43.949133566Z,2025-07-17T16:44:43.949133566Z,10,2,1108,C,A,6,14.41,100,0,165644,313928896,13.11,100,1,13.66,2,1,13.0,2,1,13.73,100,1,12.98,200,2,14.25,100,1,12.86,100,1,14.26,200,2,12.73,100,1,14.34,100,1,12.71,100,1,14.35,200,2,12.5,700,1,14.41,100,1,12.46,100,1,14.42,700,1,12.43,700,1,14.48,1400,2,12.42,700,1,14.54,700,1,ARL,376560553
2324,2025-07-17T16:44:43.950178776Z,2025-07-17T16:44:43.950178776Z,10,2,1108,C,A,6,14.41,100,0,165502,313928909,13.11,100,1,13.66,2,1,13.0,2,1,13.73,100,1,12.98,200,2,14.25,100,1,12.86,100,1,14.26,200,2,12.73,100,1,14.34,100,1,12.71,100,1,14.35,200,2,12.5,700,1,14.42,700,1,12.46,100,1,14.48,1400,2,12.43,700,1,14.54,700,1,12.42,700,1,14.56,100,1,ARL,376560685
2325,2025-07-17T16:44:43.960172259Z,2025-07-17T16:44:43.960172259Z,10,2,1108,C,A,2,14.25,100,130,165340,313928963,13.11,100,1,13.66,2,1,13.0,2,1,13.73,100,1,12.98,200,2,14.26,200,2,12.86,100,1,14.34,100,1,12.73,100,1,14.35,200,2,12.71,100,1,14.42,700,1,12.5,700,1,14.48,1400,2,12.46,100,1,14.54,700,1,12.43,700,1,14.56,100,1,12.42,700,1,14.7,200,2,ARL,376560581
2326,2025-07-17T16:44:43.960295032Z,2025-07-17T16:44:43.960295032Z,10,2,1108,A,A,7,14.52,100,130,165215,313928965,13.11,100,1,13.66,2,1,13.0,2,1,13.73,100,1,12.98,200,2,14.26,200,2,12.86,100,1,14.34,100,1,12.73,100,1,14.35,200,2,12.71,100,1,14.42,700,1,12.5,700,1,14.48,1400,2,12.46,100,1,14.52,100,1,12.43,700,1,14.54,700,1,12.42,700,1,14.56,100,1,ARL,378884345
2327,2025-07-17T16:44:43.965436032Z,2025-07-17T16:44:43.965436032Z,10,2,1108,C,A,1,13.73,100,130,165443,313928980,13.11,100,1,13.66,2,1,13.0,2,1,14.26,200,2,12.98,200,2,14.34,100,1,12.86,100,1,14.35,200,2,12.73,100,1,14.42,700,1,12.71,100,1,14.48,1400,2,12.5,700,1,14.52,100,1,12.46,100,1,14.54,700,1,12.43,700,1,14.56,100,1,12.42,700,1,14.7,200,2,ARL,376560813
2328,2025-07-17T16:44:43.965467685Z,2025-07-17T16:44:43.965467685Z,10,2,1108,C,A,4,14.42,700,130,165034,313928981,13.11,100,1,13.66,2,1,13.0,2,1,14.26,200,2,12.98,200,2,14.34,100,1,12.86,100,1,14.35,200,2,12.73,100,1,14.48,1400,2,12.71,100,1,14.52,100,1,12.5,700,1,14.54,700,1,12.46,100,1,14.56,100,1,12.43,700,1,14.7,200,2,12.42,700,1,15.11,200,2,ARL,378884161
2329,2025-07-17T16:44:43.965487362Z,2025-07-17T16:44:43.965487362Z,10,2,1108,A,A,1,14.0,100,130,165343,313928982,13.11,100,1,13.66,2,1,13.0,2,1,14.0,100,1,12.98,200,2,14.26,200,2,12.86,100,1,14.34,100,1,12.73,100,1,14.35,200,2,12.71,100,1,14.48,1400,2,12.5,700,1,14.52,100,1,12.46,100,1,14.54,700,1,12.43,700,1,14.56,100,1,12.42,700,1,14.7,200,2,ARL,378884369
2330,2025-07-17T16:44:43.966610475Z,2025-07-17T16:44:43.966610475Z,10,2,1108,C,A,9,14.7,100,0,165629,313928996,13.11,100,1,13.66,2,1,13.0,2,1,14.0,100,1,12.98,200,2,14.26,200,2,12.86,100,1,14.34,100,1,12.73,100,1,14.35,200,2,12.71,100,1,14.48,1400,2,12.5,700,1,14.52,100,1,12.46,100,1,14.54,700,1,12.43,700,1,14.56,100,1,12.42,700,1,14.7,100,1,ARL,378884209
2331,2025-07-17T16:44:43.967334622Z,2025-07-17T16:44:43.967334622Z,10,2,1108,C,B,1,13.0,2,0,165327,313929001,13.11,100,1,13.66,2,1,12.98,200,2,14.0,100,1,12.86,100,1,14.26,200,2,12.73,100,1,14.34,100,1,12.71,100,1,14.35,200,2,12.5,700,1,14.48,1400,2,12.46,100,1,14.52,100,1,12.43,700,1,14.54,700,1,12.42,700,1,14.56,100,1,12.37,700,1,14.7,100,1,ARL,376560493
2332,2025-07-17T16:44:43.967334622Z,2025-07-17T16:44:43.967334622Z,10,2,1108,A,B,2,12.88,2,130,165327,313929001,13.11,100,1,13.66,2,1,12.98,200,2,14.0,100,1,12.88,2,1,14.26,200,2,12.86,100,1,14.34,100,1,12.73,100,1,14.35,200,2,12.71,100,1,14.48,1400,2,12.5,700,1,14.52,100,1,12.46,100,1,14.54,700,1,12.43,700,1,14.56,100,1,12.42,700,1,14.7,100,1,ARL,378884417
2333,2025-07-17T16:44:43.967336268Z,2025-07-17T16:44:43.967336268Z,10,2,1108,C,A,0,13.66,2,0,165307,313929002,13.11,100,1,14.0,100,1,12.98,200,2,14.26,200,2,12.88,2,1,14.34,100,1,12.86,100,1,14.35,200,2,12.73,100,1,14.48,1400,2,12.71,100,1,14.52,100,1,12.5,700,1,14.54,700,1,12.46,100,1,14.56,100,1,12.43,700,1,14.7,100,1,12.42,700,1,14.93,100,1,ARL,378209833
2334,2025-07-17T16:44:43.967336268Z,2025-07-17T16:44:43.967336268Z,10,2,1108,A,A,0,13.98,2,130,165307,313929002,13.11,100,1,13.98,2,1,12.98,200,2,14.0,100,1,12.88,2,1,14.26,200,2,12.86,100,1,14.34,100,1,12.73,100,1,14.35,200,2,12.71,100,1,14.48,1400,2,12.5,700,1,14.52,100,1,12.46,100,1,14.54,700,1,12.43,700,1,14.56,100,1,12.42,700,1,14.7,100,1,ARL,378884421
2335,2025-07-17T16:44:43.968238011Z,2025-07-17T16:44:43.968238011Z,10,2,1108,C,A,9,14.7,100,0,165404,313929006,13.11,100,1,13.98,2,1,12.98,200,2,14.0,100,1,12.88,2,1,14.26,200,2,12.86,100,1,14.34,100,1,12.73,100,1,14.35,200,2,12.71,100,1,14.48,1400,2,12.5,700,1,14.52,100,1,12.46,100,1,14.54,700,1,12.43,700,1,14.56,100,1,12.42,700,1,14.93,100,1,ARL,378884245
2336,2025-07-17T16:44:43.998398734Z,2025-07-17T16:44:43.998398734Z,10,2,1108,C,A,8,14.56,100,0,165357,313929166,13.11,100,1,13.98,2,1,12.98,200,2,14.0,100,1,12.88,2,1,14.26,200,2,12.86,100,1,14.34,100,1,12.73,100,1,14.35,200,2,12.71,100,1,14.48,1400,2,12.5,700,1,14.52,100,1,12.46,100,1,14.54,700,1,12.43,700,1,14.93,100,1,12.42,700,1,14.96,100,1,ARL,378884201
2337,2025-07-17T16:44:43.998551330Z,2025-07-17T16:44:43.998551330Z,10,2,1108,C,A,1,14.0,100,130,165123,313929167,13.11,100,1,13.98,2,1,12.98,200,2,14.26,200,2,12.88,2,1,14.34,100,1,12.86,100,1,14.35,200,2,12.73,100,1,14.48,1400,2,12.71,100,1,14.52,100,1,12.5,700,1,14.54,700,1,12.46,100,1,14.93,100,1,12.43,700,1,14.96,100,1,12.42,700,1,15.03,100,1,ARL,378884369
2338,2025-07-17T16:44:43.998602131Z,2025-07-17T16:44:43.998602131Z,10,2,1108,A,A,1,14.23,100,130,165275,313929168,13.11,100,1,13.98,2,1,12.98,200,2,14.23,100,1,12.88,2,1,14.26,200,2,12.86,100,1,14.34,100,1,12.73,100,1,14.35,200,2,12.71,100,1,14.48,1400,2,12.5,700,1,14.52,100,1,12.46,100,1,14.54,700,1,12.43,700,1,14.93,100,1,12.42,700,1,14.96,100,1,ARL,378884757
2339,2025-07-17T16:44:44.034024501Z,2025-07-17T16:44:44.034024501Z,10,2,1108,A,A,8,14.68,700,130,165978,313929291,13.11,100,1,13.98,2,1,12.98,200,2,14.23,100,1,12.88,2,1,14.26,200,2,12.86,100,1,14.34,100,1,12.73,100,1,14.35,200,2,12.71,100,1,14.48,1400,2,12.5,700,1,14.52,100,1,12.46,100,1,14.54,700,1,12.43,700,1,14.68,700,1,12.42,700,1,14.93,100,1,ARL,378885133
2340,2025-07-17T16:44:44.140729032Z,2025-07-17T16:44:44.140729032Z,10,2,1108,A,A,9,14.81,100,130,165329,313931073,13.11,100,1,13.98,2,1,12.98,200,2,14.23,100,1,12.88,2,1,14.26,200,2,12.86,100,1,14.34,100,1,12.73,100,1,14.35,200,2,12.71,100,1,14.48,1400,2,12.5,700,1,14.52,100,1,12.46,100,1,14.54,700,1,12.43,700,1,14.68,700,1,12.42,700,1,14.81,100,1,ARL,378887673
2341,2025-07-17T16:44:44.140742632Z,2025-07-17T16:44:44.140742632Z,10,2,1108,C,A,2,14.26,100,130,165301,313931074,13.11,100,1,13.98,2,1,12.98,200,2,14.23,100,1,12.88,2,1,14.26,100,1,12.86,100,1,14.34,100,1,12.73,100,1,14.35,200,2,12.71,100,1,14.48,1400,2,12.5,700,1,14.52,100,1,12.46,100,1,14.54,700,1,12.43,700,1,14.68,700,1,12.42,700,1,14.81,100,1,ARL,376569293
2342,2025-07-17T16:44:44.228054315Z,2025-07-17T16:44:44.228054315Z,10,2,1108,A,A,1,13.99,100,130,165343,313931853,13.11,100,1,13.98,2,1,12.98,200,2,13.99,100,1,12.88,2,1,14.23,100,1,12.86,100,1,14.26,100,1,12.73,100,1,14.34,100,1,12.71,100,1,14.35,200,2,12.5,700,1,14.48,1400,2,12.46,100,1,14.52,100,1,12.43,700,1,14.54,700,1,12.42,700,1,14.68,700,1,ARL,378888877
2343,2025-07-17T16:44:44.522897140Z,2025-07-17T16:44:44.522897140Z,10,2,1108,A,A,0,13.45,15,130,165398,313938755,13.11,100,1,13.45,15,1,12.98,200,2,13.98,2,1,12.88,2,1,13.99,100,1,12.86,100,1,14.23,100,1,12.73,100,1,14.26,100,1,12.71,100,1,14.34,100,1,12.5,700,1,14.35,200,2,12.46,100,1,14.48,1400,2,12.43,700,1,14.52,100,1,12.42,700,1,14.54,700,1,ARL,378899025
2344,2025-07-17T16:44:44.570690672Z,2025-07-17T16:44:44.570690672Z,10,2,1108,C,A,5,14.34,100,130,165594,313939672,13.11,100,1,13.45,15,1,12.98,200,2,13.98,2,1,12.88,2,1,13.99,100,1,12.86,100,1,14.23,100,1,12.73,100,1,14.26,100,1,12.71,100,1,14.35,200,2,12.5,700,1,14.48,1400,2,12.46,100,1,14.52,100,1,12.43,700,1,14.54,700,1,12.42,700,1,14.68,700,1,ARL,378884205
2345,2025-07-17T16:44:44.571040568Z,2025-07-17T16:44:44.571040568Z,10,2,1108,A,A,9,14.6,100,130,165486,313939677,13.11,100,1,13.45,15,1,12.98,200,2,13.98,2,1,12.88,2,1,13.99,100,1,12.86,100,1,14.23,100,1,12.73,100,1,14.26,100,1,12.71,100,1,14.35,200,2,12.5,700,1,14.48,1400,2,12.46,100,1,14.52,100,1,12.43,700,1,14.54,700,1,12.42,700,1,14.6,100,1,ARL,378900061
2346,2025-07-17T16:44:44.961344305Z,2025-07-17T16:44:44.961344305Z,10,2,1108,C,A,7,14.52,100,0,165532,313943280,13.11,100,1,13.45,15,1,12.98,200,2,13.98,2,1,12.88,2,1,13.99,100,1,12.86,100,1,14.23,100,1,12.73,100,1,14.26,100,1,12.71,100,1,14.35,200,2,12.5,700,1,14.48,1400,2,12.46,100,1,14.54,700,1,12.43,700,1,14.6,100,1,12.42,700,1,14.68,700,1,ARL,378884345
2347,2025-07-17T16:44:46.881722229Z,2025-07-17T16:44:46.881722229Z,10,2,1108,C,A,0,13.45,15,130,165364,313964658,13.11,100,1,13.98,2,1,12.98,200,2,13.99,100,1,12.88,2,1,14.23,100,1,12.86,100,1,14.26,100,1,12.73,100,1,14.35,200,2,12.71,100,1,14.48,1400,2,12.5,700,1,14.54,700,1,12.46,100,1,14.6,100,1,12.43,700,1,14.68,700,1,12.42,700,1,14.77,100,1,ARL,378899025
2348,2025-07-17T16:44:49.387476653Z,2025-07-17T16:44:49.387476653Z,10,2,1108,C,B,2,12.88,2,0,165891,313994239,13.11,100,1,13.98,2,1,12.98,200,2,13.99,100,1,12.86,100,1,14.23,100,1,12.73,100,1,14.26,100,1,12.71,100,1,14.35,200,2,12.5,700,1,14.48,1400,2,12.46,100,1,14.54,700,1,12.43,700,1,14.6,100,1,12.42,700,1,14.68,700,1,12.37,700,1,14.77,100,1,ARL,378884417
2349,2025-07-17T16:44:49.387476653Z,2025-07-17T16:44:49.387476653Z,10,2,1108,A,B,2,12.97,2,130,165891,313994239,13.11,100,1,13.98,2,1,12.98,200,2,13.99,100,1,12.97,2,1,14.23,100,1,12.86,100,1,14.26,100,1,12.73,100,1,14.35,200,2,12.71,100,1,14.48,1400,2,12.5,700,1,14.54,700,1,12.46,100,1,14.6,100,1,12.43,700,1,14.68,700,1,12.42,700,1,14.77,100,1,ARL,378976465
2350,2025-07-17T16:44:54.882874395Z,2025-07-17T16:44:54.882874395Z,10,2,1108,A,A,0,13.45,15,130,165405,314081248,13.11,100,1,13.45,15,1,12.98,200,2,13.98,2,1,12.97,2,1,13.99,100,1,12.86,100,1,14.23,100,1,12.73,100,1,14.26,100,1,12.71,100,1,14.35,200,2,12.5,700,1,14.48,1400,2,12.46,100,1,14.54,700,1,12.43,700,1,14.6,100,1,12.42,700,1,14.68,700,1,ARL,379094717
2351,2025-07-17T16:44:54.909111232Z,2025-07-17T16:44:54.909111232Z,10,2,1108,C,A,2,13.99,100,0,165352,314082223,13.11,100,1,13.45,15,1,12.98,200,2,13.98,2,1,12.97,2,1,14.23,100,1,12.86,100,1,14.26,100,1,12.73,100,1,14.35,200,2,12.71,100,1,14.48,1400,2,12.5,700,1,14.54,700,1,12.46,100,1,14.6,100,1,12.43,700,1,14.68,700,1,12.42,700,1,14.77,100,1,ARL,378888877
2352,2025-07-17T16:44:54.909111232Z,2025-07-17T16:44:54.909111232Z,10,2,1108,A,A,1,13.46,100,130,165352,314082223,13.11,100,1,13.45,15,1,12.98,200,2,13.46,100,1,12.97,2,1,13.98,2,1,12.86,100,1,14.23,100,1,12.73,100,1,14.26,100,1,12.71,100,1,14.35,200,2,12.5,700,1,14.48,1400,2,12.46,100,1,14.54,700,1,12.43,700,1,14.6,100,1,12.42,700,1,14.68,700,1,ARL,379095909
2353,2025-07-17T16:44:54.909412092Z,2025-07-17T16:44:54.909412092Z,10,2,1108,C,A,2,13.98,2,0,165508,314082230,13.11,100,1,13.45,15,1,12.98,200,2,13.46,100,1,12.97,2,1,14.23,100,1,12.86,100,1,14.26,100,1,12.73,100,1,14.35,200,2,12.71,100,1,14.48,1400,2,12.5,700,1,14.54,700,1,12.46,100,1,14.6,100,1,12.43,700,1,14.68,700,1,12.42,700,1,14.77,100,1,ARL,378884421
2354,2025-07-17T16:44:54.909412092Z,2025-07-17T16:44:54.909412092Z,10,2,1108,A,A,2,13.79,2,130,165508,314082230,13.11,100,1,13.45,15,1,12.98,200,2,13.46,100,1,12.97,2,1,13.79,2,1,12.86,100,1,14.23,100,1,12.73,100,1,14.26,100,1,12.71,100,1,14.35,200,2,12.5,700,1,14.48,1400,2,12.46,100,1,14.54,700,1,12.43,700,1,14.6,100,1,12.42,700,1,14.68,700,1,ARL,379095929
2355,2025-07-17T16:44:54.909846352Z,2025-07-17T16:44:54.909846352Z,10,2,1108,A,A,7,14.5,100,130,165436,314082244,13.11,100,1,13.45,15,1,12.98,200,2,13.46,100,1,12.97,2,1,13.79,2,1,12.86,100,1,14.23,100,1,12.73,100,1,14.26,100,1,12.71,100,1,14.35,200,2,12.5,700,1,14.48,1400,2,12.46,100,1,14.5,100,1,12.43,700,1,14.54,700,1,12.42,700,1,14.6,100,1,ARL,379095949
2356,2025-07-17T16:44:54.909848730Z,2025-07-17T16:44:54.909848730Z,10,2,1108,C,A,9,14.6,100,130,165354,314082245,13.11,100,1,13.45,15,1,12.98,200,2,13.46,100,1,12.97,2,1,13.79,2,1,12.86,100,1,14.23,100,1,12.73,100,1,14.26,100,1,12.71,100,1,14.35,200,2,12.5,700,1,14.48,1400,2,12.46,100,1,14.5,100,1,12.43,700,1,14.54,700,1,12.42,700,1,14.68,700,1,ARL,378900061
2357,2025-07-17T16:44:54.910148272Z,2025-07-17T16:44:54.910148272Z,10,2,1108,A,A,6,14.41,100,130,165289,314082257,13.11,100,1,13.45,15,1,12.98,200,2,13.46,100,1,12.97,2,1,13.79,2,1,12.86,100,1,14.23,100,1,12.73,100,1,14.26,100,1,12.71,100,1,14.35,200,2,12.5,700,1,14.41,100,1,12.46,100,1,14.48,1400,2,12.43,700,1,14.5,100,1,12.42,700,1,14.54,700,1,ARL,379095977
2358,2025-07-17T16:44:54.910209882Z,2025-07-17T16:44:54.910209882Z,10,2,1108,A,A,3,14.06,100,130,165424,314082259,13.11,100,1,13.45,15,1,12.98,200,2,13.46,100,1,12.97,2,1,13.79,2,1,12.86,100,1,14.06,100,1,12.73,100,1,14.23,100,1,12.71,100,1,14.26,100,1,12.5,700,1,14.35,200,2,12.46,100,1,14.41,100,1,12.43,700,1,14.48,1400,2,12.42,700,1,14.5,100,1,ARL,379095981
2359,2025-07-17T16:44:54.915718215Z,2025-07-17T16:44:54.915718215Z,10,2,1108,C,A,4,14.23,100,130,165087,314082353,13.11,100,1,13.45,15,1,12.98,200,2,13.46,100,1,12.97,2,1,13.79,2,1,12.86,100,1,14.06,100,1,12.73,100,1,14.26,100,1,12.71,100,1,14.35,200,2,12.5,700,1,14.41,100,1,12.46,100,1,14.48,1400,2,12.43,700,1,14.5,100,1,12.42,700,1,14.54,700,1,ARL,378884757
2360,2025-07-17T16:44:54.915775814Z,2025-07-17T16:44:54.915775814Z,10,2,1108,A,A,2,13.73,100,130,165668,314082354,13.11,100,1,13.45,15,1,12.98,200,2,13.46,100,1,12.97,2,1,13.73,100,1,12.86,100,1,13.79,2,1,12.73,100,1,14.06,100,1,12.71,100,1,14.26,100,1,12.5,700,1,14.35,200,2,12.46,100,1,14.41,100,1,12.43,700,1,14.48,1400,2,12.42,700,1,14.5,100,1,ARL,379096113
2361,2025-07-17T16:44:54.946424043Z,2025-07-17T16:44:54.946424043Z,10,2,1108,A,A,5,14.25,100,130,165264,314082941,13.11,100,1,13.45,15,1,12.98,200,2,13.46,100,1,12.97,2,1,13.73,100,1,12.86,100,1,13.79,2,1,12.73,100,1,14.06,100,1,12.71,100,1,14.25,100,1,12.5,700,1,14.26,100,1,12.46,100,1,14.35,200,2,12.43,700,1,14.41,100,1,12.42,700,1,14.48,1400,2,ARL,379096805
2362,2025-07-17T16:44:54.966510936Z,2025-07-17T16:44:54.966510936Z,10,2,1108,A,A,8,14.41,100,130,165786,314083184,13.11,100,1,13.45,15,1,12.98,200,2,13.46,100,1,12.97,2,1,13.73,100,1,12.86,100,1,13.79,2,1,12.73,100,1,14.06,100,1,12.71,100,1,14.25,100,1,12.5,700,1,14.26,100,1,12.46,100,1,14.35,200,2,12.43,700,1,14.41,200,2,12.42,700,1,14.48,1400,2,ARL,379096981
2363,2025-07-17T16:44:55.300763037Z,2025-07-17T16:44:55.300763037Z,10,2,1108,A,A,6,14.26,100,130,165170,314089820,13.11,100,1,13.45,15,1,12.98,200,2,13.46,100,1,12.97,2,1,13.73,100,1,12.86,100,1,13.79,2,1,12.73,100,1,14.06,100,1,12.71,100,1,14.25,100,1,12.5,700,1,14.26,200,2,12.46,100,1,14.35,200,2,12.43,700,1,14.41,200,2,12.42,700,1,14.48,1400,2,ARL,379107445
2364,2025-07-17T16:44:59.834173908Z,2025-07-17T16:44:59.834173908Z,10,2,1108,A,A,5,14.18,700,130,165230,314166592,13.11,100,1,13.45,15,1,12.98,200,2,13.46,100,1,12.97,2,1,13.73,100,1,12.86,100,1,13.79,2,1,12.73,100,1,14.06,100,1,12.71,100,1,14.18,700,1,12.5,700,1,14.25,100,1,12.46,100,1,14.26,200,2,12.43,700,1,14.35,200,2,12.42,700,1,14.41,200,2,ARL,379214721
2365,2025-07-17T16:45:03.007238453Z,2025-07-17T16:45:03.007238453Z,10,2,1108,C,A,3,13.79,2,0,166382,314215324,13.11,100,1,13.45,15,1,12.98,200,2,13.46,100,1,12.97,2,1,13.73,100,1,12.86,100,1,14.06,100,1,12.73,100,1,14.18,700,1,12.71,100,1,14.25,100,1,12.5,700,1,14.26,200,2,12.46,100,1,14.35,200,2,12.43,700,1,14.41,200,2,12.42,700,1,14.48,1400,2,ARL,379095929
2366,2025-07-17T16:45:03.007238453Z,2025-07-17T16:45:03.007238453Z,10,2,1108,A,A,2,13.71,2,130,166382,314215324,13.11,100,1,13.45,15,1,12.98,200,2,13.46,100,1,12.97,2,1,13.71,2,1,12.86,100,1,13.73,100,1,12.73,100,1,14.06,100,1,12.71,100,1,14.18,700,1,12.5,700,1,14.25,100,1,12.46,100,1,14.26,200,2,12.43,700,1,14.35,200,2,12.42,700,1,14.41,200,2,ARL,379278349
2367,2025-07-17T16:45:27.018599302Z,2025-07-17T16:45:27.018599302Z,10,2,1108,A,A,2,13.49,100,130,165149,314585155,13.11,100,1,13.45,15,1,12.98,200,2,13.46,100,1,12.97,2,1,13.49,100,1,12.86,100,1,13.71,2,1,12.73,100,1,13.73,100,1,12.71,100,1,14.06,100,1,12.5,700,1,14.18,700,1,12.46,100,1,14.25,100,1,12.43,700,1,14.26,200,2,12.42,700,1,14.35,200,2,ARL,379736825
2368,2025-07-17T16:45:30.185938975Z,2025-07-17T16:45:30.185938975Z,10,2,1108,C,A,3,13.71,2,0,165564,314635721,13.11,100,1,13.45,15,1,12.98,200,2,13.46,100,1,12.97,2,1,13.49,100,1,12.86,100,1,13.73,100,1,12.73,100,1,14.06,100,1,12.71,100,1,14.18,700,1,12.5,700,1,14.25,100,1,12.46,100,1,14.26,200,2,12.43,700,1,14.35,200,2,12.42,700,1,14.41,200,2,ARL,379278349
2369,2025-07-17T16:45:30.185938975Z,2025-07-17T16:45:30.185938975Z,10,2,1108,A,A,3,13.65,2,130,165564,314635721,13.11,100,1,13.45,15,1,12.98,200,2,13.46,100,1,12.97,2,1,13.49,100,1,12.86,100,1,13.65,2,1,12.73,100,1,13.73,100,1,12.71,100,1,14.06,100,1,12.5,700,1,14.18,700,1,12.46,100,1,14.25,100,1,12.43,700,1,14.26,200,2,12.42,700,1,14.35,200,2,ARL,379801189
2370,2025-07-17T16:46:28.859642188Z,2025-07-17T16:46:28.859642188Z,10,2,1108,A,B,0,13.11,10,130,165325,315728525,13.11,110,2,13.45,15,1,12.98,200,2,13.46,100,1,12.97,2,1,13.49,100,1,12.86,100,1,13.65,2,1,12.73,100,1,13.73,100,1,12.71,100,1,14.06,100,1,12.5,700,1,14.18,700,1,12.46,100,1,14.25,100,1,12.43,700,1,14.26,200,2,12.42,700,1,14.35,200,2,ARL,381110009
2371,2025-07-17T16:46:36.884693968Z,2025-07-17T16:46:36.884693968Z,10,2,1108,C,B,0,13.11,10,130,165990,315927907,13.11,100,1,13.45,15,1,12.98,200,2,13.46,100,1,12.97,2,1,13.49,100,1,12.86,100,1,13.65,2,1,12.73,100,1,13.73,100,1,12.71,100,1,14.06,100,1,12.5,700,1,14.18,700,1,12.46,100,1,14.25,100,1,12.43,700,1,14.26,200,2,12.42,700,1,14.35,200,2,ARL,381110009
2372,2025-07-17T16:46:37.794540840Z,2025-07-17T16:46:37.794540840Z,10,2,1108,A,A,2,13.47,100,130,165202,315954210,13.11,100,1,13.45,15,1,12.98,200,2,13.46,100,1,12.97,2,1,13.47,100,1,12.86,100,1,13.49,100,1,12.73,100,1,13.65,2,1,12.71,100,1,13.73,100,1,12.5,700,1,14.06,100,1,12.46,100,1,14.18,700,1,12.43,700,1,14.25,100,1,12.42,700,1,14.26,200,2,ARL,381366917
2373,2025-07-17T16:46:37.801930526Z,2025-07-17T16:46:37.801930526Z,10,2,1108,C,A,3,13.49,100,130,165354,315954275,13.11,100,1,13.45,15,1,12.98,200,2,13.46,100,1,12.97,2,1,13.47,100,1,12.86,100,1,13.65,2,1,12.73,100,1,13.73,100,1,12.71,100,1,14.06,100,1,12.5,700,1,14.18,700,1,12.46,100,1,14.25,100,1,12.43,700,1,14.26,200,2,12.42,700,1,14.35,200,2,ARL,379736825
2374,2025-07-17T16:46:38.884538478Z,2025-07-17T16:46:38.884538478Z,10,2,1108,A,A,0,13.43,15,130,165212,315968206,13.11,100,1,13.43,15,1,12.98,200,2,13.45,15,1,12.97,2,1,13.46,100,1,12.86,100,1,13.47,100,1,12.73,100,1,13.65,2,1,12.71,100,1,13.73,100,1,12.5,700,1,14.06,100,1,12.46,100,1,14.18,700,1,12.43,700,1,14.25,100,1,12.42,700,1,14.26,200,2,ARL,381385565
2375,2025-07-17T16:46:39.214664841Z,2025-07-17T16:46:39.214664841Z,10,2,1108,C,A,2,13.46,100,0,165437,315973473,13.11,100,1,13.43,15,1,12.98,200,2,13.45,15,1,12.97,2,1,13.47,100,1,12.86,100,1,13.65,2,1,12.73,100,1,13.73,100,1,12.71,100,1,14.06,100,1,12.5,700,1,14.18,700,1,12.46,100,1,14.25,100,1,12.43,700,1,14.26,200,2,12.42,700,1,14.35,200,2,ARL,379095909
2376,2025-07-17T16:46:39.214664841Z,2025-07-17T16:46:39.214664841Z,10,2,1108,A,A,1,13.44,100,130,165437,315973473,13.11,100,1,13.43,15,1,12.98,200,2,13.44,100,1,12.97,2,1,13.45,15,1,12.86,100,1,13.47,100,1,12.73,100,1,13.65,2,1,12.71,100,1,13.73,100,1,12.5,700,1,14.06,100,1,12.46,100,1,14.18,700,1,12.43,700,1,14.25,100,1,12.42,700,1,14.26,200,2,ARL,381389921
2377,2025-07-17T16:46:39.495672905Z,2025-07-17T16:46:39.495672905Z,10,2,1108,A,A,6,13.97,100,130,165231,315977251,13.11,100,1,13.43,15,1,12.98,200,2,13.44,100,1,12.97,2,1,13.45,15,1,12.86,100,1,13.47,100,1,12.73,100,1,13.65,2,1,12.71,100,1,13.73,100,1,12.5,700,1,13.97,100,1,12.46,100,1,14.06,100,1,12.43,700,1,14.18,700,1,12.42,700,1,14.25,100,1,ARL,381395205
2378,2025-07-17T16:47:10.013892892Z,2025-07-17T16:47:10.013892892Z,10,2,1108,C,A,1,13.44,100,130,165326,316423218,13.11,100,1,13.43,15,1,12.98,200,2,13.45,15,1,12.97,2,1,13.47,100,1,12.86,100,1,13.65,2,1,12.73,100,1,13.73,100,1,12.71,100,1,13.97,100,1,12.5,700,1,14.06,100,1,12.46,100,1,14.18,700,1,12.43,700,1,14.25,100,1,12.42,700,1,14.26,100,1,ARL,381389921
2379,2025-07-17T16:47:10.015510357Z,2025-07-17T16:47:10.015510357Z,10,2,1108,C,A,1,13.45,15,130,165205,316423231,13.11,100,1,13.43,15,1,12.98,200,2,13.47,100,1,12.97,2,1,13.65,2,1,12.86,100,1,13.73,100,1,12.73,100,1,13.97,100,1,12.71,100,1,14.06,100,1,12.5,700,1,14.18,700,1,12.46,100,1,14.25,100,1,12.43,700,1,14.26,100,1,12.42,700,1,14.35,200,2,ARL,379094717
2380,2025-07-17T16:47:11.017528057Z,2025-07-17T16:47:11.017528057Z,10,2,1108,A,A,0,13.4,15,130,165344,316439018,13.11,100,1,13.4,15,1,12.98,200,2,13.43,15,1,12.97,2,1,13.47,100,1,12.86,100,1,13.65,2,1,12.73,100,1,13.73,100,1,12.71,100,1,13.97,100,1,12.5,700,1,14.06,100,1,12.46,100,1,14.18,700,1,12.43,700,1,14.25,100,1,12.42,700,1,14.26,100,1,ARL,381931621
2381,2025-07-17T16:47:11.276507069Z,2025-07-17T16:47:11.276507069Z,10,2,1108,A,A,2,13.44,100,130,165165,316442554,13.11,100,1,13.4,15,1,12.98,200,2,13.43,15,1,12.97,2,1,13.44,100,1,12.86,100,1,13.47,100,1,12.73,100,1,13.65,2,1,12.71,100,1,13.73,100,1,12.5,700,1,13.97,100,1,12.46,100,1,14.06,100,1,12.43,700,1,14.18,700,1,12.42,700,1,14.25,100,1,ARL,381937585
2382,2025-07-17T16:47:20.734111066Z,2025-07-17T16:47:20.734111066Z,10,2,1108,C,A,0,13.4,15,130,165393,316605363,13.11,100,1,13.43,15,1,12.98,200,2,13.44,100,1,12.97,2,1,13.47,100,1,12.86,100,1,13.65,2,1,12.73,100,1,13.73,100,1,12.71,100,1,13.97,100,1,12.5,700,1,14.06,100,1,12.46,100,1,14.18,700,1,12.43,700,1,14.25,100,1,12.42,700,1,14.26,100,1,ARL,381931621
2383,2025-07-17T16:47:20.735283296Z,2025-07-17T16:47:20.735283296Z,10,2,1108,C,A,0,13.43,15,130,165219,316605399,13.11,100,1,13.44,100,1,12.98,200,2,13.47,100,1,12.97,2,1,13.65,2,1,12.86,100,1,13.73,100,1,12.73,100,1,13.97,100,1,12.71,100,1,14.06,100,1,12.5,700,1,14.18,700,1,12.46,100,1,14.25,100,1,12.43,700,1,14.26,100,1,12.42,700,1,14.35,200,2,ARL,381385565
2384,2025-07-17T16:47:39.209310686Z,2025-07-17T16:47:39.209310686Z,10,2,1108,A,A,0,13.39,15,130,165232,316885657,13.11,100,1,13.39,15,1,12.98,200,2,13.44,100,1,12.97,2,1,13.47,100,1,12.86,100,1,13.65,2,1,12.73,100,1,13.73,100,1,12.71,100,1,13.97,100,1,12.5,700,1,14.06,100,1,12.46,100,1,14.18,700,1,12.43,700,1,14.25,100,1,12.42,700,1,14.26,100,1,ARL,382444445
2385,2025-07-17T16:47:46.798089272Z,2025-07-17T16:47:46.798089272Z,10,2,1108,C,A,2,13.47,100,130,165361,316999429,13.11,100,1,13.39,15,1,12.98,200,2,13.44,100,1,12.97,2,1,13.65,2,1,12.86,100,1,13.73,100,1,12.73,100,1,13.97,100,1,12.71,100,1,14.06,100,1,12.5,700,1,14.18,700,1,12.46,100,1,14.25,100,1,12.43,700,1,14.26,100,1,12.42,700,1,14.35,200,2,ARL,381366917
2386,2025-07-17T16:47:46.799129468Z,2025-07-17T16:47:46.799129468Z,10,2,1108,A,A,0,13.37,15,130,165509,316999432,13.11,100,1,13.37,15,1,12.98,200,2,13.39,15,1,12.97,2,1,13.44,100,1,12.86,100,1,13.65,2,1,12.73,100,1,13.73,100,1,12.71,100,1,13.97,100,1,12.5,700,1,14.06,100,1,12.46,100,1,14.18,700,1,12.43,700,1,14.25,100,1,12.42,700,1,14.26,100,1,ARL,382585849
2387,2025-07-17T16:47:56.799193045Z,2025-07-17T16:47:56.799193045Z,10,2,1108,C,A,1,13.39,15,130,165947,317127138,13.11,100,1,13.37,15,1,12.98,200,2,13.44,100,1,12.97,2,1,13.65,2,1,12.86,100,1,13.73,100,1,12.73,100,1,13.97,100,1,12.71,100,1,14.06,100,1,12.5,700,1,14.18,700,1,12.46,100,1,14.25,100,1,12.43,700,1,14.26,100,1,12.42,700,1,14.35,200,2,ARL,382444445
2388,2025-07-17T16:48:45.976405116Z,2025-07-17T16:48:45.976405116Z,10,2,1108,A,A,0,13.35,15,130,165394,317969792,13.11,100,1,13.35,15,1,12.98,200,2,13.37,15,1,12.97,2,1,13.44,100,1,12.86,100,1,13.65,2,1,12.73,100,1,13.73,100,1,12.71,100,1,13.97,100,1,12.5,700,1,14.06,100,1,12.46,100,1,14.18,700,1,12.43,700,1,14.25,100,1,12.42,700,1,14.26,100,1,ARL,383773141
2389,2025-07-17T16:49:41.077352984Z,2025-07-17T16:49:41.077352984Z,10,2,1108,C,A,1,13.37,15,130,165302,318962185,13.11,100,1,13.35,15,1,12.98,200,2,13.44,100,1,12.97,2,1,13.65,2,1,12.86,100,1,13.73,100,1,12.73,100,1,13.97,100,1,12.71,100,1,14.06,100,1,12.5,700,1,14.18,700,1,12.46,100,1,14.25,100,1,12.43,700,1,14.26,100,1,12.42,700,1,14.35,200,2,ARL,382585849
2390,2025-07-17T16:49:42.080880890Z,2025-07-17T16:49:42.080880890Z,10,2,1108,A,A,0,13.33,15,130,165429,318972429,13.11,100,1,13.33,15,1,12.98,200,2,13.35,15,1,12.97,2,1,13.44,100,1,12.86,100,1,13.65,2,1,12.73,100,1,13.73,100,1,12.71,100,1,13.97,100,1,12.5,700,1,14.06,100,1,12.46,100,1,14.18,700,1,12.43,700,1,14.25,100,1,12.42,700,1,14.26,100,1,ARL,384964609
2391,2025-07-17T16:49:42.080966181Z,2025-07-17T16:49:42.080966181Z,10,2,1108,A,A,8,14.23,100,130,165502,318972430,13.11,100,1,13.33,15,1,12.98,200,2,13.35,15,1,12.97,2,1,13.44,100,1,12.86,100,1,13.65,2,1,12.73,100,1,13.73,100,1,12.71,100,1,13.97,100,1,12.5,700,1,14.06,100,1,12.46,100,1,14.18,700,1,12.43,700,1,14.23,100,1,12.42,700,1,14.25,100,1,ARL,384964613
2392,2025-07-17T16:49:42.081026152Z,2025-07-17T16:49:42.081026152Z,10,2,1108,A,A,8,14.23,100,130,165626,318972432,13.11,100,1,13.33,15,1,12.98,200,2,13.35,15,1,12.97,2,1,13.44,100,1,12.86,100,1,13.65,2,1,12.73,100,1,13.73,100,1,12.71,100,1,13.97,100,1,12.5,700,1,14.06,100,1,12.46,100,1,14.18,700,1,12.43,700,1,14.23,200,2,12.42,700,1,14.25,100,1,ARL,384964617
2393,2025-07-17T16:50:35.554910694Z,2025-07-17T16:50:35.554910694Z,10,2,1108,C,A,0,13.33,15,130,167360,319771042,13.11,100,1,13.35,15,1,12.98,200,2,13.44,100,1,12.97,2,1,13.65,2,1,12.86,100,1,13.73,100,1,12.73,100,1,13.97,100,1,12.71,100,1,14.06,100,1,12.5,700,1,14.18,700,1,12.46,100,1,14.23,200,2,12.43,700,1,14.25,100,1,12.42,700,1,14.26,100,1,ARL,384964609
2394,2025-07-17T16:50:35.568627090Z,2025-07-17T16:50:35.568627090Z,10,2,1108,C,A,0,13.35,15,130,169996,319772565,13.11,100,1,13.44,100,1,12.98,200,2,13.65,2,1,12.97,2,1,13.73,100,1,12.86,100,1,13.97,100,1,12.73,100,1,14.06,100,1,12.71,100,1,14.18,700,1,12.5,700,1,14.23,200,2,12.46,100,1,14.25,100,1,12.43,700,1,14.26,100,1,12.42,700,1,14.41,200,2,ARL,383773141
2395,2025-07-17T16:50:37.518305138Z,2025-07-17T16:50:37.518305138Z,10,2,1108,A,A,0,13.33,15,130,166701,319815357,13.11,100,1,13.33,15,1,12.98,200,2,13.44,100,1,12.97,2,1,13.65,2,1,12.86,100,1,13.73,100,1,12.73,100,1,13.97,100,1,12.71,100,1,14.06,100,1,12.5,700,1,14.18,700,1,12.46,100,1,14.23,200,2,12.43,700,1,14.25,100,1,12.42,700,1,14.26,100,1,ARL,386002397
2396,2025-07-17T16:50:50.893077384Z,2025-07-17T16:50:50.893077384Z,10,2,1108,A,A,0,13.31,15,130,165746,320022719,13.11,100,1,13.31,15,1,12.98,200,2,13.33,15,1,12.97,2,1,13.44,100,1,12.86,100,1,13.65,2,1,12.73,100,1,13.73,100,1,12.71,100,1,13.97,100,1,12.5,700,1,14.06,100,1,12.46,100,1,14.18,700,1,12.43,700,1,14.23,200,2,12.42,700,1,14.25,100,1,ARL,386239877
2397,2025-07-17T16:51:49.202985817Z,2025-07-17T16:51:49.202985817Z,10,2,1108,T,B,0,13.11,100,130,166096,320804609,12.98,200,2,13.31,15,1,12.97,2,1,13.33,15,1,12.86,100,1,13.44,100,1,12.73,100,1,13.65,2,1,12.71,100,1,13.73,100,1,12.5,700,1,13.97,100,1,12.46,100,1,14.06,100,1,12.43,700,1,14.18,700,1,12.42,700,1,14.23,200,2,12.37,700,1,14.25,100,1,ARL,326158877
2397,2025-07-17T16:51:49.203017730Z,2025-07-17T16:51:49.203017730Z,10,2,1108,A,A,0,13.27,12,130,165349,320804610,12.98,200,2,13.27,12,1,12.97,2,1,13.31,15,1,12.86,100,1,13.33,15,1,12.73,100,1,13.44,100,1,12.71,100,1,13.65,2,1,12.5,700,1,13.73,100,1,12.46,100,1,13.97,100,1,12.43,700,1,14.06,100,1,12.42,700,1,14.18,700,1,12.37,700,1,14.23,200,2,ARL,387208141
2398,2025-07-17T16:51:49.203297464Z,2025-07-17T16:51:49.203297464Z,10,2,1108,A,A,8,14.18,700,130,165256,320804615,12.98,200,2,13.27,12,1,12.97,2,1,13.31,15,1,12.86,100,1,13.33,15,1,12.73,100,1,13.44,100,1,12.71,100,1,13.65,2,1,12.5,700,1,13.73,100,1,12.46,100,1,13.97,100,1,12.43,700,1,14.06,100,1,12.42,700,1,14.18,1400,2,12.37,700,1,14.23,200,2,ARL,387208149
2399,2025-07-17T16:51:49.203325727Z,2025-07-17T16:51:49.203325727Z,10,2,1108,C,B,0,12.98,100,130,165580,320804616,12.98,100,1,13.27,12,1,12.97,2,1,13.31,15,1,12.86,100,1,13.33,15,1,12.73,100,1,13.44,100,1,12.71,100,1,13.65,2,1,12.5,700,1,13.73,100,1,12.46,100,1,13.97,100,1,12.43,700,1,14.06,100,1,12.42,700,1,14.18,1400,2,12.37,700,1,14.23,200,2,ARL,328489377
2400,2025-07-17T16:51:49.203327079Z,2025-07-17T16:51:49.203327079Z,10,2,1108,C,B,0,12.98,100,130,165376,320804617,12.97,2,1,13.27,12,1,12.86,100,1,13.31,15,1,12.73,100,1,13.33,15,1,12.71,100,1,13.44,100,1,12.5,700,1,13.65,2,1,12.46,100,1,13.73,100,1,12.43,700,1,13.97,100,1,12.42,700,1,14.06,100,1,12.37,700,1,14.18,1400,2,12.33,100,1,14.23,200,2,ARL,328489385
2401,2025-07-17T16:51:49.203372483Z,2025-07-17T16:51:49.203372483Z,10,2,1108,C,B,8,12.37,700,130,165566,320804619,12.97,2,1,13.27,12,1,12.86,100,1,13.31,15,1,12.73,100,1,13.33,15,1,12.71,100,1,13.44,100,1,12.5,700,1,13.65,2,1,12.46,100,1,13.73,100,1,12.43,700,1,13.97,100,1,12.42,700,1,14.06,100,1,12.33,100,1,14.18,1400,2,12.22,200,2,14.23,200,2,ARL,45025165
2402,2025-07-17T16:51:49.203373534Z,2025-07-17T16:51:49.203373534Z,10,2,1108,C,B,6,12.43,700,130,165536,320804620,12.97,2,1,13.27,12,1,12.86,100,1,13.31,15,1,12.73,100,1,13.33,15,1,12.71,100,1,13.44,100,1,12.5,700,1,13.65,2,1,12.46,100,1,13.73,100,1,12.42,700,1,13.97,100,1,12.33,100,1,14.06,100,1,12.22,200,2,14.18,1400,2,12.2,200,2,14.23,200,2,ARL,47383873
2403,2025-07-17T16:51:49.203417555Z,2025-07-17T16:51:49.203417555Z,10,2,1108,A,B,9,12.21,700,130,165365,320804621,12.97,2,1,13.27,12,1,12.86,100,1,13.31,15,1,12.73,100,1,13.33,15,1,12.71,100,1,13.44,100,1,12.5,700,1,13.65,2,1,12.46,100,1,13.73,100,1,12.42,700,1,13.97,100,1,12.33,100,1,14.06,100,1,12.22,200,2,14.18,1400,2,12.21,700,1,14.23,200,2,ARL,387208153
2404,2025-07-17T16:51:49.203728024Z,2025-07-17T16:51:49.203728024Z,10,2,1108,C,B,3,12.71,100,130,165746,320804626,12.97,2,1,13.27,12,1,12.86,100,1,13.31,15,1,12.73,100,1,13.33,15,1,12.5,700,1,13.44,100,1,12.46,100,1,13.65,2,1,12.42,700,1,13.73,100,1,12.33,100,1,13.97,100,1,12.22,200,2,14.06,100,1,12.21,700,1,14.18,1400,2,12.2,200,2,14.23,200,2,ARL,285586093
2405,2025-07-17T16:51:49.204082713Z,2025-07-17T16:51:49.204082713Z,10,2,1108,A,B,7,12.29,100,130,165292,320804630,12.97,2,1,13.27,12,1,12.86,100,1,13.31,15,1,12.73,100,1,13.33,15,1,12.5,700,1,13.44,100,1,12.46,100,1,13.65,2,1,12.42,700,1,13.73,100,1,12.33,100,1,13.97,100,1,12.29,100,1,14.06,100,1,12.22,200,2,14.18,1400,2,12.21,700,1,14.23,200,2,ARL,387208173
2406,2025-07-17T16:51:49.204097932Z,2025-07-17T16:51:49.204097932Z,10,2,1108,C,B,5,12.42,700,130,165358,320804631,12.97,2,1,13.27,12,1,12.86,100,1,13.31,15,1,12.73,100,1,13.33,15,1,12.5,700,1,13.44,100,1,12.46,100,1,13.65,2,1,12.33,100,1,13.73,100,1,12.29,100,1,13.97,100,1,12.22,200,2,14.06,100,1,12.21,700,1,14.18,1400,2,12.2,200,2,14.23,200,2,ARL,44720357
2407,2025-07-17T16:51:49.204850120Z,2025-07-17T16:51:49.204850120Z,10,2,1108,C,B,9,12.2,100,0,165533,320804636,12.97,2,1,13.27,12,1,12.86,100,1,13.31,15,1,12.73,100,1,13.33,15,1,12.5,700,1,13.44,100,1,12.46,100,1,13.65,2,1,12.33,100,1,13.73,100,1,12.29,100,1,13.97,100,1,12.22,200,2,14.06,100,1,12.21,700,1,14.18,1400,2,12.2,100,1,14.23,200,2,ARL,327112385
2408,2025-07-17T16:51:49.204893061Z,2025-07-17T16:51:49.204893061Z,10,2,1108,C,B,9,12.2,100,0,165412,320804638,12.97,2,1,13.27,12,1,12.86,100,1,13.31,15,1,12.73,100,1,13.33,15,1,12.5,700,1,13.44,100,1,12.46,100,1,13.65,2,1,12.33,100,1,13.73,100,1,12.29,100,1,13.97,100,1,12.22,200,2,14.06,100,1,12.21,700,1,14.18,1400,2,12.18,700,1,14.23,200,2,ARL,327112393
2409,2025-07-17T16:51:49.205347703Z,2025-07-17T16:51:49.205347703Z,10,2,1108,C,B,5,12.33,100,0,165638,320804639,12.97,2,1,13.27,12,1,12.86,100,1,13.31,15,1,12.73,100,1,13.33,15,1,12.5,700,1,13.44,100,1,12.46,100,1,13.65,2,1,12.29,100,1,13.73,100,1,12.22,200,2,13.97,100,1,12.21,700,1,14.06,100,1,12.18,700,1,14.18,1400,2,12.15,700,1,14.23,200,2,ARL,327114465
2410,2025-07-17T16:51:49.207976677Z,2025-07-17T16:51:49.207976677Z,10,2,1108,C,A,2,13.33,15,130,165260,320804643,12.97,2,1,13.27,12,1,12.86,100,1,13.31,15,1,12.73,100,1,13.44,100,1,12.5,700,1,13.65,2,1,12.46,100,1,13.73,100,1,12.29,100,1,13.97,100,1,12.22,200,2,14.06,100,1,12.21,700,1,14.18,1400,2,12.18,700,1,14.23,200,2,12.15,700,1,14.25,100,1,ARL,386002397
2411,2025-07-17T16:51:49.209264359Z,2025-07-17T16:51:49.209264359Z,10,2,1108,C,B,0,12.97,2,0,165442,320804652,12.86,100,1,13.27,12,1,12.73,100,1,13.31,15,1,12.5,700,1,13.44,100,1,12.46,100,1,13.65,2,1,12.29,100,1,13.73,100,1,12.22,200,2,13.97,100,1,12.21,700,1,14.06,100,1,12.18,700,1,14.18,1400,2,12.15,700,1,14.23,200,2,12.08,100,1,14.25,100,1,ARL,378976465
2412,2025-07-17T16:51:49.209264359Z,2025-07-17T16:51:49.209264359Z,10,2,1108,A,B,0,12.86,2,130,165442,320804652,12.86,102,2,13.27,12,1,12.73,100,1,13.31,15,1,12.5,700,1,13.44,100,1,12.46,100,1,13.65,2,1,12.29,100,1,13.73,100,1,12.22,200,2,13.97,100,1,12.21,700,1,14.06,100,1,12.18,700,1,14.18,1400,2,12.15,700,1,14.23,200,2,12.08,100,1,14.25,100,1,ARL,387208221
2413,2025-07-17T16:51:49.227895926Z,2025-07-17T16:51:49.227895926Z,10,2,1108,C,B,0,12.86,100,130,165588,320804783,12.86,2,1,13.27,12,1,12.73,100,1,13.31,15,1,12.5,700,1,13.44,100,1,12.46,100,1,13.65,2,1,12.29,100,1,13.73,100,1,12.22,200,2,13.97,100,1,12.21,700,1,14.06,100,1,12.18,700,1,14.18,1400,2,12.15,700,1,14.23,200,2,12.08,100,1,14.25,100,1,ARL,327112577
2414,2025-07-17T16:51:49.227918298Z,2025-07-17T16:51:49.227918298Z,10,2,1108,C,A,0,13.27,12,130,165095,320804784,12.86,2,1,13.31,15,1,12.73,100,1,13.44,100,1,12.5,700,1,13.65,2,1,12.46,100,1,13.73,100,1,12.29,100,1,13.97,100,1,12.22,200,2,14.06,100,1,12.21,700,1,14.18,1400,2,12.18,700,1,14.23,200,2,12.15,700,1,14.25,100,1,12.08,100,1,14.26,100,1,ARL,387208141
2415,2025-07-17T16:51:49.227950521Z,2025-07-17T16:51:49.227950521Z,10,2,1108,A,B,2,12.72,100,130,165313,320804785,12.86,2,1,13.31,15,1,12.73,100,1,13.44,100,1,12.72,100,1,13.65,2,1,12.5,700,1,13.73,100,1,12.46,100,1,13.97,100,1,12.29,100,1,14.06,100,1,12.22,200,2,14.18,1400,2,12.21,700,1,14.23,200,2,12.18,700,1,14.25,100,1,12.15,700,1,14.26,100,1,ARL,387208393
2416,2025-07-17T16:51:49.228027215Z,2025-07-17T16:51:49.228027215Z,10,2,1108,A,A,1,13.35,100,130,165075,320804787,12.86,2,1,13.31,15,1,12.73,100,1,13.35,100,1,12.72,100,1,13.44,100,1,12.5,700,1,13.65,2,1,12.46,100,1,13.73,100,1,12.29,100,1,13.97,100,1,12.22,200,2,14.06,100,1,12.21,700,1,14.18,1400,2,12.18,700,1,14.23,200,2,12.15,700,1,14.25,100,1,ARL,387208401
2417,2025-07-17T16:51:49.228776421Z,2025-07-17T16:51:49.228776421Z,10,2,1108,C,B,2,12.72,100,130,164940,320804797,12.86,2,1,13.31,15,1,12.73,100,1,13.35,100,1,12.5,700,1,13.44,100,1,12.46,100,1,13.65,2,1,12.29,100,1,13.73,100,1,12.22,200,2,13.97,100,1,12.21,700,1,14.06,100,1,12.18,700,1,14.18,1400,2,12.15,700,1,14.23,200,2,12.08,100,1,14.25,100,1,ARL,387208393
2418,2025-07-17T16:51:49.228824994Z,2025-07-17T16:51:49.228824994Z,10,2,1108,A,B,2,12.6,100,130,165157,320804800,12.86,2,1,13.31,15,1,12.73,100,1,13.35,100,1,12.6,100,1,13.44,100,1,12.5,700,1,13.65,2,1,12.46,100,1,13.73,100,1,12.29,100,1,13.97,100,1,12.22,200,2,14.06,100,1,12.21,700,1,14.18,1400,2,12.18,700,1,14.23,200,2,12.15,700,1,14.25,100,1,ARL,387208445
2419,2025-07-17T16:51:49.229017895Z,2025-07-17T16:51:49.229017895Z,10,2,1108,C,B,3,12.5,700,130,165208,320804802,12.86,2,1,13.31,15,1,12.73,100,1,13.35,100,1,12.6,100,1,13.44,100,1,12.46,100,1,13.65,2,1,12.29,100,1,13.73,100,1,12.22,200,2,13.97,100,1,12.21,700,1,14.06,100,1,12.18,700,1,14.18,1400,2,12.15,700,1,14.23,200,2,12.08,100,1,14.25,100,1,ARL,216223005
2420,2025-07-17T16:51:49.247917413Z,2025-07-17T16:51:49.247917413Z,10,2,1108,C,B,2,12.6,100,130,165039,320804925,12.86,2,1,13.31,15,1,12.73,100,1,13.35,100,1,12.46,100,1,13.44,100,1,12.29,100,1,13.65,2,1,12.22,200,2,13.73,100,1,12.21,700,1,13.97,100,1,12.18,700,1,14.06,100,1,12.15,700,1,14.18,1400,2,12.08,100,1,14.23,200,2,11.97,100,1,14.25,100,1,ARL,387208445
2421,2025-07-17T16:51:49.247956413Z,2025-07-17T16:51:49.247956413Z,10,2,1108,C,A,4,13.73,100,130,165288,320804926,12.86,2,1,13.31,15,1,12.73,100,1,13.35,100,1,12.46,100,1,13.44,100,1,12.29,100,1,13.65,2,1,12.22,200,2,13.97,100,1,12.21,700,1,14.06,100,1,12.18,700,1,14.18,1400,2,12.15,700,1,14.23,200,2,12.08,100,1,14.25,100,1,11.97,100,1,14.26,100,1,ARL,379096113
2422,2025-07-17T16:51:49.247966903Z,2025-07-17T16:51:49.247966903Z,10,2,1108,A,B,2,12.48,100,130,165118,320804927,12.86,2,1,13.31,15,1,12.73,100,1,13.35,100,1,12.48,100,1,13.44,100,1,12.46,100,1,13.65,2,1,12.29,100,1,13.97,100,1,12.22,200,2,14.06,100,1,12.21,700,1,14.18,1400,2,12.18,700,1,14.23,200,2,12.15,700,1,14.25,100,1,12.08,100,1,14.26,100,1,ARL,387208693
2423,2025-07-17T16:51:49.248005919Z,2025-07-17T16:51:49.248005919Z,10,2,1108,A,A,3,13.62,100,130,165158,320804928,12.86,2,1,13.31,15,1,12.73,100,1,13.35,100,1,12.48,100,1,13.44,100,1,12.46,100,1,13.62,100,1,12.29,100,1,13.65,2,1,12.22,200,2,13.97,100,1,12.21,700,1,14.06,100,1,12.18,700,1,14.18,1400,2,12.15,700,1,14.23,200,2,12.08,100,1,14.25,100,1,ARL,387208697
2424,2025-07-17T16:51:49.486638813Z,2025-07-17T16:51:49.486638813Z,10,2,1108,C,B,3,12.46,100,130,165371,320807856,12.86,2,1,13.31,15,1,12.73,100,1,13.35,100,1,12.48,100,1,13.44,100,1,12.29,100,1,13.62,100,1,12.22,200,2,13.65,2,1,12.21,700,1,13.97,100,1,12.18,700,1,14.06,100,1,12.15,700,1,14.18,1400,2,12.08,100,1,14.23,200,2,11.97,100,1,14.25,100,1,ARL,43804025
2425,2025-07-17T16:51:49.800370631Z,2025-07-17T16:51:49.800370631Z,10,2,1108,C,B,1,12.73,100,130,165436,320817705,12.86,2,1,13.31,15,1,12.48,100,1,13.35,100,1,12.29,100,1,13.44,100,1,12.22,200,2,13.62,100,1,12.21,700,1,13.65,2,1,12.18,700,1,13.97,100,1,12.15,700,1,14.06,100,1,12.08,100,1,14.18,1400,2,11.97,100,1,14.23,200,2,11.95,200,2,14.25,100,1,ARL,44066409
2426,2025-07-17T16:51:49.800372140Z,2025-07-17T16:51:49.800372140Z,10,2,1108,A,B,3,12.22,100,130,165233,320817706,12.86,2,1,13.31,15,1,12.48,100,1,13.35,100,1,12.29,100,1,13.44,100,1,12.22,300,3,13.62,100,1,12.21,700,1,13.65,2,1,12.18,700,1,13.97,100,1,12.15,700,1,14.06,100,1,12.08,100,1,14.18,1400,2,11.97,100,1,14.23,200,2,11.95,200,2,14.25,100,1,ARL,387224049
2427,2025-07-17T16:51:49.800684387Z,2025-07-17T16:51:49.800684387Z,10,2,1108,C,B,4,12.21,700,130,165357,320817711,12.86,2,1,13.31,15,1,12.48,100,1,13.35,100,1,12.29,100,1,13.44,100,1,12.22,300,3,13.62,100,1,12.18,700,1,13.65,2,1,12.15,700,1,13.97,100,1,12.08,100,1,14.06,100,1,11.97,100,1,14.18,1400,2,11.95,200,2,14.23,200,2,11.9,700,1,14.25,100,1,ARL,387208153
2428,2025-07-17T16:51:49.800726814Z,2025-07-17T16:51:49.800726814Z,10,2,1108,A,B,7,12.04,700,130,165337,320817712,12.86,2,1,13.31,15,1,12.48,100,1,13.35,100,1,12.29,100,1,13.44,100,1,12.22,300,3,13.62,100,1,12.18,700,1,13.65,2,1,12.15,700,1,13.97,100,1,12.08,100,1,14.06,100,1,12.04,700,1,14.18,1400,2,11.97,100,1,14.23,200,2,11.95,200,2,14.25,100,1,ARL,387224057
2429,2025-07-17T16:51:49.802991246Z,2025-07-17T16:51:49.802991246Z,10,2,1108,C,B,9,11.95,100,0,165324,320817732,12.86,2,1,13.31,15,1,12.48,100,1,13.35,100,1,12.29,100,1,13.44,100,1,12.22,300,3,13.62,100,1,12.18,700,1,13.65,2,1,12.15,700,1,13.97,100,1,12.08,100,1,14.06,100,1,12.04,700,1,14.18,1400,2,11.97,100,1,14.23,200,2,11.95,100,1,14.25,100,1,ARL,387208189
2430,2025-07-17T16:51:49.859256253Z,2025-07-17T16:51:49.859256253Z,10,2,1108,C,B,9,11.95,100,0,165242,320818164,12.86,2,1,13.31,15,1,12.48,100,1,13.35,100,1,12.29,100,1,13.44,100,1,12.22,300,3,13.62,100,1,12.18,700,1,13.65,2,1,12.15,700,1,13.97,100,1,12.08,100,1,14.06,100,1,12.04,700,1,14.18,1400,2,11.97,100,1,14.23,200,2,11.9,700,1,14.25,100,1,ARL,387208197
2431,2025-07-17T16:51:49.859301062Z,2025-07-17T16:51:49.859301062Z,10,2,1108,C,B,5,12.15,700,0,165642,320818165,12.86,2,1,13.31,15,1,12.48,100,1,13.35,100,1,12.29,100,1,13.44,100,1,12.22,300,3,13.62,100,1,12.18,700,1,13.65,2,1,12.08,100,1,13.97,100,1,12.04,700,1,14.06,100,1,11.97,100,1,14.18,1400,2,11.9,700,1,14.23,200,2,11.79,200,2,14.25,100,1,ARL,387208157
2432,2025-07-17T16:51:49.859301512Z,2025-07-17T16:51:49.859301512Z,10,2,1108,C,B,6,12.04,700,130,165192,320818166,12.86,2,1,13.31,15,1,12.48,100,1,13.35,100,1,12.29,100,1,13.44,100,1,12.22,300,3,13.62,100,1,12.18,700,1,13.65,2,1,12.08,100,1,13.97,100,1,11.97,100,1,14.06,100,1,11.9,700,1,14.18,1400,2,11.79,200,2,14.23,200,2,11.76,100,1,14.25,100,1,ARL,387224057
2433,2025-07-17T16:51:49.859340670Z,2025-07-17T16:51:49.859340670Z,10,2,1108,A,B,8,11.85,700,130,165286,320818167,12.86,2,1,13.31,15,1,12.48,100,1,13.35,100,1,12.29,100,1,13.44,100,1,12.22,300,3,13.62,100,1,12.18,700,1,13.65,2,1,12.08,100,1,13.97,100,1,11.97,100,1,14.06,100,1,11.9,700,1,14.18,1400,2,11.85,700,1,14.23,200,2,11.79,200,2,14.25,100,1,ARL,387224445
2434,2025-07-17T16:51:49.859351324Z,2025-07-17T16:51:49.859351324Z,10,2,1108,A,B,9,11.79,700,130,165306,320818168,12.86,2,1,13.31,15,1,12.48,100,1,13.35,100,1,12.29,100,1,13.44,100,1,12.22,300,3,13.62,100,1,12.18,700,1,13.65,2,1,12.08,100,1,13.97,100,1,11.97,100,1,14.06,100,1,11.9,700,1,14.18,1400,2,11.85,700,1,14.23,200,2,11.79,900,3,14.25,100,1,ARL,387224449
2435,2025-07-17T16:51:49.859680717Z,2025-07-17T16:51:49.859680717Z,10,2,1108,C,B,0,12.86,2,0,165955,320818176,12.48,100,1,13.31,15,1,12.29,100,1,13.35,100,1,12.22,300,3,13.44,100,1,12.18,700,1,13.62,100,1,12.08,100,1,13.65,2,1,11.97,100,1,13.97,100,1,11.9,700,1,14.06,100,1,11.85,700,1,14.18,1400,2,11.79,900,3,14.23,200,2,11.76,100,1,14.25,100,1,ARL,387208221
2436,2025-07-17T16:51:49.859680717Z,2025-07-17T16:51:49.859680717Z,10,2,1108,A,B,0,12.48,2,130,165955,320818176,12.48,102,2,13.31,15,1,12.29,100,1,13.35,100,1,12.22,300,3,13.44,100,1,12.18,700,1,13.62,100,1,12.08,100,1,13.65,2,1,11.97,100,1,13.97,100,1,11.9,700,1,14.06,100,1,11.85,700,1,14.18,1400,2,11.79,900,3,14.23,200,2,11.76,100,1,14.25,100,1,ARL,387224461
2437,2025-07-17T16:51:49.859769986Z,2025-07-17T16:51:49.859769986Z,10,2,1108,C,B,1,12.29,100,130,165019,320818179,12.48,102,2,13.31,15,1,12.22,300,3,13.35,100,1,12.18,700,1,13.44,100,1,12.08,100,1,13.62,100,1,11.97,100,1,13.65,2,1,11.9,700,1,13.97,100,1,11.85,700,1,14.06,100,1,11.79,900,3,14.18,1400,2,11.76,100,1,14.23,200,2,11.69,100,1,14.25,100,1,ARL,387208173
2438,2025-07-17T16:51:49.859810002Z,2025-07-17T16:51:49.859810002Z,10,2,1108,C,B,2,12.18,700,130,165260,320818180,12.48,102,2,13.31,15,1,12.22,300,3,13.35,100,1,12.08,100,1,13.44,100,1,11.97,100,1,13.62,100,1,11.9,700,1,13.65,2,1,11.85,700,1,13.97,100,1,11.79,900,3,14.06,100,1,11.76,100,1,14.18,1400,2,11.69,100,1,14.23,200,2,11.57,200,2,14.25,100,1,ARL,387208181
2439,2025-07-17T16:51:49.860119158Z,2025-07-17T16:51:49.860119158Z,10,2,1108,A,B,4,11.92,100,130,165298,320818186,12.48,102,2,13.31,15,1,12.22,300,3,13.35,100,1,12.08,100,1,13.44,100,1,11.97,100,1,13.62,100,1,11.92,100,1,13.65,2,1,11.9,700,1,13.97,100,1,11.85,700,1,14.06,100,1,11.79,900,3,14.18,1400,2,11.76,100,1,14.23,200,2,11.69,100,1,14.25,100,1,ARL,387224477
2440,2025-07-17T16:51:49.860256159Z,2025-07-17T16:51:49.860256159Z,10,2,1108,A,B,7,11.82,700,130,165241,320818196,12.48,102,2,13.31,15,1,12.22,300,3,13.35,100,1,12.08,100,1,13.44,100,1,11.97,100,1,13.62,100,1,11.92,100,1,13.65,2,1,11.9,700,1,13.97,100,1,11.85,700,1,14.06,100,1,11.82,700,1,14.18,1400,2,11.79,900,3,14.23,200,2,11.76,100,1,14.25,100,1,ARL,387224481
2441,2025-07-17T16:51:49.861191695Z,2025-07-17T16:51:49.861191695Z,10,2,1108,C,B,8,11.79,100,0,165285,320818220,12.48,102,2,13.31,15,1,12.22,300,3,13.35,100,1,12.08,100,1,13.44,100,1,11.97,100,1,13.62,100,1,11.92,100,1,13.65,2,1,11.9,700,1,13.97,100,1,11.85,700,1,14.06,100,1,11.82,700,1,14.18,1400,2,11.79,800,2,14.23,200,2,11.76,100,1,14.25,100,1,ARL,387224105
2442,2025-07-17T16:51:49.866210978Z,2025-07-17T16:51:49.866210978Z,10,2,1108,C,B,0,12.48,100,130,165541,320818236,12.48,2,1,13.31,15,1,12.22,300,3,13.35,100,1,12.08,100,1,13.44,100,1,11.97,100,1,13.62,100,1,11.92,100,1,13.65,2,1,11.9,700,1,13.97,100,1,11.85,700,1,14.06,100,1,11.82,700,1,14.18,1400,2,11.79,800,2,14.23,200,2,11.76,100,1,14.25,100,1,ARL,387208693
2443,2025-07-17T16:51:49.866261553Z,2025-07-17T16:51:49.866261553Z,10,2,1108,A,B,1,12.23,100,130,165639,320818237,12.48,2,1,13.31,15,1,12.23,100,1,13.35,100,1,12.22,300,3,13.44,100,1,12.08,100,1,13.62,100,1,11.97,100,1,13.65,2,1,11.92,100,1,13.97,100,1,11.9,700,1,14.06,100,1,11.85,700,1,14.18,1400,2,11.82,700,1,14.23,200,2,11.79,800,2,14.25,100,1,ARL,387224537
2444,2025-07-17T16:51:49.883908795Z,2025-07-17T16:51:49.883908795Z,10,2,1108,C,B,9,11.79,100,0,165168,320818367,12.48,2,1,13.31,15,1,12.23,100,1,13.35,100,1,12.22,300,3,13.44,100,1,12.08,100,1,13.62,100,1,11.97,100,1,13.65,2,1,11.92,100,1,13.97,100,1,11.9,700,1,14.06,100,1,11.85,700,1,14.18,1400,2,11.82,700,1,14.23,200,2,11.79,700,1,14.25,100,1,ARL,387224437
2445,2025-07-17T16:51:50.208210239Z,2025-07-17T16:51:50.208210239Z,10,2,1108,C,B,3,12.08,100,130,165108,320822967,12.48,2,1,13.31,15,1,12.23,100,1,13.35,100,1,12.22,300,3,13.44,100,1,11.97,100,1,13.62,100,1,11.92,100,1,13.65,2,1,11.9,700,1,13.97,100,1,11.85,700,1,14.06,100,1,11.82,700,1,14.18,1400,2,11.79,700,1,14.23,200,2,11.76,100,1,14.25,100,1,ARL,387208201
2446,2025-07-17T16:51:50.698845651Z,2025-07-17T16:51:50.698845651Z,10,2,1108,A,A,0,13.29,15,130,165515,320827751,12.48,2,1,13.29,15,1,12.23,100,1,13.31,15,1,12.22,300,3,13.35,100,1,11.97,100,1,13.44,100,1,11.92,100,1,13.62,100,1,11.9,700,1,13.65,2,1,11.85,700,1,13.97,100,1,11.82,700,1,14.06,100,1,11.79,700,1,14.18,1400,2,11.76,100,1,14.23,200,2,ARL,387234697
2447,2025-07-17T16:51:51.700995710Z,2025-07-17T16:51:51.700995710Z,10,2,1108,A,A,2,13.33,100,130,165423,320835508,12.48,2,1,13.29,15,1,12.23,100,1,13.31,15,1,12.22,300,3,13.33,100,1,11.97,100,1,13.35,100,1,11.92,100,1,13.44,100,1,11.9,700,1,13.62,100,1,11.85,700,1,13.65,2,1,11.82,700,1,13.97,100,1,11.79,700,1,14.06,100,1,11.76,100,1,14.18,1400,2,ARL,387246049
2448,2025-07-17T16:51:51.713795931Z,2025-07-17T16:51:51.713795931Z,10,2,1108,A,A,9,14.11,100,130,165595,320835557,12.48,2,1,13.29,15,1,12.23,100,1,13.31,15,1,12.22,300,3,13.33,100,1,11.97,100,1,13.35,100,1,11.92,100,1,13.44,100,1,11.9,700,1,13.62,100,1,11.85,700,1,13.65,2,1,11.82,700,1,13.97,100,1,11.79,700,1,14.06,100,1,11.76,100,1,14.11,100,1,ARL,387246169
2449,2025-07-17T16:51:51.724992350Z,2025-07-17T16:51:51.724992350Z,10,2,1108,C,A,3,13.35,100,130,165438,320835691,12.48,2,1,13.29,15,1,12.23,100,1,13.31,15,1,12.22,300,3,13.33,100,1,11.97,100,1,13.44,100,1,11.92,100,1,13.62,100,1,11.9,700,1,13.65,2,1,11.85,700,1,13.97,100,1,11.82,700,1,14.06,100,1,11.79,700,1,14.11,100,1,11.76,100,1,14.18,1400,2,ARL,387208401
2450,2025-07-17T16:51:54.352829325Z,2025-07-17T16:51:54.352829325Z,10,2,1108,A,A,7,14.06,700,130,165656,320864203,12.48,2,1,13.29,15,1,12.23,100,1,13.31,15,1,12.22,300,3,13.33,100,1,11.97,100,1,13.44,100,1,11.92,100,1,13.62,100,1,11.9,700,1,13.65,2,1,11.85,700,1,13.97,100,1,11.82,700,1,14.06,800,2,11.79,700,1,14.11,100,1,11.76,100,1,14.18,1400,2,ARL,387277657
2451,2025-07-17T16:52:09.189496109Z,2025-07-17T16:52:09.189496109Z,10,2,1108,C,A,5,13.65,2,0,165831,321054296,12.48,2,1,13.29,15,1,12.23,100,1,13.31,15,1,12.22,300,3,13.33,100,1,11.97,100,1,13.44,100,1,11.92,100,1,13.62,100,1,11.9,700,1,13.97,100,1,11.85,700,1,14.06,800,2,11.82,700,1,14.11,100,1,11.79,700,1,14.18,1400,2,11.76,100,1,14.2,700,1,ARL,379801189
2452,2025-07-17T16:52:09.189496109Z,2025-07-17T16:52:09.189496109Z,10,2,1108,A,A,3,13.4,2,130,165831,321054296,12.48,2,1,13.29,15,1,12.23,100,1,13.31,15,1,12.22,300,3,13.33,100,1,11.97,100,1,13.4,2,1,11.92,100,1,13.44,100,1,11.9,700,1,13.62,100,1,11.85,700,1,13.97,100,1,11.82,700,1,14.06,800,2,11.79,700,1,14.11,100,1,11.76,100,1,14.18,1400,2,ARL,387521285
2453,2025-07-17T16:52:25.385796835Z,2025-07-17T16:52:25.385796835Z,10,2,1108,C,A,3,13.4,2,0,165648,321280124,12.48,2,1,13.29,15,1,12.23,100,1,13.31,15,1,12.22,300,3,13.33,100,1,11.97,100,1,13.44,100,1,11.92,100,1,13.62,100,1,11.9,700,1,13.97,100,1,11.85,700,1,14.06,800,2,11.82,700,1,14.11,100,1,11.79,700,1,14.18,1400,2,11.76,100,1,14.2,700,1,ARL,387521285
2454,2025-07-17T16:52:25.385796835Z,2025-07-17T16:52:25.385796835Z,10,2,1108,A,A,3,13.34,2,130,165648,321280124,12.48,2,1,13.29,15,1,12.23,100,1,13.31,15,1,12.22,300,3,13.33,100,1,11.97,100,1,13.34,2,1,11.92,100,1,13.44,100,1,11.9,700,1,13.62,100,1,11.85,700,1,13.97,100,1,11.82,700,1,14.06,800,2,11.79,700,1,14.11,100,1,11.76,100,1,14.18,1400,2,ARL,387814377
2455,2025-07-17T16:52:44.599769693Z,2025-07-17T16:52:44.599769693Z,10,2,1108,C,A,1,13.31,15,130,166793,321507803,12.48,2,1,13.29,15,1,12.23,100,1,13.33,100,1,12.22,300,3,13.34,2,1,11.97,100,1,13.44,100,1,11.92,100,1,13.62,100,1,11.9,700,1,13.97,100,1,11.85,700,1,14.06,800,2,11.82,700,1,14.11,100,1,11.79,700,1,14.18,1400,2,11.76,100,1,14.2,700,1,ARL,386239877
2456,2025-07-17T16:52:45.910353639Z,2025-07-17T16:52:45.910353639Z,10,2,1108,A,A,0,13.27,15,130,165383,321528658,12.48,2,1,13.27,15,1,12.23,100,1,13.29,15,1,12.22,300,3,13.33,100,1,11.97,100,1,13.34,2,1,11.92,100,1,13.44,100,1,11.9,700,1,13.62,100,1,11.85,700,1,13.97,100,1,11.82,700,1,14.06,800,2,11.79,700,1,14.11,100,1,11.76,100,1,14.18,1400,2,ARL,388154969
2457,2025-07-17T16:52:45.913010349Z,2025-07-17T16:52:45.913010349Z,10,2,1108,A,A,2,13.31,100,130,165135,321528927,12.48,2,1,13.27,15,1,12.23,100,1,13.29,15,1,12.22,300,3,13.31,100,1,11.97,100,1,13.33,100,1,11.92,100,1,13.34,2,1,11.9,700,1,13.44,100,1,11.85,700,1,13.62,100,1,11.82,700,1,13.97,100,1,11.79,700,1,14.06,800,2,11.76,100,1,14.11,100,1,ARL,388155109
2458,2025-07-17T16:52:45.915732713Z,2025-07-17T16:52:45.915732713Z,10,2,1108,C,A,3,13.33,100,130,165255,321528989,12.48,2,1,13.27,15,1,12.23,100,1,13.29,15,1,12.22,300,3,13.31,100,1,11.97,100,1,13.34,2,1,11.92,100,1,13.44,100,1,11.9,700,1,13.62,100,1,11.85,700,1,13.97,100,1,11.82,700,1,14.06,800,2,11.79,700,1,14.11,100,1,11.76,100,1,14.18,1400,2,ARL,387246049
2459,2025-07-17T16:53:02.591772327Z,2025-07-17T16:53:02.591772327Z,10,2,1108,C,A,3,13.34,2,0,165627,321769923,12.48,2,1,13.27,15,1,12.23,100,1,13.29,15,1,12.22,300,3,13.31,100,1,11.97,100,1,13.44,100,1,11.92,100,1,13.62,100,1,11.9,700,1,13.97,100,1,11.85,700,1,14.06,800,2,11.82,700,1,14.11,100,1,11.79,700,1,14.18,1400,2,11.76,100,1,14.2,700,1,ARL,387814377
2460,2025-07-17T16:53:02.591772327Z,2025-07-17T16:53:02.591772327Z,10,2,1108,A,A,2,13.31,2,130,165627,321769923,12.48,2,1,13.27,15,1,12.23,100,1,13.29,15,1,12.22,300,3,13.31,102,2,11.97,100,1,13.44,100,1,11.92,100,1,13.62,100,1,11.9,700,1,13.97,100,1,11.85,700,1,14.06,800,2,11.82,700,1,14.11,100,1,11.79,700,1,14.18,1400,2,11.76,100,1,14.2,700,1,ARL,388467165
2461,2025-07-17T16:53:04.318857617Z,2025-07-17T16:53:04.318857617Z,10,2,1108,C,A,0,13.27,15,128,169881,321820208,12.48,2,1,13.29,15,1,12.23,100,1,13.31,102,2,12.22,300,3,13.44,100,1,11.97,100,1,13.62,100,1,11.92,100,1,13.97,100,1,11.9,700,1,14.06,800,2,11.85,700,1,14.11,100,1,11.82,700,1,14.18,1400,2,11.79,700,1,14.2,700,1,11.76,100,1,14.23,200,2,ARL,388154969
2462,2025-07-17T16:53:04.327496343Z,2025-07-17T16:53:04.327496343Z,10,2,1108,C,A,0,13.29,15,130,165382,321823264,12.48,2,1,13.31,102,2,12.23,100,1,13.44,100,1,12.22,300,3,13.62,100,1,11.97,100,1,13.97,100,1,11.92,100,1,14.06,800,2,11.9,700,1,14.11,100,1,11.85,700,1,14.18,1400,2,11.82,700,1,14.2,700,1,11.79,700,1,14.23,200,2,11.76,100,1,14.26,100,1,ARL,387234697
2463,2025-07-17T16:53:05.349324407Z,2025-07-17T16:53:05.349324407Z,10,2,1108,A,A,0,13.27,15,130,165302,321852281,12.48,2,1,13.27,15,1,12.23,100,1,13.31,102,2,12.22,300,3,13.44,100,1,11.97,100,1,13.62,100,1,11.92,100,1,13.97,100,1,11.9,700,1,14.06,800,2,11.85,700,1,14.11,100,1,11.82,700,1,14.18,1400,2,11.79,700,1,14.2,700,1,11.76,100,1,14.23,200,2,ARL,388572113
2464,2025-07-17T16:53:06.896211496Z,2025-07-17T16:53:06.896211496Z,10,2,1108,C,A,0,13.27,15,130,165855,321876648,12.48,2,1,13.31,102,2,12.23,100,1,13.44,100,1,12.22,300,3,13.62,100,1,11.97,100,1,13.97,100,1,11.92,100,1,14.06,800,2,11.9,700,1,14.11,100,1,11.85,700,1,14.18,1400,2,11.82,700,1,14.2,700,1,11.79,700,1,14.23,200,2,11.76,100,1,14.26,100,1,ARL,388572113
2465,2025-07-17T16:53:26.171430778Z,2025-07-17T16:53:26.171430778Z,10,2,1108,C,A,0,13.31,100,130,165819,322130469,12.48,2,1,13.31,2,1,12.23,100,1,13.44,100,1,12.22,300,3,13.62,100,1,11.97,100,1,13.97,100,1,11.92,100,1,14.06,800,2,11.9,700,1,14.11,100,1,11.85,700,1,14.18,1400,2,11.82,700,1,14.2,700,1,11.79,700,1,14.23,200,2,11.76,100,1,14.26,100,1,ARL,388155109
2466,2025-07-17T16:53:26.190494051Z,2025-07-17T16:53:26.190494051Z,10,2,1108,C,A,2,13.62,100,130,165507,322130570,12.48,2,1,13.31,2,1,12.23,100,1,13.44,100,1,12.22,300,3,13.97,100,1,11.97,100,1,14.06,800,2,11.92,100,1,14.11,100,1,11.9,700,1,14.18,1400,2,11.85,700,1,14.2,700,1,11.82,700,1,14.23,200,2,11.79,700,1,14.26,100,1,11.76,100,1,14.27,200,2,ARL,387208697
2467,2025-07-17T16:53:26.190544047Z,2025-07-17T16:53:26.190544047Z,10,2,1108,A,A,2,13.71,100,130,165353,322130571,12.48,2,1,13.31,2,1,12.23,100,1,13.44,100,1,12.22,300,3,13.71,100,1,11.97,100,1,13.97,100,1,11.92,100,1,14.06,800,2,11.9,700,1,14.11,100,1,11.85,700,1,14.18,1400,2,11.82,700,1,14.2,700,1,11.79,700,1,14.23,200,2,11.76,100,1,14.26,100,1,ARL,388943785
2468,2025-07-17T16:53:30.899381745Z,2025-07-17T16:53:30.899381745Z,10,2,1108,A,A,0,13.25,15,130,165283,322188510,12.48,2,1,13.25,15,1,12.23,100,1,13.31,2,1,12.22,300,3,13.44,100,1,11.97,100,1,13.71,100,1,11.92,100,1,13.97,100,1,11.9,700,1,14.06,800,2,11.85,700,1,14.11,100,1,11.82,700,1,14.18,1400,2,11.79,700,1,14.2,700,1,11.76,100,1,14.23,200,2,ARL,389031981
2469,2025-07-17T16:53:40.523811512Z,2025-07-17T16:53:40.523811512Z,10,2,1108,A,A,1,13.29,100,130,165539,322295689,12.48,2,1,13.25,15,1,12.23,100,1,13.29,100,1,12.22,300,3,13.31,2,1,11.97,100,1,13.44,100,1,11.92,100,1,13.71,100,1,11.9,700,1,13.97,100,1,11.85,700,1,14.06,800,2,11.82,700,1,14.11,100,1,11.79,700,1,14.18,1400,2,11.76,100,1,14.2,700,1,ARL,389168405
2470,2025-07-17T16:53:40.543834425Z,2025-07-17T16:53:40.543834425Z,10,2,1108,C,A,4,13.71,100,130,165539,322295865,12.48,2,1,13.25,15,1,12.23,100,1,13.29,100,1,12.22,300,3,13.31,2,1,11.97,100,1,13.44,100,1,11.92,100,1,13.97,100,1,11.9,700,1,14.06,800,2,11.85,700,1,14.11,100,1,11.82,700,1,14.18,1400,2,11.79,700,1,14.2,700,1,11.76,100,1,14.23,200,2,ARL,388943785
2471,2025-07-17T16:53:40.543887042Z,2025-07-17T16:53:40.543887042Z,10,2,1108,A,A,4,13.56,100,130,165262,322295866,12.48,2,1,13.25,15,1,12.23,100,1,13.29,100,1,12.22,300,3,13.31,2,1,11.97,100,1,13.44,100,1,11.92,100,1,13.56,100,1,11.9,700,1,13.97,100,1,11.85,700,1,14.06,800,2,11.82,700,1,14.11,100,1,11.79,700,1,14.18,1400,2,11.76,100,1,14.2,700,1,ARL,389168529
2472,2025-07-17T16:53:58.389483902Z,2025-07-17T16:53:58.389483902Z,10,2,1108,C,A,2,13.31,2,0,165642,322603434,12.48,2,1,13.25,15,1,12.23,100,1,13.29,100,1,12.22,300,3,13.44,100,1,11.97,100,1,13.56,100,1,11.92,100,1,13.97,100,1,11.9,700,1,14.06,800,2,11.85,700,1,14.11,100,1,11.82,700,1,14.18,1400,2,11.79,700,1,14.2,700,1,11.76,100,1,14.23,200,2,ARL,388467165
2473,2025-07-17T16:53:58.389483902Z,2025-07-17T16:53:58.389483902Z,10,2,1108,A,A,1,13.29,2,130,165642,322603434,12.48,2,1,13.25,15,1,12.23,100,1,13.29,102,2,12.22,300,3,13.44,100,1,11.97,100,1,13.56,100,1,11.92,100,1,13.97,100,1,11.9,700,1,14.06,800,2,11.85,700,1,14.11,100,1,11.82,700,1,14.18,1400,2,11.79,700,1,14.2,700,1,11.76,100,1,14.23,200,2,ARL,389540593
2474,2025-07-17T16:54:21.081881368Z,2025-07-17T16:54:21.081881368Z,10,2,1108,A,A,1,13.27,100,130,165365,322944902,12.48,2,1,13.25,15,1,12.23,100,1,13.27,100,1,12.22,300,3,13.29,102,2,11.97,100,1,13.44,100,1,11.92,100,1,13.56,100,1,11.9,700,1,13.97,100,1,11.85,700,1,14.06,800,2,11.82,700,1,14.11,100,1,11.79,700,1,14.18,1400,2,11.76,100,1,14.2,700,1,ARL,389948353
2475,2025-07-17T16:54:21.084582385Z,2025-07-17T16:54:21.084582385Z,10,2,1108,C,A,2,13.29,100,128,167248,322945104,12.48,2,1,13.25,15,1,12.23,100,1,13.27,100,1,12.22,300,3,13.29,2,1,11.97,100,1,13.44,100,1,11.92,100,1,13.56,100,1,11.9,700,1,13.97,100,1,11.85,700,1,14.06,800,2,11.82,700,1,14.11,100,1,11.79,700,1,14.18,1400,2,11.76,100,1,14.2,700,1,ARL,389168405
2476,2025-07-17T16:54:22.887832854Z,2025-07-17T16:54:22.887832854Z,10,2,1108,A,A,7,14.11,100,130,165655,323001879,12.48,2,1,13.25,15,1,12.23,100,1,13.27,100,1,12.22,300,3,13.29,2,1,11.97,100,1,13.44,100,1,11.92,100,1,13.56,100,1,11.9,700,1,13.97,100,1,11.85,700,1,14.06,800,2,11.82,700,1,14.11,200,2,11.79,700,1,14.18,1400,2,11.76,100,1,14.2,700,1,ARL,390012165
2477,2025-07-17T16:54:22.888082967Z,2025-07-17T16:54:22.888082967Z,10,2,1108,A,A,7,14.11,100,130,165751,323001880,12.48,2,1,13.25,15,1,12.23,100,1,13.27,100,1,12.22,300,3,13.29,2,1,11.97,100,1,13.44,100,1,11.92,100,1,13.56,100,1,11.9,700,1,13.97,100,1,11.85,700,1,14.06,800,2,11.82,700,1,14.11,300,3,11.79,700,1,14.18,1400,2,11.76,100,1,14.2,700,1,ARL,390012177
2478,2025-07-17T16:54:22.889930161Z,2025-07-17T16:54:22.889930161Z,10,2,1108,A,A,0,13.23,15,130,165544,323001883,12.48,2,1,13.23,15,1,12.23,100,1,13.25,15,1,12.22,300,3,13.27,100,1,11.97,100,1,13.29,2,1,11.92,100,1,13.44,100,1,11.9,700,1,13.56,100,1,11.85,700,1,13.97,100,1,11.82,700,1,14.06,800,2,11.79,700,1,14.11,300,3,11.76,100,1,14.18,1400,2,ARL,390012185
2479,2025-07-17T16:54:25.387036791Z,2025-07-17T16:54:25.387036791Z,10,2,1108,C,A,3,13.29,2,0,165639,323044153,12.48,2,1,13.23,15,1,12.23,100,1,13.25,15,1,12.22,300,3,13.27,100,1,11.97,100,1,13.44,100,1,11.92,100,1,13.56,100,1,11.9,700,1,13.97,100,1,11.85,700,1,14.06,800,2,11.82,700,1,14.11,300,3,11.79,700,1,14.18,1400,2,11.76,100,1,14.2,700,1,ARL,389540593
2480,2025-07-17T16:54:25.387036791Z,2025-07-17T16:54:25.387036791Z,10,2,1108,A,A,2,13.27,2,130,165639,323044153,12.48,2,1,13.23,15,1,12.23,100,1,13.25,15,1,12.22,300,3,13.27,102,2,11.97,100,1,13.44,100,1,11.92,100,1,13.56,100,1,11.9,700,1,13.97,100,1,11.85,700,1,14.06,800,2,11.82,700,1,14.11,300,3,11.79,700,1,14.18,1400,2,11.76,100,1,14.2,700,1,ARL,390060109
2481,2025-07-17T16:54:29.752451645Z,2025-07-17T16:54:29.752451645Z,10,2,1108,A,A,1,13.25,100,130,165650,323103133,12.48,2,1,13.23,15,1,12.23,100,1,13.25,115,2,12.22,300,3,13.27,102,2,11.97,100,1,13.44,100,1,11.92,100,1,13.56,100,1,11.9,700,1,13.97,100,1,11.85,700,1,14.06,800,2,11.82,700,1,14.11,300,3,11.79,700,1,14.18,1400,2,11.76,100,1,14.2,700,1,ARL,390133645
2482,2025-07-17T16:54:29.752502545Z,2025-07-17T16:54:29.752502545Z,10,2,1108,T,A,0,13.23,15,0,169818,323103134,12.48,2,1,13.25,115,2,12.23,100,1,13.27,102,2,12.22,300,3,13.44,100,1,11.97,100,1,13.56,100,1,11.92,100,1,13.97,100,1,11.9,700,1,14.06,800,2,11.85,700,1,14.11,300,3,11.82,700,1,14.18,1400,2,11.79,700,1,14.2,700,1,11.76,100,1,14.26,100,1,ARL,390012185
2482,2025-07-17T16:54:29.752502545Z,2025-07-17T16:54:29.752502545Z,10,2,1108,T,A,0,13.25,15,0,169818,323103136,12.48,2,1,13.25,100,1,12.23,100,1,13.27,102,2,12.22,300,3,13.44,100,1,11.97,100,1,13.56,100,1,11.92,100,1,13.97,100,1,11.9,700,1,14.06,800,2,11.85,700,1,14.11,300,3,11.82,700,1,14.18,1400,2,11.79,700,1,14.2,700,1,11.76,100,1,14.26,100,1,ARL,389031981
2482,2025-07-17T16:54:29.752502545Z,2025-07-17T16:54:29.752502545Z,10,2,1108,T,A,0,13.25,50,130,169818,323103137,12.48,2,1,13.25,50,0,12.23,100,1,13.27,102,2,12.22,300,3,13.44,100,1,11.97,100,1,13.56,100,1,11.92,100,1,13.97,100,1,11.9,700,1,14.06,800,2,11.85,700,1,14.11,300,3,11.82,700,1,14.18,1400,2,11.79,700,1,14.2,700,1,11.76,100,1,14.26,100,1,ARL,390133645
2482,2025-07-17T16:54:29.752536458Z,2025-07-17T16:54:29.752536458Z,10,2,1108,A,B,0,12.86,5,130,165240,323103138,12.86,5,1,13.25,50,0,12.48,2,1,13.27,102,2,12.23,100,1,13.44,100,1,12.22,300,3,13.56,100,1,11.97,100,1,13.97,100,1,11.92,100,1,14.06,800,2,11.9,700,1,14.11,300,3,11.85,700,1,14.18,1400,2,11.82,700,1,14.2,700,1,11.79,700,1,14.26,100,1,ARL,390133657
2483,2025-07-17T16:54:29.752550566Z,2025-07-17T16:54:29.752550566Z,10,2,1108,A,B,0,12.86,1,130,165104,323103139,12.86,6,2,13.25,50,0,12.48,2,1,13.27,102,2,12.23,100,1,13.44,100,1,12.22,300,3,13.56,100,1,11.97,100,1,13.97,100,1,11.92,100,1,14.06,800,2,11.9,700,1,14.11,300,3,11.85,700,1,14.18,1400,2,11.82,700,1,14.2,700,1,11.79,700,1,14.26,100,1,ARL,390133665
2484,2025-07-17T16:54:29.752572767Z,2025-07-17T16:54:29.752572767Z,10,2,1108,A,B,1,12.63,3,130,165142,323103140,12.86,6,2,13.25,50,0,12.63,3,1,13.27,102,2,12.48,2,1,13.44,100,1,12.23,100,1,13.56,100,1,12.22,300,3,13.97,100,1,11.97,100,1,14.06,800,2,11.92,100,1,14.11,300,3,11.9,700,1,14.18,1400,2,11.85,700,1,14.2,700,1,11.82,700,1,14.26,100,1,ARL,390133673
2485,2025-07-17T16:54:29.752820958Z,2025-07-17T16:54:29.752820958Z,10,2,1108,A,B,0,13.12,1,128,168417,323103150,13.12,1,1,13.25,50,0,12.86,6,2,13.27,102,2,12.63,3,1,13.44,100,1,12.48,2,1,13.56,100,1,12.23,100,1,13.97,100,1,12.22,300,3,14.06,800,2,11.97,100,1,14.11,300,3,11.92,100,1,14.18,1400,2,11.9,700,1,14.2,700,1,11.85,700,1,14.26,100,1,ARL,390133713
2486,2025-07-17T16:54:29.753192989Z,2025-07-17T16:54:29.753192989Z,10,2,1108,C,A,5,14.06,100,130,165701,323103186,13.12,1,1,13.25,50,0,12.86,6,2,13.27,102,2,12.63,3,1,13.44,100,1,12.48,2,1,13.56,100,1,12.23,100,1,13.97,100,1,12.22,300,3,14.06,700,1,11.97,100,1,14.11,300,3,11.92,100,1,14.18,1400,2,11.9,700,1,14.2,700,1,11.85,700,1,14.26,100,1,ARL,379095981
2487,2025-07-17T16:54:29.753550555Z,2025-07-17T16:54:29.753550555Z,10,2,1108,A,A,4,13.86,100,130,165193,323103207,13.12,1,1,13.25,50,0,12.86,6,2,13.27,102,2,12.63,3,1,13.44,100,1,12.48,2,1,13.56,100,1,12.23,100,1,13.86,100,1,12.22,300,3,13.97,100,1,11.97,100,1,14.06,700,1,11.92,100,1,14.11,300,3,11.9,700,1,14.18,1400,2,11.85,700,1,14.2,700,1,ARL,390133893
2488,2025-07-17T16:54:29.753552806Z,2025-07-17T16:54:29.753552806Z,10,2,1108,C,B,1,12.86,5,130,165434,323103208,13.12,1,1,13.25,50,0,12.86,1,1,13.27,102,2,12.63,3,1,13.44,100,1,12.48,2,1,13.56,100,1,12.23,100,1,13.86,100,1,12.22,300,3,13.97,100,1,11.97,100,1,14.06,700,1,11.92,100,1,14.11,300,3,11.9,700,1,14.18,1400,2,11.85,700,1,14.2,700,1,ARL,390133657
2489,2025-07-17T16:54:29.753564036Z,2025-07-17T16:54:29.753564036Z,10,2,1108,C,B,1,12.86,1,130,164986,323103209,13.12,1,1,13.25,50,0,12.63,3,1,13.27,102,2,12.48,2,1,13.44,100,1,12.23,100,1,13.56,100,1,12.22,300,3,13.86,100,1,11.97,100,1,13.97,100,1,11.92,100,1,14.06,700,1,11.9,700,1,14.11,300,3,11.85,700,1,14.18,1400,2,11.82,700,1,14.2,700,1,ARL,390133665
2490,2025-07-17T16:54:29.753868181Z,2025-07-17T16:54:29.753868181Z,10,2,1108,C,B,0,13.12,1,130,164799,323103214,12.63,3,1,13.25,50,0,12.48,2,1,13.27,102,2,12.23,100,1,13.44,100,1,12.22,300,3,13.56,100,1,11.97,100,1,13.86,100,1,11.92,100,1,13.97,100,1,11.9,700,1,14.06,700,1,11.85,700,1,14.11,300,3,11.82,700,1,14.18,1400,2,11.79,700,1,14.2,700,1,ARL,390133713
2491,2025-07-17T16:54:29.755508553Z,2025-07-17T16:54:29.755508553Z,10,2,1108,C,A,1,13.27,100,130,165611,323103374,12.63,3,1,13.25,50,0,12.48,2,1,13.27,2,1,12.23,100,1,13.44,100,1,12.22,300,3,13.56,100,1,11.97,100,1,13.86,100,1,11.92,100,1,13.97,100,1,11.9,700,1,14.06,700,1,11.85,700,1,14.11,300,3,11.82,700,1,14.18,1400,2,11.79,700,1,14.2,700,1,ARL,389948353
2492,2025-07-17T16:54:29.765107655Z,2025-07-17T16:54:29.765107655Z,10,2,1108,C,A,3,13.56,100,130,165288,323103685,12.63,3,1,13.25,50,0,12.48,2,1,13.27,2,1,12.23,100,1,13.44,100,1,12.22,300,3,13.86,100,1,11.97,100,1,13.97,100,1,11.92,100,1,14.06,700,1,11.9,700,1,14.11,300,3,11.85,700,1,14.18,1400,2,11.82,700,1,14.2,700,1,11.79,700,1,14.26,100,1,ARL,389168529
2493,2025-07-17T16:54:29.765130910Z,2025-07-17T16:54:29.765130910Z,10,2,1108,C,B,0,12.63,3,130,165457,323103690,12.48,2,1,13.25,50,0,12.23,100,1,13.27,2,1,12.22,300,3,13.44,100,1,11.97,100,1,13.86,100,1,11.92,100,1,13.97,100,1,11.9,700,1,14.06,700,1,11.85,700,1,14.11,300,3,11.82,700,1,14.18,1400,2,11.79,700,1,14.2,700,1,11.76,100,1,14.26,100,1,ARL,390133673
2494,2025-07-17T16:54:29.765159050Z,2025-07-17T16:54:29.765159050Z,10,2,1108,A,A,3,13.71,100,130,165203,323103691,12.48,2,1,13.25,50,0,12.23,100,1,13.27,2,1,12.22,300,3,13.44,100,1,11.97,100,1,13.71,100,1,11.92,100,1,13.86,100,1,11.9,700,1,13.97,100,1,11.85,700,1,14.06,700,1,11.82,700,1,14.11,300,3,11.79,700,1,14.18,1400,2,11.76,100,1,14.2,700,1,ARL,390134597
2495,2025-07-17T16:54:29.901984378Z,2025-07-17T16:54:29.901984378Z,10,2,1108,C,A,0,13.25,50,130,165531,323105144,12.48,2,1,13.27,2,1,12.23,100,1,13.44,100,1,12.22,300,3,13.71,100,1,11.97,100,1,13.86,100,1,11.92,100,1,13.97,100,1,11.9,700,1,14.06,700,1,11.85,700,1,14.11,300,3,11.82,700,1,14.18,1400,2,11.79,700,1,14.2,700,1,11.76,100,1,14.26,100,1,ARL,390133645
2496,2025-07-17T16:54:29.902034700Z,2025-07-17T16:54:29.902034700Z,10,2,1108,C,A,1,13.44,100,130,165364,323105146,12.48,2,1,13.27,2,1,12.23,100,1,13.71,100,1,12.22,300,3,13.86,100,1,11.97,100,1,13.97,100,1,11.92,100,1,14.06,700,1,11.9,700,1,14.11,300,3,11.85,700,1,14.18,1400,2,11.82,700,1,14.2,700,1,11.79,700,1,14.26,100,1,11.76,100,1,14.27,200,2,ARL,381937585
2497,2025-07-17T16:54:29.903453684Z,2025-07-17T16:54:29.903453684Z,10,2,1108,C,A,6,14.18,700,130,165258,323105162,12.48,2,1,13.27,2,1,12.23,100,1,13.71,100,1,12.22,300,3,13.86,100,1,11.97,100,1,13.97,100,1,11.92,100,1,14.06,700,1,11.9,700,1,14.11,300,3,11.85,700,1,14.18,700,1,11.82,700,1,14.2,700,1,11.79,700,1,14.26,100,1,11.76,100,1,14.27,200,2,ARL,387208149
2498,2025-07-17T16:54:29.903454701Z,2025-07-17T16:54:29.903454701Z,10,2,1108,C,A,6,14.18,700,130,165126,323105163,12.48,2,1,13.27,2,1,12.23,100,1,13.71,100,1,12.22,300,3,13.86,100,1,11.97,100,1,13.97,100,1,11.92,100,1,14.06,700,1,11.9,700,1,14.11,300,3,11.85,700,1,14.2,700,1,11.82,700,1,14.26,100,1,11.79,700,1,14.27,200,2,11.76,100,1,14.54,100,1,ARL,379214721
2499,2025-07-17T16:54:29.903499198Z,2025-07-17T16:54:29.903499198Z,10,2,1108,A,A,9,14.4,700,0,166797,323105164,12.48,2,1,13.27,2,1,12.23,100,1,13.71,100,1,12.22,300,3,13.86,100,1,11.97,100,1,13.97,100,1,11.92,100,1,14.06,700,1,11.9,700,1,14.11,300,3,11.85,700,1,14.2,700,1,11.82,700,1,14.26,100,1,11.79,700,1,14.27,200,2,11.76,100,1,14.4,700,1,ARL,390136249
2500,2025-07-17T16:54:29.903986354Z,2025-07-17T16:54:29.903986354Z,10,2,1108,C,A,4,14.06,700,130,165157,323105172,12.48,2,1,13.27,2,1,12.23,100,1,13.71,100,1,12.22,300,3,13.86,100,1,11.97,100,1,13.97,100,1,11.92,100,1,14.11,300,3,11.9,700,1,14.2,700,1,11.85,700,1,14.26,100,1,11.82,700,1,14.27,200,2,11.79,700,1,14.4,700,1,11.76,100,1,14.47,700,1,ARL,387277657
2501,2025-07-17T16:54:29.904429181Z,2025-07-17T16:54:29.904429181Z,10,2,1108,A,A,9,14.43,700,130,165419,323105173,12.48,2,1,13.27,2,1,12.23,100,1,13.71,100,1,12.22,300,3,13.86,100,1,11.97,100,1,13.97,100,1,11.92,100,1,14.11,300,3,11.9,700,1,14.2,700,1,11.85,700,1,14.26,100,1,11.82,700,1,14.27,200,2,11.79,700,1,14.4,700,1,11.76,100,1,14.43,700,1,ARL,390136281
2502,2025-07-17T16:54:29.904545815Z,2025-07-17T16:54:29.904545815Z,10,2,1108,C,A,7,14.27,100,0,165886,323105174,12.48,2,1,13.27,2,1,12.23,100,1,13.71,100,1,12.22,300,3,13.86,100,1,11.97,100,1,13.97,100,1,11.92,100,1,14.11,300,3,11.9,700,1,14.2,700,1,11.85,700,1,14.26,100,1,11.82,700,1,14.27,100,1,11.79,700,1,14.4,700,1,11.76,100,1,14.43,700,1,ARL,387246077
2503,2025-07-17T16:54:29.905981039Z,2025-07-17T16:54:29.905981039Z,10,2,1108,C,A,4,14.11,100,130,165942,323105179,12.48,2,1,13.27,2,1,12.23,100,1,13.71,100,1,12.22,300,3,13.86,100,1,11.97,100,1,13.97,100,1,11.92,100,1,14.11,200,2,11.9,700,1,14.2,700,1,11.85,700,1,14.26,100,1,11.82,700,1,14.27,100,1,11.79,700,1,14.4,700,1,11.76,100,1,14.43,700,1,ARL,387246169
2504,2025-07-17T16:54:29.913200271Z,2025-07-17T16:54:29.913200271Z,10,2,1108,C,A,7,14.27,100,0,165758,323105271,12.48,2,1,13.27,2,1,12.23,100,1,13.71,100,1,12.22,300,3,13.86,100,1,11.97,100,1,13.97,100,1,11.92,100,1,14.11,200,2,11.9,700,1,14.2,700,1,11.85,700,1,14.26,100,1,11.82,700,1,14.4,700,1,11.79,700,1,14.43,700,1,11.76,100,1,14.47,700,1,ARL,387246189
2505,2025-07-17T16:54:29.941034461Z,2025-07-17T16:54:29.941034461Z,10,2,1108,C,A,1,13.71,100,130,165141,323105451,12.48,2,1,13.27,2,1,12.23,100,1,13.86,100,1,12.22,300,3,13.97,100,1,11.97,100,1,14.11,200,2,11.92,100,1,14.2,700,1,11.9,700,1,14.26,100,1,11.85,700,1,14.4,700,1,11.82,700,1,14.43,700,1,11.79,700,1,14.47,700,1,11.76,100,1,14.49,100,1,ARL,390134597
2506,2025-07-17T16:54:29.941070856Z,2025-07-17T16:54:29.941070856Z,10,2,1108,C,A,6,14.4,700,130,165001,323105452,12.48,2,1,13.27,2,1,12.23,100,1,13.86,100,1,12.22,300,3,13.97,100,1,11.97,100,1,14.11,200,2,11.92,100,1,14.2,700,1,11.9,700,1,14.26,100,1,11.85,700,1,14.43,700,1,11.82,700,1,14.47,700,1,11.79,700,1,14.49,100,1,11.76,100,1,14.54,100,1,ARL,390136249
2507,2025-07-17T16:54:29.941083801Z,2025-07-17T16:54:29.941083801Z,10,2,1108,A,A,3,13.98,100,130,165175,323105453,12.48,2,1,13.27,2,1,12.23,100,1,13.86,100,1,12.22,300,3,13.97,100,1,11.97,100,1,13.98,100,1,11.92,100,1,14.11,200,2,11.9,700,1,14.2,700,1,11.85,700,1,14.26,100,1,11.82,700,1,14.43,700,1,11.79,700,1,14.47,700,1,11.76,100,1,14.49,100,1,ARL,390136733
2508,2025-07-17T16:54:29.941340365Z,2025-07-17T16:54:29.941340365Z,10,2,1108,C,B,0,12.48,2,130,165511,323105457,12.23,100,1,13.27,2,1,12.22,300,3,13.86,100,1,11.97,100,1,13.97,100,1,11.92,100,1,13.98,100,1,11.9,700,1,14.11,200,2,11.85,700,1,14.2,700,1,11.82,700,1,14.26,100,1,11.79,700,1,14.43,700,1,11.76,100,1,14.47,700,1,11.72,100,1,14.49,100,1,ARL,387224461
2509,2025-07-17T16:54:29.941342597Z,2025-07-17T16:54:29.941342597Z,10,2,1108,C,A,0,13.27,2,130,165184,323105458,12.23,100,1,13.86,100,1,12.22,300,3,13.97,100,1,11.97,100,1,13.98,100,1,11.92,100,1,14.11,200,2,11.9,700,1,14.2,700,1,11.85,700,1,14.26,100,1,11.82,700,1,14.43,700,1,11.79,700,1,14.47,700,1,11.76,100,1,14.49,100,1,11.72,100,1,14.54,100,1,ARL,390060109
2510,2025-07-17T16:54:29.941721119Z,2025-07-17T16:54:29.941721119Z,10,2,1108,C,B,1,12.22,100,0,165757,323105460,12.23,100,1,13.86,100,1,12.22,200,2,13.97,100,1,11.97,100,1,13.98,100,1,11.92,100,1,14.11,200,2,11.9,700,1,14.2,700,1,11.85,700,1,14.26,100,1,11.82,700,1,14.43,700,1,11.79,700,1,14.47,700,1,11.76,100,1,14.49,100,1,11.72,100,1,14.54,100,1,ARL,342029561
2511,2025-07-17T16:54:29.941775542Z,2025-07-17T16:54:29.941775542Z,10,2,1108,C,A,3,14.11,100,0,165483,323105461,12.23,100,1,13.86,100,1,12.22,200,2,13.97,100,1,11.97,100,1,13.98,100,1,11.92,100,1,14.11,100,1,11.9,700,1,14.2,700,1,11.85,700,1,14.26,100,1,11.82,700,1,14.43,700,1,11.79,700,1,14.47,700,1,11.76,100,1,14.49,100,1,11.72,100,1,14.54,100,1,ARL,390012177
2512,2025-07-17T16:54:29.941775542Z,2025-07-17T16:54:29.941775542Z,10,2,1108,A,A,6,14.33,100,130,165483,323105461,12.23,100,1,13.86,100,1,12.22,200,2,13.97,100,1,11.97,100,1,13.98,100,1,11.92,100,1,14.11,100,1,11.9,700,1,14.2,700,1,11.85,700,1,14.26,100,1,11.82,700,1,14.33,100,1,11.79,700,1,14.43,700,1,11.76,100,1,14.47,700,1,11.72,100,1,14.49,100,1,ARL,390136761
2513,2025-07-17T16:54:29.942110273Z,2025-07-17T16:54:29.942110273Z,10,2,1108,C,B,1,12.22,100,0,165525,323105463,12.23,100,1,13.86,100,1,12.22,100,1,13.97,100,1,11.97,100,1,13.98,100,1,11.92,100,1,14.11,100,1,11.9,700,1,14.2,700,1,11.85,700,1,14.26,100,1,11.82,700,1,14.33,100,1,11.79,700,1,14.43,700,1,11.76,100,1,14.47,700,1,11.72,100,1,14.49,100,1,ARL,342029581
2514,2025-07-17T16:54:29.942181221Z,2025-07-17T16:54:29.942181221Z,10,2,1108,C,A,3,14.11,100,0,165469,323105465,12.23,100,1,13.86,100,1,12.22,100,1,13.97,100,1,11.97,100,1,13.98,100,1,11.92,100,1,14.2,700,1,11.9,700,1,14.26,100,1,11.85,700,1,14.33,100,1,11.82,700,1,14.43,700,1,11.79,700,1,14.47,700,1,11.76,100,1,14.49,100,1,11.72,100,1,14.54,100,1,ARL,390012165
2515,2025-07-17T16:54:29.942181221Z,2025-07-17T16:54:29.942181221Z,10,2,1108,A,A,5,14.33,100,130,165469,323105465,12.23,100,1,13.86,100,1,12.22,100,1,13.97,100,1,11.97,100,1,13.98,100,1,11.92,100,1,14.2,700,1,11.9,700,1,14.26,100,1,11.85,700,1,14.33,200,2,11.82,700,1,14.43,700,1,11.79,700,1,14.47,700,1,11.76,100,1,14.49,100,1,11.72,100,1,14.54,100,1,ARL,390136777
2516,2025-07-17T16:54:29.949651286Z,2025-07-17T16:54:29.949651286Z,10,2,1108,C,A,2,13.98,100,130,165362,323105536,12.23,100,1,13.86,100,1,12.22,100,1,13.97,100,1,11.97,100,1,14.2,700,1,11.92,100,1,14.26,100,1,11.9,700,1,14.33,200,2,11.85,700,1,14.43,700,1,11.82,700,1,14.47,700,1,11.79,700,1,14.49,100,1,11.76,100,1,14.54,100,1,11.72,100,1,14.84,200,2,ARL,390136733
2517,2025-07-17T16:54:29.949698550Z,2025-07-17T16:54:29.949698550Z,10,2,1108,A,A,2,14.14,100,130,165328,323105537,12.23,100,1,13.86,100,1,12.22,100,1,13.97,100,1,11.97,100,1,14.14,100,1,11.92,100,1,14.2,700,1,11.9,700,1,14.26,100,1,11.85,700,1,14.33,200,2,11.82,700,1,14.43,700,1,11.79,700,1,14.47,700,1,11.76,100,1,14.49,100,1,11.72,100,1,14.54,100,1,ARL,390136953
2518,2025-07-17T16:54:29.952969836Z,2025-07-17T16:54:29.952969836Z,10,2,1108,C,A,9,14.54,100,0,165424,323105548,12.23,100,1,13.86,100,1,12.22,100,1,13.97,100,1,11.97,100,1,14.14,100,1,11.92,100,1,14.2,700,1,11.9,700,1,14.26,100,1,11.85,700,1,14.33,200,2,11.82,700,1,14.43,700,1,11.79,700,1,14.47,700,1,11.76,100,1,14.49,100,1,11.72,100,1,14.84,200,2,ARL,390136225
2519,2025-07-17T16:54:29.957872826Z,2025-07-17T16:54:29.957872826Z,10,2,1108,A,A,9,14.56,700,130,165247,323105616,12.23,100,1,13.86,100,1,12.22,100,1,13.97,100,1,11.97,100,1,14.14,100,1,11.92,100,1,14.2,700,1,11.9,700,1,14.26,100,1,11.85,700,1,14.33,200,2,11.82,700,1,14.43,700,1,11.79,700,1,14.47,700,1,11.76,100,1,14.49,100,1,11.72,100,1,14.56,700,1,ARL,390137005
2520,2025-07-17T16:54:29.980450077Z,2025-07-17T16:54:29.980450077Z,10,2,1108,A,A,1,13.87,100,130,165264,323106126,12.23,100,1,13.86,100,1,12.22,100,1,13.87,100,1,11.97,100,1,13.97,100,1,11.92,100,1,14.14,100,1,11.9,700,1,14.2,700,1,11.85,700,1,14.26,100,1,11.82,700,1,14.33,200,2,11.79,700,1,14.43,700,1,11.76,100,1,14.47,700,1,11.72,100,1,14.49,100,1,ARL,390137561
2521,2025-07-17T16:54:30.291453478Z,2025-07-17T16:54:30.291453478Z,10,2,1108,C,A,0,13.86,100,130,165099,323111095,12.23,100,1,13.87,100,1,12.22,100,1,13.97,100,1,11.97,100,1,14.14,100,1,11.92,100,1,14.2,700,1,11.9,700,1,14.26,100,1,11.85,700,1,14.33,200,2,11.82,700,1,14.43,700,1,11.79,700,1,14.47,700,1,11.76,100,1,14.49,100,1,11.72,100,1,14.56,700,1,ARL,390133893
2522,2025-07-17T16:54:30.291805387Z,2025-07-17T16:54:30.291805387Z,10,2,1108,A,A,8,14.48,100,130,165222,323111099,12.23,100,1,13.87,100,1,12.22,100,1,13.97,100,1,11.97,100,1,14.14,100,1,11.92,100,1,14.2,700,1,11.9,700,1,14.26,100,1,11.85,700,1,14.33,200,2,11.82,700,1,14.43,700,1,11.79,700,1,14.47,700,1,11.76,100,1,14.48,100,1,11.72,100,1,14.49,100,1,ARL,390141957
2523,2025-07-17T16:54:30.389668907Z,2025-07-17T16:54:30.389668907Z,10,2,1108,C,A,4,14.26,100,130,165235,323116867,12.23,100,1,13.87,100,1,12.22,100,1,13.97,100,1,11.97,100,1,14.14,100,1,11.92,100,1,14.2,700,1,11.9,700,1,14.33,200,2,11.85,700,1,14.43,700,1,11.82,700,1,14.47,700,1,11.79,700,1,14.48,100,1,11.76,100,1,14.49,100,1,11.72,100,1,14.56,700,1,ARL,379107445
2524,2025-07-17T16:54:30.880608525Z,2025-07-17T16:54:30.880608525Z,10,2,1108,C,A,1,13.97,100,130,165468,323122333,12.23,100,1,13.87,100,1,12.22,100,1,14.14,100,1,11.97,100,1,14.2,700,1,11.92,100,1,14.33,200,2,11.9,700,1,14.43,700,1,11.85,700,1,14.47,700,1,11.82,700,1,14.48,100,1,11.79,700,1,14.49,100,1,11.76,100,1,14.56,700,1,11.72,100,1,14.69,100,1,ARL,381395205
2525,2025-07-17T16:54:30.880610836Z,2025-07-17T16:54:30.880610836Z,10,2,1108,A,A,4,14.42,100,130,165642,323122334,12.23,100,1,13.87,100,1,12.22,100,1,14.14,100,1,11.97,100,1,14.2,700,1,11.92,100,1,14.33,200,2,11.9,700,1,14.42,100,1,11.85,700,1,14.43,700,1,11.82,700,1,14.47,700,1,11.79,700,1,14.48,100,1,11.76,100,1,14.49,100,1,11.72,100,1,14.56,700,1,ARL,390153597
2526,2025-07-17T16:54:30.908587894Z,2025-07-17T16:54:30.908587894Z,10,2,1108,C,A,8,14.49,100,0,165432,323122430,12.23,100,1,13.87,100,1,12.22,100,1,14.14,100,1,11.97,100,1,14.2,700,1,11.92,100,1,14.33,200,2,11.9,700,1,14.42,100,1,11.85,700,1,14.43,700,1,11.82,700,1,14.47,700,1,11.79,700,1,14.48,100,1,11.76,100,1,14.56,700,1,11.72,100,1,14.69,100,1,ARL,390136305
2527,2025-07-17T16:54:30.908587894Z,2025-07-17T16:54:30.908587894Z,10,2,1108,A,A,9,14.65,100,130,165432,323122430,12.23,100,1,13.87,100,1,12.22,100,1,14.14,100,1,11.97,100,1,14.2,700,1,11.92,100,1,14.33,200,2,11.9,700,1,14.42,100,1,11.85,700,1,14.43,700,1,11.82,700,1,14.47,700,1,11.79,700,1,14.48,100,1,11.76,100,1,14.56,700,1,11.72,100,1,14.65,100,1,ARL,390153953
2528,2025-07-17T16:54:30.982648521Z,2025-07-17T16:54:30.982648521Z,10,2,1108,A,B,1,12.22,100,130,165479,323123335,12.23,100,1,13.87,100,1,12.22,200,2,14.14,100,1,11.97,100,1,14.2,700,1,11.92,100,1,14.33,200,2,11.9,700,1,14.42,100,1,11.85,700,1,14.43,700,1,11.82,700,1,14.47,700,1,11.79,700,1,14.48,100,1,11.76,100,1,14.56,700,1,11.72,100,1,14.65,100,1,ARL,390155937
2529,2025-07-17T16:54:30.989615198Z,2025-07-17T16:54:30.989615198Z,10,2,1108,A,B,1,12.22,100,130,165726,323123542,12.23,100,1,13.87,100,1,12.22,300,3,14.14,100,1,11.97,100,1,14.2,700,1,11.92,100,1,14.33,200,2,11.9,700,1,14.42,100,1,11.85,700,1,14.43,700,1,11.82,700,1,14.47,700,1,11.79,700,1,14.48,100,1,11.76,100,1,14.56,700,1,11.72,100,1,14.65,100,1,ARL,390156205
2530,2025-07-17T16:54:33.001823770Z,2025-07-17T16:54:33.001823770Z,10,2,1108,A,B,0,13.1,10,130,165294,323145588,13.1,10,1,13.87,100,1,12.23,100,1,14.14,100,1,12.22,300,3,14.2,700,1,11.97,100,1,14.33,200,2,11.92,100,1,14.42,100,1,11.9,700,1,14.43,700,1,11.85,700,1,14.47,700,1,11.82,700,1,14.48,100,1,11.79,700,1,14.56,700,1,11.76,100,1,14.65,100,1,ARL,390188869
2531,2025-07-17T16:54:36.494842320Z,2025-07-17T16:54:36.494842320Z,10,2,1108,A,A,0,13.45,10,130,165133,323190336,13.1,10,1,13.45,10,1,12.23,100,1,13.87,100,1,12.22,300,3,14.14,100,1,11.97,100,1,14.2,700,1,11.92,100,1,14.33,200,2,11.9,700,1,14.42,100,1,11.85,700,1,14.43,700,1,11.82,700,1,14.47,700,1,11.79,700,1,14.48,100,1,11.76,100,1,14.56,700,1,ARL,390244445
2532,2025-07-17T16:54:39.639240088Z,2025-07-17T16:54:39.639240088Z,10,2,1108,C,B,0,13.1,10,128,166275,323229343,12.23,100,1,13.45,10,1,12.22,300,3,13.87,100,1,11.97,100,1,14.14,100,1,11.92,100,1,14.2,700,1,11.9,700,1,14.33,200,2,11.85,700,1,14.42,100,1,11.82,700,1,14.43,700,1,11.79,700,1,14.47,700,1,11.76,100,1,14.48,100,1,11.72,100,1,14.56,700,1,ARL,390188869
2533,2025-07-17T16:54:39.640376331Z,2025-07-17T16:54:39.640376331Z,10,2,1108,C,B,1,12.22,100,0,165723,323229401,12.23,100,1,13.45,10,1,12.22,200,2,13.87,100,1,11.97,100,1,14.14,100,1,11.92,100,1,14.2,700,1,11.9,700,1,14.33,200,2,11.85,700,1,14.42,100,1,11.82,700,1,14.43,700,1,11.79,700,1,14.47,700,1,11.76,100,1,14.48,100,1,11.72,100,1,14.56,700,1,ARL,390155937
2534,2025-07-17T16:54:39.641052077Z,2025-07-17T16:54:39.641052077Z,10,2,1108,C,B,1,12.22,100,0,165810,323229423,12.23,100,1,13.45,10,1,12.22,100,1,13.87,100,1,11.97,100,1,14.14,100,1,11.92,100,1,14.2,700,1,11.9,700,1,14.33,200,2,11.85,700,1,14.42,100,1,11.82,700,1,14.43,700,1,11.79,700,1,14.47,700,1,11.76,100,1,14.48,100,1,11.72,100,1,14.56,700,1,ARL,390156205
2535,2025-07-17T16:54:39.742481344Z,2025-07-17T16:54:39.742481344Z,10,2,1108,C,A,1,13.87,100,0,165539,323233034,12.23,100,1,13.45,10,1,12.22,100,1,14.14,100,1,11.97,100,1,14.2,700,1,11.92,100,1,14.33,200,2,11.9,700,1,14.42,100,1,11.85,700,1,14.43,700,1,11.82,700,1,14.47,700,1,11.79,700,1,14.48,100,1,11.76,100,1,14.56,700,1,11.72,100,1,14.65,100,1,ARL,390137561
2536,2025-07-17T16:54:39.742481344Z,2025-07-17T16:54:39.742481344Z,10,2,1108,A,A,1,13.46,100,130,165539,323233034,12.23,100,1,13.45,10,1,12.22,100,1,13.46,100,1,11.97,100,1,14.14,100,1,11.92,100,1,14.2,700,1,11.9,700,1,14.33,200,2,11.85,700,1,14.42,100,1,11.82,700,1,14.43,700,1,11.79,700,1,14.47,700,1,11.76,100,1,14.48,100,1,11.72,100,1,14.56,700,1,ARL,390297413
2537,2025-07-17T16:54:39.743220634Z,2025-07-17T16:54:39.743220634Z,10,2,1108,C,A,8,14.48,100,130,165140,323233082,12.23,100,1,13.45,10,1,12.22,100,1,13.46,100,1,11.97,100,1,14.14,100,1,11.92,100,1,14.2,700,1,11.9,700,1,14.33,200,2,11.85,700,1,14.42,100,1,11.82,700,1,14.43,700,1,11.79,700,1,14.47,700,1,11.76,100,1,14.56,700,1,11.72,100,1,14.65,100,1,ARL,390141957
2538,2025-07-17T16:54:39.743224193Z,2025-07-17T16:54:39.743224193Z,10,2,1108,A,A,8,14.5,100,130,165512,323233083,12.23,100,1,13.45,10,1,12.22,100,1,13.46,100,1,11.97,100,1,14.14,100,1,11.92,100,1,14.2,700,1,11.9,700,1,14.33,200,2,11.85,700,1,14.42,100,1,11.82,700,1,14.43,700,1,11.79,700,1,14.47,700,1,11.76,100,1,14.5,100,1,11.72,100,1,14.56,700,1,ARL,390297517
2539,2025-07-17T16:54:39.743571651Z,2025-07-17T16:54:39.743571651Z,10,2,1108,A,A,2,14.06,100,128,166421,323233099,12.23,100,1,13.45,10,1,12.22,100,1,13.46,100,1,11.97,100,1,14.06,100,1,11.92,100,1,14.14,100,1,11.9,700,1,14.2,700,1,11.85,700,1,14.33,200,2,11.82,700,1,14.42,100,1,11.79,700,1,14.43,700,1,11.76,100,1,14.47,700,1,11.72,100,1,14.5,100,1,ARL,390297545
2540,2025-07-17T16:54:39.745075591Z,2025-07-17T16:54:39.745075591Z,10,2,1108,A,A,6,14.41,100,130,165396,323233188,12.23,100,1,13.45,10,1,12.22,100,1,13.46,100,1,11.97,100,1,14.06,100,1,11.92,100,1,14.14,100,1,11.9,700,1,14.2,700,1,11.85,700,1,14.33,200,2,11.82,700,1,14.41,100,1,11.79,700,1,14.42,100,1,11.76,100,1,14.43,700,1,11.72,100,1,14.47,700,1,ARL,390297581
2541,2025-07-17T16:54:39.746718759Z,2025-07-17T16:54:39.746718759Z,10,2,1108,C,A,3,14.14,100,130,165514,323233222,12.23,100,1,13.45,10,1,12.22,100,1,13.46,100,1,11.97,100,1,14.06,100,1,11.92,100,1,14.2,700,1,11.9,700,1,14.33,200,2,11.85,700,1,14.41,100,1,11.82,700,1,14.42,100,1,11.79,700,1,14.43,700,1,11.76,100,1,14.47,700,1,11.72,100,1,14.5,100,1,ARL,390136953
2542,2025-07-17T16:54:39.746770470Z,2025-07-17T16:54:39.746770470Z,10,2,1108,A,A,2,13.73,100,130,165510,323233223,12.23,100,1,13.45,10,1,12.22,100,1,13.46,100,1,11.97,100,1,13.73,100,1,11.92,100,1,14.06,100,1,11.9,700,1,14.2,700,1,11.85,700,1,14.33,200,2,11.82,700,1,14.41,100,1,11.79,700,1,14.42,100,1,11.76,100,1,14.43,700,1,11.72,100,1,14.47,700,1,ARL,390297625
2543,2025-07-17T16:54:39.749455133Z,2025-07-17T16:54:39.749455133Z,10,2,1108,A,B,0,12.49,2,130,165335,323233314,12.49,2,1,13.45,10,1,12.23,100,1,13.46,100,1,12.22,100,1,13.73,100,1,11.97,100,1,14.06,100,1,11.92,100,1,14.2,700,1,11.9,700,1,14.33,200,2,11.85,700,1,14.41,100,1,11.82,700,1,14.42,100,1,11.79,700,1,14.43,700,1,11.76,100,1,14.47,700,1,ARL,390297773
2544,2025-07-17T16:54:39.749457160Z,2025-07-17T16:54:39.749457160Z,10,2,1108,A,A,1,13.46,2,130,165309,323233315,12.49,2,1,13.45,10,1,12.23,100,1,13.46,102,2,12.22,100,1,13.73,100,1,11.97,100,1,14.06,100,1,11.92,100,1,14.2,700,1,11.9,700,1,14.33,200,2,11.85,700,1,14.41,100,1,11.82,700,1,14.42,100,1,11.79,700,1,14.43,700,1,11.76,100,1,14.47,700,1,ARL,390297777
2545,2025-07-17T16:54:39.754488276Z,2025-07-17T16:54:39.754488276Z,10,2,1108,A,A,5,14.24,100,130,165305,323233451,12.49,2,1,13.45,10,1,12.23,100,1,13.46,102,2,12.22,100,1,13.73,100,1,11.97,100,1,14.06,100,1,11.92,100,1,14.2,700,1,11.9,700,1,14.24,100,1,11.85,700,1,14.33,200,2,11.82,700,1,14.41,100,1,11.79,700,1,14.42,100,1,11.76,100,1,14.43,700,1,ARL,390297949
2546,2025-07-17T16:54:39.856189932Z,2025-07-17T16:54:39.856189932Z,10,2,1108,A,A,7,14.41,100,130,165478,323234881,12.49,2,1,13.45,10,1,12.23,100,1,13.46,102,2,12.22,100,1,13.73,100,1,11.97,100,1,14.06,100,1,11.92,100,1,14.2,700,1,11.9,700,1,14.24,100,1,11.85,700,1,14.33,200,2,11.82,700,1,14.41,200,2,11.79,700,1,14.42,100,1,11.76,100,1,14.43,700,1,ARL,390300213
2547,2025-07-17T16:54:39.925701041Z,2025-07-17T16:54:39.925701041Z,10,2,1108,A,A,6,14.26,100,130,165651,323235398,12.49,2,1,13.45,10,1,12.23,100,1,13.46,102,2,12.22,100,1,13.73,100,1,11.97,100,1,14.06,100,1,11.92,100,1,14.2,700,1,11.9,700,1,14.24,100,1,11.85,700,1,14.26,100,1,11.82,700,1,14.33,200,2,11.79,700,1,14.41,200,2,11.76,100,1,14.42,100,1,ARL,390301509
2548,2025-07-17T16:54:40.360069276Z,2025-07-17T16:54:40.360069276Z,10,2,1108,A,A,3,13.99,100,130,165355,323249703,12.49,2,1,13.45,10,1,12.23,100,1,13.46,102,2,12.22,100,1,13.73,100,1,11.97,100,1,13.99,100,1,11.92,100,1,14.06,100,1,11.9,700,1,14.2,700,1,11.85,700,1,14.24,100,1,11.82,700,1,14.26,100,1,11.79,700,1,14.33,200,2,11.76,100,1,14.41,200,2,ARL,390315289
2549,2025-07-17T16:54:40.657858797Z,2025-07-17T16:54:40.657858797Z,10,2,1108,A,B,2,12.22,100,130,165446,323252340,12.49,2,1,13.45,10,1,12.23,100,1,13.46,102,2,12.22,200,2,13.73,100,1,11.97,100,1,13.99,100,1,11.92,100,1,14.06,100,1,11.9,700,1,14.2,700,1,11.85,700,1,14.24,100,1,11.82,700,1,14.26,100,1,11.79,700,1,14.33,200,2,11.76,100,1,14.41,200,2,ARL,390318665
2550,2025-07-17T16:54:40.672319951Z,2025-07-17T16:54:40.672319951Z,10,2,1108,A,B,2,12.22,100,130,165364,323252412,12.49,2,1,13.45,10,1,12.23,100,1,13.46,102,2,12.22,300,3,13.73,100,1,11.97,100,1,13.99,100,1,11.92,100,1,14.06,100,1,11.9,700,1,14.2,700,1,11.85,700,1,14.24,100,1,11.82,700,1,14.26,100,1,11.79,700,1,14.33,200,2,11.76,100,1,14.41,200,2,ARL,390318917
2551,2025-07-17T16:54:48.636571204Z,2025-07-17T16:54:48.636571204Z,10,2,1108,A,A,5,14.14,700,130,165414,323339823,12.49,2,1,13.45,10,1,12.23,100,1,13.46,102,2,12.22,300,3,13.73,100,1,11.97,100,1,13.99,100,1,11.92,100,1,14.06,100,1,11.9,700,1,14.14,700,1,11.85,700,1,14.2,700,1,11.82,700,1,14.24,100,1,11.79,700,1,14.26,100,1,11.76,100,1,14.33,200,2,ARL,390418545
2552,2025-07-17T16:55:18.860820293Z,2025-07-17T16:55:18.860820293Z,10,2,1108,C,A,0,13.45,10,128,167809,323792027,12.49,2,1,13.46,102,2,12.23,100,1,13.73,100,1,12.22,300,3,13.99,100,1,11.97,100,1,14.06,100,1,11.92,100,1,14.14,700,1,11.9,700,1,14.2,700,1,11.85,700,1,14.24,100,1,11.82,700,1,14.26,100,1,11.79,700,1,14.33,200,2,11.76,100,1,14.41,200,2,ARL,390244445
2553,2025-07-17T17:10:10.000893422Z,2025-07-17T17:10:10.000893422Z,10,2,1108,C,A,0,13.46,2,0,165667,336433579,12.49,2,1,13.46,100,1,12.23,100,1,13.73,100,1,12.22,300,3,13.99,100,1,11.97,100,1,14.06,100,1,11.92,100,1,14.14,700,1,11.9,700,1,14.2,700,1,11.85,700,1,14.24,100,1,11.82,700,1,14.26,100,1,11.79,700,1,14.33,200,2,11.76,100,1,14.41,200,2,ARL,390297777
2554,2025-07-17T17:10:10.000893422Z,2025-07-17T17:10:10.000893422Z,10,2,1108,A,A,0,13.44,2,130,165667,336433579,12.49,2,1,13.44,2,1,12.23,100,1,13.46,100,1,12.22,300,3,13.73,100,1,11.97,100,1,13.99,100,1,11.92,100,1,14.06,100,1,11.9,700,1,14.14,700,1,11.85,700,1,14.2,700,1,11.82,700,1,14.24,100,1,11.79,700,1,14.26,100,1,11.76,100,1,14.33,200,2,ARL,407450073
2555,2025-07-17T17:10:10.361772221Z,2025-07-17T17:10:10.361772221Z,10,2,1108,C,A,1,13.46,100,0,165555,336439763,12.49,2,1,13.44,2,1,12.23,100,1,13.73,100,1,12.22,300,3,13.99,100,1,11.97,100,1,14.06,100,1,11.92,100,1,14.14,700,1,11.9,700,1,14.2,700,1,11.85,700,1,14.24,100,1,11.82,700,1,14.26,100,1,11.79,700,1,14.33,200,2,11.76,100,1,14.41,200,2,ARL,390297413
2556,2025-07-17T17:10:10.361772221Z,2025-07-17T17:10:10.361772221Z,10,2,1108,A,A,1,13.45,100,130,165555,336439763,12.49,2,1,13.44,2,1,12.23,100,1,13.45,100,1,12.22,300,3,13.73,100,1,11.97,100,1,13.99,100,1,11.92,100,1,14.06,100,1,11.9,700,1,14.14,700,1,11.85,700,1,14.2,700,1,11.82,700,1,14.24,100,1,11.79,700,1,14.26,100,1,11.76,100,1,14.33,200,2,ARL,407456589
2557,2025-07-17T17:10:43.029659505Z,2025-07-17T17:10:43.029659505Z,10,2,1108,C,A,1,13.45,100,130,165315,336947991,12.49,2,1,13.44,2,1,12.23,100,1,13.73,100,1,12.22,300,3,13.99,100,1,11.97,100,1,14.06,100,1,11.92,100,1,14.14,700,1,11.9,700,1,14.2,700,1,11.85,700,1,14.24,100,1,11.82,700,1,14.26,100,1,11.79,700,1,14.33,200,2,11.76,100,1,14.41,200,2,ARL,407456589
2558,2025-07-17T17:10:43.031388893Z,2025-07-17T17:10:43.031388893Z,10,2,1108,A,A,2,13.74,100,130,165550,336948067,12.49,2,1,13.44,2,1,12.23,100,1,13.73,100,1,12.22,300,3,13.74,100,1,11.97,100,1,13.99,100,1,11.92,100,1,14.06,100,1,11.9,700,1,14.14,700,1,11.85,700,1,14.2,700,1,11.82,700,1,14.24,100,1,11.79,700,1,14.26,100,1,11.76,100,1,14.33,200,2,ARL,408122037
2559,2025-07-17T17:14:42.263977687Z,2025-07-17T17:14:42.263977687Z,10,2,1108,A,A,0,13.44,4,130,165490,340033053,12.49,2,1,13.44,6,2,12.23,100,1,13.73,100,1,12.22,300,3,13.74,100,1,11.97,100,1,13.99,100,1,11.92,100,1,14.06,100,1,11.9,700,1,14.14,700,1,11.85,700,1,14.2,700,1,11.82,700,1,14.24,100,1,11.79,700,1,14.26,100,1,11.76,100,1,14.33,200,2,ARL,412198129
2560,2025-07-17T17:24:42.260738507Z,2025-07-17T17:24:42.260738507Z,10,2,1108,C,A,0,13.44,4,130,165482,347925516,12.49,2,1,13.44,2,1,12.23,100,1,13.73,100,1,12.22,300,3,13.74,100,1,11.97,100,1,13.99,100,1,11.92,100,1,14.06,100,1,11.9,700,1,14.14,700,1,11.85,700,1,14.2,700,1,11.82,700,1,14.24,100,1,11.79,700,1,14.26,100,1,11.76,100,1,14.33,200,2,ARL,412198129
2561,2025-07-17T17:24:42.261761757Z,2025-07-17T17:24:42.261761757Z,10,2,1108,C,A,2,13.74,100,0,165545,347925524,12.49,2,1,13.44,2,1,12.23,100,1,13.73,100,1,12.22,300,3,13.99,100,1,11.97,100,1,14.06,100,1,11.92,100,1,14.14,700,1,11.9,700,1,14.2,700,1,11.85,700,1,14.24,100,1,11.82,700,1,14.26,100,1,11.79,700,1,14.33,200,2,11.76,100,1,14.41,200,2,ARL,408122037
2562,2025-07-17T17:24:42.261761757Z,2025-07-17T17:24:42.261761757Z,10,2,1108,A,A,1,13.45,100,130,165545,347925524,12.49,2,1,13.44,2,1,12.23,100,1,13.45,100,1,12.22,300,3,13.73,100,1,11.97,100,1,13.99,100,1,11.92,100,1,14.06,100,1,11.9,700,1,14.14,700,1,11.85,700,1,14.2,700,1,11.82,700,1,14.24,100,1,11.79,700,1,14.26,100,1,11.76,100,1,14.33,200,2,ARL,422564177
2563,2025-07-17T17:24:42.262806771Z,2025-07-17T17:24:42.262806771Z,10,2,1108,C,B,2,12.22,100,0,165707,347925526,12.49,2,1,13.44,2,1,12.23,100,1,13.45,100,1,12.22,200,2,13.73,100,1,11.97,100,1,13.99,100,1,11.92,100,1,14.06,100,1,11.9,700,1,14.14,700,1,11.85,700,1,14.2,700,1,11.82,700,1,14.24,100,1,11.79,700,1,14.26,100,1,11.76,100,1,14.33,200,2,ARL,390318917
2564,2025-07-17T17:24:42.262822690Z,2025-07-17T17:24:42.262822690Z,10,2,1108,C,B,2,12.22,100,0,165355,347925527,12.49,2,1,13.44,2,1,12.23,100,1,13.45,100,1,12.22,100,1,13.73,100,1,11.97,100,1,13.99,100,1,11.92,100,1,14.06,100,1,11.9,700,1,14.14,700,1,11.85,700,1,14.2,700,1,11.82,700,1,14.24,100,1,11.79,700,1,14.26,100,1,11.76,100,1,14.33,200,2,ARL,390318665
2565,2025-07-17T17:24:42.548027809Z,2025-07-17T17:24:42.548027809Z,10,2,1108,C,A,1,13.45,100,130,165151,347929285,12.49,2,1,13.44,2,1,12.23,100,1,13.73,100,1,12.22,100,1,13.99,100,1,11.97,100,1,14.06,100,1,11.92,100,1,14.14,700,1,11.9,700,1,14.2,700,1,11.85,700,1,14.24,100,1,11.82,700,1,14.26,100,1,11.79,700,1,14.33,200,2,11.76,100,1,14.41,200,2,ARL,422564177
2566,2025-07-17T17:24:42.549392732Z,2025-07-17T17:24:42.549392732Z,10,2,1108,A,A,2,13.74,100,130,165451,347929289,12.49,2,1,13.44,2,1,12.23,100,1,13.73,100,1,12.22,100,1,13.74,100,1,11.97,100,1,13.99,100,1,11.92,100,1,14.06,100,1,11.9,700,1,14.14,700,1,11.85,700,1,14.2,700,1,11.82,700,1,14.24,100,1,11.79,700,1,14.26,100,1,11.76,100,1,14.33,200,2,ARL,422568905
2567,2025-07-17T17:56:30.441768063Z,2025-07-17T17:56:30.441768063Z,10,2,1108,A,A,0,13.43,10,130,165852,374792938,12.49,2,1,13.43,10,1,12.23,100,1,13.44,2,1,12.22,100,1,13.73,100,1,11.97,100,1,13.74,100,1,11.92,100,1,13.99,100,1,11.9,700,1,14.06,100,1,11.85,700,1,14.14,700,1,11.82,700,1,14.2,700,1,11.79,700,1,14.24,100,1,11.76,100,1,14.26,100,1,ARL,457191725
2568,2025-07-17T17:56:30.636700055Z,2025-07-17T17:56:30.636700055Z,10,2,1108,C,A,3,13.74,100,0,165458,374794445,12.49,2,1,13.43,10,1,12.23,100,1,13.44,2,1,12.22,100,1,13.73,100,1,11.97,100,1,13.99,100,1,11.92,100,1,14.06,100,1,11.9,700,1,14.14,700,1,11.85,700,1,14.2,700,1,11.82,700,1,14.24,100,1,11.79,700,1,14.26,100,1,11.76,100,1,14.33,200,2,ARL,422568905
2569,2025-07-17T17:56:30.636700055Z,2025-07-17T17:56:30.636700055Z,10,2,1108,A,A,2,13.45,100,130,165458,374794445,12.49,2,1,13.43,10,1,12.23,100,1,13.44,2,1,12.22,100,1,13.45,100,1,11.97,100,1,13.73,100,1,11.92,100,1,13.99,100,1,11.9,700,1,14.06,100,1,11.85,700,1,14.14,700,1,11.82,700,1,14.2,700,1,11.79,700,1,14.24,100,1,11.76,100,1,14.26,100,1,ARL,457194033
2570,2025-07-17T17:57:00.747417750Z,2025-07-17T17:57:00.747417750Z,10,2,1108,A,B,3,12.05,100,130,167002,375114806,12.49,2,1,13.43,10,1,12.23,100,1,13.44,2,1,12.22,100,1,13.45,100,1,12.05,100,1,13.73,100,1,11.97,100,1,13.99,100,1,11.92,100,1,14.06,100,1,11.9,700,1,14.14,700,1,11.85,700,1,14.2,700,1,11.82,700,1,14.24,100,1,11.79,700,1,14.26,100,1,ARL,457630209
2571,2025-07-17T17:57:00.748171838Z,2025-07-17T17:57:00.748171838Z,10,2,1108,A,B,3,12.05,100,130,165554,375114814,12.49,2,1,13.43,10,1,12.23,100,1,13.44,2,1,12.22,100,1,13.45,100,1,12.05,200,2,13.73,100,1,11.97,100,1,13.99,100,1,11.92,100,1,14.06,100,1,11.9,700,1,14.14,700,1,11.85,700,1,14.2,700,1,11.82,700,1,14.24,100,1,11.79,700,1,14.26,100,1,ARL,457630269
2572,2025-07-17T18:02:45.504573741Z,2025-07-17T18:02:45.504573741Z,10,2,1108,A,A,0,13.37,1,130,165344,380174467,12.49,2,1,13.37,1,1,12.23,100,1,13.43,10,1,12.22,100,1,13.44,2,1,12.05,200,2,13.45,100,1,11.97,100,1,13.73,100,1,11.92,100,1,13.99,100,1,11.9,700,1,14.06,100,1,11.85,700,1,14.14,700,1,11.82,700,1,14.2,700,1,11.79,700,1,14.24,100,1,ARL,464268809
2573,2025-07-17T18:02:45.511528908Z,2025-07-17T18:02:45.511528908Z,10,2,1108,A,A,0,13.37,10,130,165350,380174502,12.49,2,1,13.37,11,2,12.23,100,1,13.43,10,1,12.22,100,1,13.44,2,1,12.05,200,2,13.45,100,1,11.97,100,1,13.73,100,1,11.92,100,1,13.99,100,1,11.9,700,1,14.06,100,1,11.85,700,1,14.14,700,1,11.82,700,1,14.2,700,1,11.79,700,1,14.24,100,1,ARL,464268845
2574,2025-07-17T18:02:45.604569852Z,2025-07-17T18:02:45.604569852Z,10,2,1108,C,A,0,13.37,1,130,164995,380175836,12.49,2,1,13.37,10,1,12.23,100,1,13.43,10,1,12.22,100,1,13.44,2,1,12.05,200,2,13.45,100,1,11.97,100,1,13.73,100,1,11.92,100,1,13.99,100,1,11.9,700,1,14.06,100,1,11.85,700,1,14.14,700,1,11.82,700,1,14.2,700,1,11.79,700,1,14.24,100,1,ARL,464268809
2575,2025-07-17T18:02:45.758288837Z,2025-07-17T18:02:45.758288837Z,10,2,1108,A,B,1,12.48,19,130,165185,380177351,12.49,2,1,13.37,10,1,12.48,19,1,13.43,10,1,12.23,100,1,13.44,2,1,12.22,100,1,13.45,100,1,12.05,200,2,13.73,100,1,11.97,100,1,13.99,100,1,11.92,100,1,14.06,100,1,11.9,700,1,14.14,700,1,11.85,700,1,14.2,700,1,11.82,700,1,14.24,100,1,ARL,464272409
2576,2025-07-17T18:03:28.674884242Z,2025-07-17T18:03:28.674884242Z,10,2,1108,C,A,0,13.37,10,130,166146,380875617,12.49,2,1,13.43,10,1,12.48,19,1,13.44,2,1,12.23,100,1,13.45,100,1,12.22,100,1,13.73,100,1,12.05,200,2,13.99,100,1,11.97,100,1,14.06,100,1,11.92,100,1,14.14,700,1,11.9,700,1,14.2,700,1,11.85,700,1,14.24,100,1,11.82,700,1,14.26,100,1,ARL,464268845
2577,2025-07-17T18:03:28.675033913Z,2025-07-17T18:03:28.675033913Z,10,2,1108,C,A,0,13.43,10,130,165396,380875662,12.49,2,1,13.44,2,1,12.48,19,1,13.45,100,1,12.23,100,1,13.73,100,1,12.22,100,1,13.99,100,1,12.05,200,2,14.06,100,1,11.97,100,1,14.14,700,1,11.92,100,1,14.2,700,1,11.9,700,1,14.24,100,1,11.85,700,1,14.26,100,1,11.82,700,1,14.33,200,2,ARL,457191725
2578,2025-07-17T18:03:37.156700909Z,2025-07-17T18:03:37.156700909Z,10,2,1108,A,A,0,13.43,10,130,165340,381033247,12.49,2,1,13.43,10,1,12.48,19,1,13.44,2,1,12.23,100,1,13.45,100,1,12.22,100,1,13.73,100,1,12.05,200,2,13.99,100,1,11.97,100,1,14.06,100,1,11.92,100,1,14.14,700,1,11.9,700,1,14.2,700,1,11.85,700,1,14.24,100,1,11.82,700,1,14.26,100,1,ARL,465436101
2579,2025-07-17T18:03:39.024464975Z,2025-07-17T18:03:39.024464975Z,10,2,1108,C,A,0,13.43,10,130,164971,381055717,12.49,2,1,13.44,2,1,12.48,19,1,13.45,100,1,12.23,100,1,13.73,100,1,12.22,100,1,13.99,100,1,12.05,200,2,14.06,100,1,11.97,100,1,14.14,700,1,11.92,100,1,14.2,700,1,11.9,700,1,14.24,100,1,11.85,700,1,14.26,100,1,11.82,700,1,14.33,200,2,ARL,465436101
2580,2025-07-17T18:03:45.510423349Z,2025-07-17T18:03:45.510423349Z,10,2,1108,A,A,0,13.43,10,130,165311,381155408,12.49,2,1,13.43,10,1,12.48,19,1,13.44,2,1,12.23,100,1,13.45,100,1,12.22,100,1,13.73,100,1,12.05,200,2,13.99,100,1,11.97,100,1,14.06,100,1,11.92,100,1,14.14,700,1,11.9,700,1,14.2,700,1,11.85,700,1,14.24,100,1,11.82,700,1,14.26,100,1,ARL,465595785
2581,2025-07-17T18:03:55.373753982Z,2025-07-17T18:03:55.373753982Z,10,2,1108,C,A,0,13.43,10,128,174956,381294591,12.49,2,1,13.44,2,1,12.48,19,1,13.45,100,1,12.23,100,1,13.73,100,1,12.22,100,1,13.99,100,1,12.05,200,2,14.06,100,1,11.97,100,1,14.14,700,1,11.92,100,1,14.2,700,1,11.9,700,1,14.24,100,1,11.85,700,1,14.26,100,1,11.82,700,1,14.33,200,2,ARL,465595785
2582,2025-07-17T18:04:03.101919454Z,2025-07-17T18:04:03.101919454Z,10,2,1108,A,A,0,13.43,10,128,167128,381395570,12.49,2,1,13.43,10,1,12.48,19,1,13.44,2,1,12.23,100,1,13.45,100,1,12.22,100,1,13.73,100,1,12.05,200,2,13.99,100,1,11.97,100,1,14.06,100,1,11.92,100,1,14.14,700,1,11.9,700,1,14.2,700,1,11.85,700,1,14.24,100,1,11.82,700,1,14.26,100,1,ARL,465889901
2583,2025-07-17T18:04:45.575158670Z,2025-07-17T18:04:45.575158670Z,10,2,1108,A,A,0,13.43,10,130,165602,382020181,12.49,2,1,13.43,20,2,12.48,19,1,13.44,2,1,12.23,100,1,13.45,100,1,12.22,100,1,13.73,100,1,12.05,200,2,13.99,100,1,11.97,100,1,14.06,100,1,11.92,100,1,14.14,700,1,11.9,700,1,14.2,700,1,11.85,700,1,14.24,100,1,11.82,700,1,14.26,100,1,ARL,466717245
2584,2025-07-17T18:08:14.760305571Z,2025-07-17T18:08:14.760305571Z,10,2,1108,C,B,1,12.48,19,130,165370,384965197,12.49,2,1,13.43,20,2,12.23,100,1,13.44,2,1,12.22,100,1,13.45,100,1,12.05,200,2,13.73,100,1,11.97,100,1,13.99,100,1,11.92,100,1,14.06,100,1,11.9,700,1,14.14,700,1,11.85,700,1,14.2,700,1,11.82,700,1,14.24,100,1,11.79,700,1,14.26,100,1,ARL,464272409
2585,2025-07-17T18:19:43.054558147Z,2025-07-17T18:19:43.054558147Z,10,2,1108,C,A,0,13.43,10,130,165419,394283063,12.49,2,1,13.43,10,1,12.23,100,1,13.44,2,1,12.22,100,1,13.45,100,1,12.05,200,2,13.73,100,1,11.97,100,1,13.99,100,1,11.92,100,1,14.06,100,1,11.9,700,1,14.14,700,1,11.85,700,1,14.2,700,1,11.82,700,1,14.24,100,1,11.79,700,1,14.26,100,1,ARL,465889901
2586,2025-07-17T18:19:47.055249706Z,2025-07-17T18:19:47.055249706Z,10,2,1108,A,A,0,13.43,10,130,165320,394326337,12.49,2,1,13.43,20,2,12.23,100,1,13.44,2,1,12.22,100,1,13.45,100,1,12.05,200,2,13.73,100,1,11.97,100,1,13.99,100,1,11.92,100,1,14.06,100,1,11.9,700,1,14.14,700,1,11.85,700,1,14.2,700,1,11.82,700,1,14.24,100,1,11.79,700,1,14.26,100,1,ARL,482798553
2587,2025-07-17T18:19:50.478297341Z,2025-07-17T18:19:50.478297341Z,10,2,1108,C,B,3,12.05,100,0,165511,394363038,12.49,2,1,13.43,20,2,12.23,100,1,13.44,2,1,12.22,100,1,13.45,100,1,12.05,100,1,13.73,100,1,11.97,100,1,13.99,100,1,11.92,100,1,14.06,100,1,11.9,700,1,14.14,700,1,11.85,700,1,14.2,700,1,11.82,700,1,14.24,100,1,11.79,700,1,14.26,100,1,ARL,457630209
2588,2025-07-17T18:19:50.478404811Z,2025-07-17T18:19:50.478404811Z,10,2,1108,C,B,3,12.05,100,0,165790,394363039,12.49,2,1,13.43,20,2,12.23,100,1,13.44,2,1,12.22,100,1,13.45,100,1,11.97,100,1,13.73,100,1,11.92,100,1,13.99,100,1,11.9,700,1,14.06,100,1,11.85,700,1,14.14,700,1,11.82,700,1,14.2,700,1,11.79,700,1,14.24,100,1,11.76,100,1,14.26,100,1,ARL,457630269
2589,2025-07-17T18:19:50.487934498Z,2025-07-17T18:19:50.487934498Z,10,2,1108,C,A,2,13.45,100,130,165254,394363891,12.49,2,1,13.43,20,2,12.23,100,1,13.44,2,1,12.22,100,1,13.73,100,1,11.97,100,1,13.99,100,1,11.92,100,1,14.06,100,1,11.9,700,1,14.14,700,1,11.85,700,1,14.2,700,1,11.82,700,1,14.24,100,1,11.79,700,1,14.26,100,1,11.76,100,1,14.33,200,2,ARL,457194033
2590,2025-07-17T18:19:50.492220295Z,2025-07-17T18:19:50.492220295Z,10,2,1108,A,A,3,13.74,100,130,165226,394364230,12.49,2,1,13.43,20,2,12.23,100,1,13.44,2,1,12.22,100,1,13.73,100,1,11.97,100,1,13.74,100,1,11.92,100,1,13.99,100,1,11.9,700,1,14.06,100,1,11.85,700,1,14.14,700,1,11.82,700,1,14.2,700,1,11.79,700,1,14.24,100,1,11.76,100,1,14.26,100,1,ARL,482851573
2591,2025-07-17T18:19:50.980530549Z,2025-07-17T18:19:50.980530549Z,10,2,1108,C,A,3,13.74,100,0,165332,394370279,12.49,2,1,13.43,20,2,12.23,100,1,13.44,2,1,12.22,100,1,13.73,100,1,11.97,100,1,13.99,100,1,11.92,100,1,14.06,100,1,11.9,700,1,14.14,700,1,11.85,700,1,14.2,700,1,11.82,700,1,14.24,100,1,11.79,700,1,14.26,100,1,11.76,100,1,14.33,200,2,ARL,482851573
2592,2025-07-17T18:19:50.980530549Z,2025-07-17T18:19:50.980530549Z,10,2,1108,A,A,2,13.45,100,130,165332,394370279,12.49,2,1,13.43,20,2,12.23,100,1,13.44,2,1,12.22,100,1,13.45,100,1,11.97,100,1,13.73,100,1,11.92,100,1,13.99,100,1,11.9,700,1,14.06,100,1,11.85,700,1,14.14,700,1,11.82,700,1,14.2,700,1,11.79,700,1,14.24,100,1,11.76,100,1,14.26,100,1,ARL,482863949
2593,2025-07-17T18:20:07.054794050Z,2025-07-17T18:20:07.054794050Z,10,2,1108,C,A,0,13.43,10,130,165248,394619081,12.49,2,1,13.43,10,1,12.23,100,1,13.44,2,1,12.22,100,1,13.45,100,1,11.97,100,1,13.73,100,1,11.92,100,1,13.99,100,1,11.9,700,1,14.06,100,1,11.85,700,1,14.14,700,1,11.82,700,1,14.2,700,1,11.79,700,1,14.24,100,1,11.76,100,1,14.26,100,1,ARL,482798553
2594,2025-07-17T18:20:13.055117687Z,2025-07-17T18:20:13.055117687Z,10,2,1108,A,A,0,13.43,10,130,165461,394709628,12.49,2,1,13.43,20,2,12.23,100,1,13.44,2,1,12.22,100,1,13.45,100,1,11.97,100,1,13.73,100,1,11.92,100,1,13.99,100,1,11.9,700,1,14.06,100,1,11.85,700,1,14.14,700,1,11.82,700,1,14.2,700,1,11.79,700,1,14.24,100,1,11.76,100,1,14.26,100,1,ARL,483298361
2595,2025-07-17T18:20:18.733857768Z,2025-07-17T18:20:18.733857768Z,10,2,1108,C,A,0,13.43,10,130,165209,394792459,12.49,2,1,13.43,10,1,12.23,100,1,13.44,2,1,12.22,100,1,13.45,100,1,11.97,100,1,13.73,100,1,11.92,100,1,13.99,100,1,11.9,700,1,14.06,100,1,11.85,700,1,14.14,700,1,11.82,700,1,14.2,700,1,11.79,700,1,14.24,100,1,11.76,100,1,14.26,100,1,ARL,483298361
2596,2025-07-17T18:20:31.890228636Z,2025-07-17T18:20:31.890228636Z,10,2,1108,A,A,0,13.43,10,130,166612,394964577,12.49,2,1,13.43,20,2,12.23,100,1,13.44,2,1,12.22,100,1,13.45,100,1,11.97,100,1,13.73,100,1,11.92,100,1,13.99,100,1,11.9,700,1,14.06,100,1,11.85,700,1,14.14,700,1,11.82,700,1,14.2,700,1,11.79,700,1,14.24,100,1,11.76,100,1,14.26,100,1,ARL,483612169
2597,2025-07-17T18:21:34.342574608Z,2025-07-17T18:21:34.342574608Z,10,2,1108,C,B,0,12.49,2,0,167003,395825259,12.23,100,1,13.43,20,2,12.22,100,1,13.44,2,1,11.97,100,1,13.45,100,1,11.92,100,1,13.73,100,1,11.9,700,1,13.99,100,1,11.85,700,1,14.06,100,1,11.82,700,1,14.14,700,1,11.79,700,1,14.2,700,1,11.76,100,1,14.24,100,1,11.72,100,1,14.26,100,1,ARL,390297773
2598,2025-07-17T18:21:34.342574608Z,2025-07-17T18:21:34.342574608Z,10,2,1108,A,B,0,12.37,2,130,167003,395825259,12.37,2,1,13.43,20,2,12.23,100,1,13.44,2,1,12.22,100,1,13.45,100,1,11.97,100,1,13.73,100,1,11.92,100,1,13.99,100,1,11.9,700,1,14.06,100,1,11.85,700,1,14.14,700,1,11.82,700,1,14.2,700,1,11.79,700,1,14.24,100,1,11.76,100,1,14.26,100,1,ARL,484764453
2599,2025-07-17T18:21:41.375189503Z,2025-07-17T18:21:41.375189503Z,10,2,1108,C,A,0,13.43,10,130,165230,395912308,12.37,2,1,13.43,10,1,12.23,100,1,13.44,2,1,12.22,100,1,13.45,100,1,11.97,100,1,13.73,100,1,11.92,100,1,13.99,100,1,11.9,700,1,14.06,100,1,11.85,700,1,14.14,700,1,11.82,700,1,14.2,700,1,11.79,700,1,14.24,100,1,11.76,100,1,14.26,100,1,ARL,483612169
2600,2025-07-17T18:21:42.509963215Z,2025-07-17T18:21:42.509963215Z,10,2,1108,A,A,0,13.43,10,130,165257,395938501,12.37,2,1,13.43,20,2,12.23,100,1,13.44,2,1,12.22,100,1,13.45,100,1,11.97,100,1,13.73,100,1,11.92,100,1,13.99,100,1,11.9,700,1,14.06,100,1,11.85,700,1,14.14,700,1,11.82,700,1,14.2,700,1,11.79,700,1,14.24,100,1,11.76,100,1,14.26,100,1,ARL,484908201
2601,2025-07-17T18:21:43.021411133Z,2025-07-17T18:21:43.021411133Z,10,2,1108,C,A,0,13.43,10,130,165314,395964087,12.37,2,1,13.43,10,1,12.23,100,1,13.44,2,1,12.22,100,1,13.45,100,1,11.97,100,1,13.73,100,1,11.92,100,1,13.99,100,1,11.9,700,1,14.06,100,1,11.85,700,1,14.14,700,1,11.82,700,1,14.2,700,1,11.79,700,1,14.24,100,1,11.76,100,1,14.26,100,1,ARL,484908201
2602,2025-07-17T18:21:52.394059116Z,2025-07-17T18:21:52.394059116Z,10,2,1108,C,A,1,13.44,2,0,165619,396204170,12.37,2,1,13.43,10,1,12.23,100,1,13.45,100,1,12.22,100,1,13.73,100,1,11.97,100,1,13.99,100,1,11.92,100,1,14.06,100,1,11.9,700,1,14.14,700,1,11.85,700,1,14.2,700,1,11.82,700,1,14.24,100,1,11.79,700,1,14.26,100,1,11.76,100,1,14.33,200,2,ARL,407450073
2603,2025-07-17T18:21:52.394059116Z,2025-07-17T18:21:52.394059116Z,10,2,1108,A,A,2,13.56,2,130,165619,396204170,12.37,2,1,13.43,10,1,12.23,100,1,13.45,100,1,12.22,100,1,13.56,2,1,11.97,100,1,13.73,100,1,11.92,100,1,13.99,100,1,11.9,700,1,14.06,100,1,11.85,700,1,14.14,700,1,11.82,700,1,14.2,700,1,11.79,700,1,14.24,100,1,11.76,100,1,14.26,100,1,ARL,485232841
2604,2025-07-17T18:21:55.669141274Z,2025-07-17T18:21:55.669141274Z,10,2,1108,C,A,1,13.45,100,0,165597,396249515,12.37,2,1,13.43,10,1,12.23,100,1,13.56,2,1,12.22,100,1,13.73,100,1,11.97,100,1,13.99,100,1,11.92,100,1,14.06,100,1,11.9,700,1,14.14,700,1,11.85,700,1,14.2,700,1,11.82,700,1,14.24,100,1,11.79,700,1,14.26,100,1,11.76,100,1,14.33,200,2,ARL,482863949
2605,2025-07-17T18:21:55.669141274Z,2025-07-17T18:21:55.669141274Z,10,2,1108,A,A,1,13.44,100,130,165597,396249515,12.37,2,1,13.43,10,1,12.23,100,1,13.44,100,1,12.22,100,1,13.56,2,1,11.97,100,1,13.73,100,1,11.92,100,1,13.99,100,1,11.9,700,1,14.06,100,1,11.85,700,1,14.14,700,1,11.82,700,1,14.2,700,1,11.79,700,1,14.24,100,1,11.76,100,1,14.26,100,1,ARL,485292661
2606,2025-07-17T18:21:55.669742041Z,2025-07-17T18:21:55.669742041Z,10,2,1108,A,A,4,13.74,4,130,165086,396249524,12.37,2,1,13.43,10,1,12.23,100,1,13.44,100,1,12.22,100,1,13.56,2,1,11.97,100,1,13.73,100,1,11.92,100,1,13.74,4,1,11.9,700,1,13.99,100,1,11.85,700,1,14.06,100,1,11.82,700,1,14.14,700,1,11.79,700,1,14.2,700,1,11.76,100,1,14.24,100,1,ARL,485292677
2607,2025-07-17T18:22:01.058506892Z,2025-07-17T18:22:01.058506892Z,10,2,1108,A,A,0,13.43,10,130,165369,396320334,12.37,2,1,13.43,20,2,12.23,100,1,13.44,100,1,12.22,100,1,13.56,2,1,11.97,100,1,13.73,100,1,11.92,100,1,13.74,4,1,11.9,700,1,13.99,100,1,11.85,700,1,14.06,100,1,11.82,700,1,14.14,700,1,11.79,700,1,14.2,700,1,11.76,100,1,14.24,100,1,ARL,485391097
2608,2025-07-17T18:22:13.435844247Z,2025-07-17T18:22:13.435844247Z,10,2,1108,C,A,0,13.43,10,130,165056,396492898,12.37,2,1,13.43,10,1,12.23,100,1,13.44,100,1,12.22,100,1,13.56,2,1,11.97,100,1,13.73,100,1,11.92,100,1,13.74,4,1,11.9,700,1,13.99,100,1,11.85,700,1,14.06,100,1,11.82,700,1,14.14,700,1,11.79,700,1,14.2,700,1,11.76,100,1,14.24,100,1,ARL,485391097
2609,2025-07-17T18:22:39.060839850Z,2025-07-17T18:22:39.060839850Z,10,2,1108,A,A,0,13.43,10,130,165490,396801846,12.37,2,1,13.43,20,2,12.23,100,1,13.44,100,1,12.22,100,1,13.56,2,1,11.97,100,1,13.73,100,1,11.92,100,1,13.74,4,1,11.9,700,1,13.99,100,1,11.85,700,1,14.06,100,1,11.82,700,1,14.14,700,1,11.79,700,1,14.2,700,1,11.76,100,1,14.24,100,1,ARL,486051129
2610,2025-07-17T18:24:02.569341036Z,2025-07-17T18:24:02.569341036Z,10,2,1108,C,A,0,13.43,10,130,165169,397768837,12.37,2,1,13.43,10,1,12.23,100,1,13.44,100,1,12.22,100,1,13.56,2,1,11.97,100,1,13.73,100,1,11.92,100,1,13.74,4,1,11.9,700,1,13.99,100,1,11.85,700,1,14.06,100,1,11.82,700,1,14.14,700,1,11.79,700,1,14.2,700,1,11.76,100,1,14.24,100,1,ARL,486051129
2611,2025-07-17T18:24:05.242489364Z,2025-07-17T18:24:05.242489364Z,10,2,1108,A,A,0,13.43,10,130,165253,397805897,12.37,2,1,13.43,20,2,12.23,100,1,13.44,100,1,12.22,100,1,13.56,2,1,11.97,100,1,13.73,100,1,11.92,100,1,13.74,4,1,11.9,700,1,13.99,100,1,11.85,700,1,14.06,100,1,11.82,700,1,14.14,700,1,11.79,700,1,14.2,700,1,11.76,100,1,14.24,100,1,ARL,487432113
2612,2025-07-17T18:24:20.246982063Z,2025-07-17T18:24:20.246982063Z,10,2,1108,C,A,0,13.43,10,130,166084,398013865,12.37,2,1,13.43,10,1,12.23,100,1,13.44,100,1,12.22,100,1,13.56,2,1,11.97,100,1,13.73,100,1,11.92,100,1,13.74,4,1,11.9,700,1,13.99,100,1,11.85,700,1,14.06,100,1,11.82,700,1,14.14,700,1,11.79,700,1,14.2,700,1,11.76,100,1,14.24,100,1,ARL,487432113
2613,2025-07-17T18:25:00.146030189Z,2025-07-17T18:25:00.146030189Z,10,2,1108,A,A,0,13.43,10,128,177493,398730846,12.37,2,1,13.43,20,2,12.23,100,1,13.44,100,1,12.22,100,1,13.56,2,1,11.97,100,1,13.73,100,1,11.92,100,1,13.74,4,1,11.9,700,1,13.99,100,1,11.85,700,1,14.06,100,1,11.82,700,1,14.14,700,1,11.79,700,1,14.2,700,1,11.76,100,1,14.24,100,1,ARL,488547681
2614,2025-07-17T18:25:04.834777122Z,2025-07-17T18:25:04.834777122Z,10,2,1108,C,A,0,13.43,10,130,165334,398832320,12.37,2,1,13.43,10,1,12.23,100,1,13.44,100,1,12.22,100,1,13.56,2,1,11.97,100,1,13.73,100,1,11.92,100,1,13.74,4,1,11.9,700,1,13.99,100,1,11.85,700,1,14.06,100,1,11.82,700,1,14.14,700,1,11.79,700,1,14.2,700,1,11.76,100,1,14.24,100,1,ARL,488547681
2615,2025-07-17T18:25:13.233934332Z,2025-07-17T18:25:13.233934332Z,10,2,1108,A,A,0,13.43,10,130,165613,398973618,12.37,2,1,13.43,20,2,12.23,100,1,13.44,100,1,12.22,100,1,13.56,2,1,11.97,100,1,13.73,100,1,11.92,100,1,13.74,4,1,11.9,700,1,13.99,100,1,11.85,700,1,14.06,100,1,11.82,700,1,14.14,700,1,11.79,700,1,14.2,700,1,11.76,100,1,14.24,100,1,ARL,488839225
2616,2025-07-17T18:25:32.715248018Z,2025-07-17T18:25:32.715248018Z,10,2,1108,A,B,9,11.76,100,130,165488,399247257,12.37,2,1,13.43,20,2,12.23,100,1,13.44,100,1,12.22,100,1,13.56,2,1,11.97,100,1,13.73,100,1,11.92,100,1,13.74,4,1,11.9,700,1,13.99,100,1,11.85,700,1,14.06,100,1,11.82,700,1,14.14,700,1,11.79,700,1,14.2,700,1,11.76,200,2,14.24,100,1,ARL,489200865
2617,2025-07-17T18:25:32.715715815Z,2025-07-17T18:25:32.715715815Z,10,2,1108,A,B,9,11.76,100,130,165427,399247258,12.37,2,1,13.43,20,2,12.23,100,1,13.44,100,1,12.22,100,1,13.56,2,1,11.97,100,1,13.73,100,1,11.92,100,1,13.74,4,1,11.9,700,1,13.99,100,1,11.85,700,1,14.06,100,1,11.82,700,1,14.14,700,1,11.79,700,1,14.2,700,1,11.76,300,3,14.24,100,1,ARL,489200877
2618,2025-07-17T18:28:52.016623464Z,2025-07-17T18:28:52.016623464Z,10,2,1108,C,A,0,13.43,10,130,166192,401929725,12.37,2,1,13.43,10,1,12.23,100,1,13.44,100,1,12.22,100,1,13.56,2,1,11.97,100,1,13.73,100,1,11.92,100,1,13.74,4,1,11.9,700,1,13.99,100,1,11.85,700,1,14.06,100,1,11.82,700,1,14.14,700,1,11.79,700,1,14.2,700,1,11.76,300,3,14.24,100,1,ARL,488839225
2619,2025-07-17T18:28:53.050696982Z,2025-07-17T18:28:53.050696982Z,10,2,1108,A,A,0,13.43,10,130,165292,401946425,12.37,2,1,13.43,20,2,12.23,100,1,13.44,100,1,12.22,100,1,13.56,2,1,11.97,100,1,13.73,100,1,11.92,100,1,13.74,4,1,11.9,700,1,13.99,100,1,11.85,700,1,14.06,100,1,11.82,700,1,14.14,700,1,11.79,700,1,14.2,700,1,11.76,300,3,14.24,100,1,ARL,492865077
2620,2025-07-17T18:29:05.900193653Z,2025-07-17T18:29:05.900193653Z,10,2,1108,A,A,0,13.3,10,130,165356,402134637,12.37,2,1,13.3,10,1,12.23,100,1,13.43,20,2,12.22,100,1,13.44,100,1,11.97,100,1,13.56,2,1,11.92,100,1,13.73,100,1,11.9,700,1,13.74,4,1,11.85,700,1,13.99,100,1,11.82,700,1,14.06,100,1,11.79,700,1,14.14,700,1,11.76,300,3,14.2,700,1,ARL,493143705
2621,2025-07-17T18:29:05.901152755Z,2025-07-17T18:29:05.901152755Z,10,2,1108,A,A,9,14.17,100,130,165553,402134673,12.37,2,1,13.3,10,1,12.23,100,1,13.43,20,2,12.22,100,1,13.44,100,1,11.97,100,1,13.56,2,1,11.92,100,1,13.73,100,1,11.9,700,1,13.74,4,1,11.85,700,1,13.99,100,1,11.82,700,1,14.06,100,1,11.79,700,1,14.14,700,1,11.76,300,3,14.17,100,1,ARL,493143725
2622,2025-07-17T18:29:05.901260136Z,2025-07-17T18:29:05.901260136Z,10,2,1108,A,A,9,14.17,100,130,165486,402134675,12.37,2,1,13.3,10,1,12.23,100,1,13.43,20,2,12.22,100,1,13.44,100,1,11.97,100,1,13.56,2,1,11.92,100,1,13.73,100,1,11.9,700,1,13.74,4,1,11.85,700,1,13.99,100,1,11.82,700,1,14.06,100,1,11.79,700,1,14.14,700,1,11.76,300,3,14.17,200,2,ARL,493143729
2623,2025-07-17T18:29:07.048172403Z,2025-07-17T18:29:07.048172403Z,10,2,1108,C,A,2,13.44,100,0,165380,402152978,12.37,2,1,13.3,10,1,12.23,100,1,13.43,20,2,12.22,100,1,13.56,2,1,11.97,100,1,13.73,100,1,11.92,100,1,13.74,4,1,11.9,700,1,13.99,100,1,11.85,700,1,14.06,100,1,11.82,700,1,14.14,700,1,11.79,700,1,14.17,200,2,11.76,300,3,14.2,700,1,ARL,485292661
2624,2025-07-17T18:29:07.048172403Z,2025-07-17T18:29:07.048172403Z,10,2,1108,A,A,1,13.31,100,130,165380,402152978,12.37,2,1,13.3,10,1,12.23,100,1,13.31,100,1,12.22,100,1,13.43,20,2,11.97,100,1,13.56,2,1,11.92,100,1,13.73,100,1,11.9,700,1,13.74,4,1,11.85,700,1,13.99,100,1,11.82,700,1,14.06,100,1,11.79,700,1,14.14,700,1,11.76,300,3,14.17,200,2,ARL,493167357
2625,2025-07-17T18:29:07.048789564Z,2025-07-17T18:29:07.048789564Z,10,2,1108,C,A,5,13.74,4,128,167685,402153113,12.37,2,1,13.3,10,1,12.23,100,1,13.31,100,1,12.22,100,1,13.43,20,2,11.97,100,1,13.56,2,1,11.92,100,1,13.73,100,1,11.9,700,1,13.99,100,1,11.85,700,1,14.06,100,1,11.82,700,1,14.14,700,1,11.79,700,1,14.17,200,2,11.76,300,3,14.2,700,1,ARL,485292677
2626,2025-07-17T18:29:07.052579008Z,2025-07-17T18:29:07.052579008Z,10,2,1108,A,A,7,14.08,100,130,165480,402153285,12.37,2,1,13.3,10,1,12.23,100,1,13.31,100,1,12.22,100,1,13.43,20,2,11.97,100,1,13.56,2,1,11.92,100,1,13.73,100,1,11.9,700,1,13.99,100,1,11.85,700,1,14.06,100,1,11.82,700,1,14.08,100,1,11.79,700,1,14.14,700,1,11.76,300,3,14.17,200,2,ARL,493167537
2627,2025-07-17T18:29:07.052710067Z,2025-07-17T18:29:07.052710067Z,10,2,1108,C,A,4,13.73,100,130,165233,402153289,12.37,2,1,13.3,10,1,12.23,100,1,13.31,100,1,12.22,100,1,13.43,20,2,11.97,100,1,13.56,2,1,11.92,100,1,13.99,100,1,11.9,700,1,14.06,100,1,11.85,700,1,14.08,100,1,11.82,700,1,14.14,700,1,11.79,700,1,14.17,200,2,11.76,300,3,14.2,700,1,ARL,390297625
2628,2025-07-17T18:29:07.052761169Z,2025-07-17T18:29:07.052761169Z,10,2,1108,A,A,4,13.58,100,130,165336,402153290,12.37,2,1,13.3,10,1,12.23,100,1,13.31,100,1,12.22,100,1,13.43,20,2,11.97,100,1,13.56,2,1,11.92,100,1,13.58,100,1,11.9,700,1,13.99,100,1,11.85,700,1,14.06,100,1,11.82,700,1,14.08,100,1,11.79,700,1,14.14,700,1,11.76,300,3,14.17,200,2,ARL,493167549
2629,2025-07-17T18:29:14.583281105Z,2025-07-17T18:29:14.583281105Z,10,2,1108,A,A,6,14.05,700,130,165518,402256375,12.37,2,1,13.3,10,1,12.23,100,1,13.31,100,1,12.22,100,1,13.43,20,2,11.97,100,1,13.56,2,1,11.92,100,1,13.58,100,1,11.9,700,1,13.99,100,1,11.85,700,1,14.05,700,1,11.82,700,1,14.06,100,1,11.79,700,1,14.08,100,1,11.76,300,3,14.14,700,1,ARL,493307877
2630,2025-07-17T18:29:16.360726793Z,2025-07-17T18:29:16.360726793Z,10,2,1108,A,A,6,14.01,700,130,165254,402282246,12.37,2,1,13.3,10,1,12.23,100,1,13.31,100,1,12.22,100,1,13.43,20,2,11.97,100,1,13.56,2,1,11.92,100,1,13.58,100,1,11.9,700,1,13.99,100,1,11.85,700,1,14.01,700,1,11.82,700,1,14.05,700,1,11.79,700,1,14.06,100,1,11.76,300,3,14.08,100,1,ARL,493339833
2631,2025-07-17T18:29:25.628721986Z,2025-07-17T18:29:25.628721986Z,10,2,1108,C,A,2,13.43,10,130,165318,402397381,12.37,2,1,13.3,10,1,12.23,100,1,13.31,100,1,12.22,100,1,13.43,10,1,11.97,100,1,13.56,2,1,11.92,100,1,13.58,100,1,11.9,700,1,13.99,100,1,11.85,700,1,14.01,700,1,11.82,700,1,14.05,700,1,11.79,700,1,14.06,100,1,11.76,300,3,14.08,100,1,ARL,492865077
2632,2025-07-17T18:29:37.071351468Z,2025-07-17T18:29:37.071351468Z,10,2,1108,A,A,0,13.2,10,130,165297,402520424,12.37,2,1,13.2,10,1,12.23,100,1,13.3,10,1,12.22,100,1,13.31,100,1,11.97,100,1,13.43,10,1,11.92,100,1,13.56,2,1,11.9,700,1,13.58,100,1,11.85,700,1,13.99,100,1,11.82,700,1,14.01,700,1,11.79,700,1,14.05,700,1,11.76,300,3,14.06,100,1,ARL,493669961
2633,2025-07-17T18:29:46.923941765Z,2025-07-17T18:29:46.923941765Z,10,2,1108,C,A,4,13.56,2,0,165468,402615919,12.37,2,1,13.2,10,1,12.23,100,1,13.3,10,1,12.22,100,1,13.31,100,1,11.97,100,1,13.43,10,1,11.92,100,1,13.58,100,1,11.9,700,1,13.99,100,1,11.85,700,1,14.01,700,1,11.82,700,1,14.05,700,1,11.79,700,1,14.06,100,1,11.76,300,3,14.08,100,1,ARL,485232841
2634,2025-07-17T18:29:46.923941765Z,2025-07-17T18:29:46.923941765Z,10,2,1108,A,A,4,13.46,2,130,165468,402615919,12.37,2,1,13.2,10,1,12.23,100,1,13.3,10,1,12.22,100,1,13.31,100,1,11.97,100,1,13.43,10,1,11.92,100,1,13.46,2,1,11.9,700,1,13.58,100,1,11.85,700,1,13.99,100,1,11.82,700,1,14.01,700,1,11.79,700,1,14.05,700,1,11.76,300,3,14.06,100,1,ARL,493814817
2635,2025-07-17T18:30:00.004148859Z,2025-07-17T18:30:00.004148859Z,10,2,1108,C,A,2,13.31,100,0,165545,402798184,12.37,2,1,13.2,10,1,12.23,100,1,13.3,10,1,12.22,100,1,13.43,10,1,11.97,100,1,13.46,2,1,11.92,100,1,13.58,100,1,11.9,700,1,13.99,100,1,11.85,700,1,14.01,700,1,11.82,700,1,14.05,700,1,11.79,700,1,14.06,100,1,11.76,300,3,14.08,100,1,ARL,493167357
2636,2025-07-17T18:30:00.004148859Z,2025-07-17T18:30:00.004148859Z,10,2,1108,A,A,1,13.21,100,130,165545,402798184,12.37,2,1,13.2,10,1,12.23,100,1,13.21,100,1,12.22,100,1,13.3,10,1,11.97,100,1,13.43,10,1,11.92,100,1,13.46,2,1,11.9,700,1,13.58,100,1,11.85,700,1,13.99,100,1,11.82,700,1,14.01,700,1,11.79,700,1,14.05,700,1,11.76,300,3,14.06,100,1,ARL,494070601
2637,2025-07-17T18:30:00.004883884Z,2025-07-17T18:30:00.004883884Z,10,2,1108,A,A,5,13.56,4,130,165315,402798221,12.37,2,1,13.2,10,1,12.23,100,1,13.21,100,1,12.22,100,1,13.3,10,1,11.97,100,1,13.43,10,1,11.92,100,1,13.46,2,1,11.9,700,1,13.56,4,1,11.85,700,1,13.58,100,1,11.82,700,1,13.99,100,1,11.79,700,1,14.01,700,1,11.76,300,3,14.05,700,1,ARL,494070737
2638,2025-07-17T18:30:00.005255746Z,2025-07-17T18:30:00.005255746Z,10,2,1108,A,A,7,13.8,100,130,165194,402798245,12.37,2,1,13.2,10,1,12.23,100,1,13.21,100,1,12.22,100,1,13.3,10,1,11.97,100,1,13.43,10,1,11.92,100,1,13.46,2,1,11.9,700,1,13.56,4,1,11.85,700,1,13.58,100,1,11.82,700,1,13.8,100,1,11.79,700,1,13.99,100,1,11.76,300,3,14.01,700,1,ARL,494070769
2639,2025-07-17T18:30:00.016437088Z,2025-07-17T18:30:00.016437088Z,10,2,1108,C,A,6,13.58,100,130,165624,402798886,12.37,2,1,13.2,10,1,12.23,100,1,13.21,100,1,12.22,100,1,13.3,10,1,11.97,100,1,13.43,10,1,11.92,100,1,13.46,2,1,11.9,700,1,13.56,4,1,11.85,700,1,13.8,100,1,11.82,700,1,13.99,100,1,11.79,700,1,14.01,700,1,11.76,300,3,14.05,700,1,ARL,493167549
2640,2025-07-17T18:30:00.038340826Z,2025-07-17T18:30:00.038340826Z,10,2,1108,A,A,5,13.47,100,130,165236,402800533,12.37,2,1,13.2,10,1,12.23,100,1,13.21,100,1,12.22,100,1,13.3,10,1,11.97,100,1,13.43,10,1,11.92,100,1,13.46,2,1,11.9,700,1,13.47,100,1,11.85,700,1,13.56,4,1,11.82,700,1,13.8,100,1,11.79,700,1,13.99,100,1,11.76,300,3,14.01,700,1,ARL,494073757
2641,2025-07-17T18:30:47.524738400Z,2025-07-17T18:30:47.524738400Z,10,2,1108,C,A,0,13.2,10,130,166543,403534811,12.37,2,1,13.21,100,1,12.23,100,1,13.3,10,1,12.22,100,1,13.43,10,1,11.97,100,1,13.46,2,1,11.92,100,1,13.47,100,1,11.9,700,1,13.56,4,1,11.85,700,1,13.8,100,1,11.82,700,1,13.99,100,1,11.79,700,1,14.01,700,1,11.76,300,3,14.05,700,1,ARL,493669961
2642,2025-07-17T18:30:59.074488718Z,2025-07-17T18:30:59.074488718Z,10,2,1108,A,A,0,13.2,10,130,165200,403703774,12.37,2,1,13.2,10,1,12.23,100,1,13.21,100,1,12.22,100,1,13.3,10,1,11.97,100,1,13.43,10,1,11.92,100,1,13.46,2,1,11.9,700,1,13.47,100,1,11.85,700,1,13.56,4,1,11.82,700,1,13.8,100,1,11.79,700,1,13.99,100,1,11.76,300,3,14.01,700,1,ARL,495283297
2643,2025-07-17T18:31:15.693333658Z,2025-07-17T18:31:15.693333658Z,10,2,1108,C,A,1,13.21,100,130,165488,403953391,12.37,2,1,13.2,10,1,12.23,100,1,13.3,10,1,12.22,100,1,13.43,10,1,11.97,100,1,13.46,2,1,11.92,100,1,13.47,100,1,11.9,700,1,13.56,4,1,11.85,700,1,13.8,100,1,11.82,700,1,13.99,100,1,11.79,700,1,14.01,700,1,11.76,300,3,14.05,700,1,ARL,494070601
2644,2025-07-17T18:31:15.693925475Z,2025-07-17T18:31:15.693925475Z,10,2,1108,A,A,2,13.43,300,130,165393,403953392,12.37,2,1,13.2,10,1,12.23,100,1,13.3,10,1,12.22,100,1,13.43,310,2,11.97,100,1,13.46,2,1,11.92,100,1,13.47,100,1,11.9,700,1,13.56,4,1,11.85,700,1,13.8,100,1,11.82,700,1,13.99,100,1,11.79,700,1,14.01,700,1,11.76,300,3,14.05,700,1,ARL,495591097
2645,2025-07-17T18:31:15.694076678Z,2025-07-17T18:31:15.694076678Z,10,2,1108,C,A,6,13.8,100,130,165274,403953395,12.37,2,1,13.2,10,1,12.23,100,1,13.3,10,1,12.22,100,1,13.43,310,2,11.97,100,1,13.46,2,1,11.92,100,1,13.47,100,1,11.9,700,1,13.56,4,1,11.85,700,1,13.99,100,1,11.82,700,1,14.01,700,1,11.79,700,1,14.05,700,1,11.76,300,3,14.08,100,1,ARL,494070769
2646,2025-07-17T18:31:15.694401607Z,2025-07-17T18:31:15.694401607Z,10,2,1108,C,A,5,13.56,4,130,165288,403953402,12.37,2,1,13.2,10,1,12.23,100,1,13.3,10,1,12.22,100,1,13.43,310,2,11.97,100,1,13.46,2,1,11.92,100,1,13.47,100,1,11.9,700,1,13.99,100,1,11.85,700,1,14.01,700,1,11.82,700,1,14.05,700,1,11.79,700,1,14.08,100,1,11.76,300,3,14.14,700,1,ARL,494070737
2647,2025-07-17T18:31:15.694412257Z,2025-07-17T18:31:15.694412257Z,10,2,1108,A,A,3,13.44,100,130,165557,403953403,12.37,2,1,13.2,10,1,12.23,100,1,13.3,10,1,12.22,100,1,13.43,310,2,11.97,100,1,13.44,100,1,11.92,100,1,13.46,2,1,11.9,700,1,13.47,100,1,11.85,700,1,13.99,100,1,11.82,700,1,14.01,700,1,11.79,700,1,14.05,700,1,11.76,300,3,14.08,100,1,ARL,495591105
2648,2025-07-17T18:31:15.694432003Z,2025-07-17T18:31:15.694432003Z,10,2,1108,A,A,8,14.03,100,130,165204,403953404,12.37,2,1,13.2,10,1,12.23,100,1,13.3,10,1,12.22,100,1,13.43,310,2,11.97,100,1,13.44,100,1,11.92,100,1,13.46,2,1,11.9,700,1,13.47,100,1,11.85,700,1,13.99,100,1,11.82,700,1,14.01,700,1,11.79,700,1,14.03,100,1,11.76,300,3,14.05,700,1,ARL,495591109
2649,2025-07-17T18:31:15.699826170Z,2025-07-17T18:31:15.699826170Z,10,2,1108,C,A,5,13.47,100,130,165370,403953423,12.37,2,1,13.2,10,1,12.23,100,1,13.3,10,1,12.22,100,1,13.43,310,2,11.97,100,1,13.44,100,1,11.92,100,1,13.46,2,1,11.9,700,1,13.99,100,1,11.85,700,1,14.01,700,1,11.82,700,1,14.03,100,1,11.79,700,1,14.05,700,1,11.76,300,3,14.08,100,1,ARL,494073757
2650,2025-07-17T18:31:15.699877151Z,2025-07-17T18:31:15.699877151Z,10,2,1108,A,A,5,13.7,100,130,165339,403953424,12.37,2,1,13.2,10,1,12.23,100,1,13.3,10,1,12.22,100,1,13.43,310,2,11.97,100,1,13.44,100,1,11.92,100,1,13.46,2,1,11.9,700,1,13.7,100,1,11.85,700,1,13.99,100,1,11.82,700,1,14.01,700,1,11.79,700,1,14.03,100,1,11.76,300,3,14.05,700,1,ARL,495591161
2651,2025-07-17T18:31:15.744440169Z,2025-07-17T18:31:15.744440169Z,10,2,1108,C,A,3,13.44,100,0,165456,403953592,12.37,2,1,13.2,10,1,12.23,100,1,13.3,10,1,12.22,100,1,13.43,310,2,11.97,100,1,13.46,2,1,11.92,100,1,13.7,100,1,11.9,700,1,13.99,100,1,11.85,700,1,14.01,700,1,11.82,700,1,14.03,100,1,11.79,700,1,14.05,700,1,11.76,300,3,14.08,100,1,ARL,495591105
2652,2025-07-17T18:31:15.744440169Z,2025-07-17T18:31:15.744440169Z,10,2,1108,A,A,2,13.31,100,130,165456,403953592,12.37,2,1,13.2,10,1,12.23,100,1,13.3,10,1,12.22,100,1,13.31,100,1,11.97,100,1,13.43,310,2,11.92,100,1,13.46,2,1,11.9,700,1,13.7,100,1,11.85,700,1,13.99,100,1,11.82,700,1,14.01,700,1,11.79,700,1,14.03,100,1,11.76,300,3,14.05,700,1,ARL,495591421
2653,2025-07-17T18:31:15.762005166Z,2025-07-17T18:31:15.762005166Z,10,2,1108,C,A,5,13.7,100,130,165014,403953648,12.37,2,1,13.2,10,1,12.23,100,1,13.3,10,1,12.22,100,1,13.31,100,1,11.97,100,1,13.43,310,2,11.92,100,1,13.46,2,1,11.9,700,1,13.99,100,1,11.85,700,1,14.01,700,1,11.82,700,1,14.03,100,1,11.79,700,1,14.05,700,1,11.76,300,3,14.08,100,1,ARL,495591161
2654,2025-07-17T18:31:15.762052983Z,2025-07-17T18:31:15.762052983Z,10,2,1108,A,A,5,13.58,100,130,165165,403953649,12.37,2,1,13.2,10,1,12.23,100,1,13.3,10,1,12.22,100,1,13.31,100,1,11.97,100,1,13.43,310,2,11.92,100,1,13.46,2,1,11.9,700,1,13.58,100,1,11.85,700,1,13.99,100,1,11.82,700,1,14.01,700,1,11.79,700,1,14.03,100,1,11.76,300,3,14.05,700,1,ARL,495591557
2655,2025-07-17T18:31:15.793835808Z,2025-07-17T18:31:15.793835808Z,10,2,1108,C,A,3,13.43,300,130,165051,403953841,12.37,2,1,13.2,10,1,12.23,100,1,13.3,10,1,12.22,100,1,13.31,100,1,11.97,100,1,13.43,10,1,11.92,100,1,13.46,2,1,11.9,700,1,13.58,100,1,11.85,700,1,13.99,100,1,11.82,700,1,14.01,700,1,11.79,700,1,14.03,100,1,11.76,300,3,14.05,700,1,ARL,495591097
2656,2025-07-17T18:31:38.260015387Z,2025-07-17T18:31:38.260015387Z,10,2,1108,C,A,2,13.31,100,0,165783,404322642,12.37,2,1,13.2,10,1,12.23,100,1,13.3,10,1,12.22,100,1,13.43,10,1,11.97,100,1,13.46,2,1,11.92,100,1,13.58,100,1,11.9,700,1,13.99,100,1,11.85,700,1,14.01,700,1,11.82,700,1,14.03,100,1,11.79,700,1,14.05,700,1,11.76,300,3,14.08,100,1,ARL,495591421
2657,2025-07-17T18:31:38.260015387Z,2025-07-17T18:31:38.260015387Z,10,2,1108,A,A,1,13.21,100,130,165783,404322642,12.37,2,1,13.2,10,1,12.23,100,1,13.21,100,1,12.22,100,1,13.3,10,1,11.97,100,1,13.43,10,1,11.92,100,1,13.46,2,1,11.9,700,1,13.58,100,1,11.85,700,1,13.99,100,1,11.82,700,1,14.01,700,1,11.79,700,1,14.03,100,1,11.76,300,3,14.05,700,1,ARL,496049113
2658,2025-07-17T18:31:38.260756978Z,2025-07-17T18:31:38.260756978Z,10,2,1108,C,A,8,14.03,100,130,165395,404322646,12.37,2,1,13.2,10,1,12.23,100,1,13.21,100,1,12.22,100,1,13.3,10,1,11.97,100,1,13.43,10,1,11.92,100,1,13.46,2,1,11.9,700,1,13.58,100,1,11.85,700,1,13.99,100,1,11.82,700,1,14.01,700,1,11.79,700,1,14.05,700,1,11.76,300,3,14.08,100,1,ARL,495591109
2659,2025-07-17T18:31:38.261120988Z,2025-07-17T18:31:38.261120988Z,10,2,1108,A,A,6,13.8,100,130,165347,404322651,12.37,2,1,13.2,10,1,12.23,100,1,13.21,100,1,12.22,100,1,13.3,10,1,11.97,100,1,13.43,10,1,11.92,100,1,13.46,2,1,11.9,700,1,13.58,100,1,11.85,700,1,13.8,100,1,11.82,700,1,13.99,100,1,11.79,700,1,14.01,700,1,11.76,300,3,14.05,700,1,ARL,496049157
2660,2025-07-17T18:31:38.282126121Z,2025-07-17T18:31:38.282126121Z,10,2,1108,C,A,5,13.58,100,130,165340,404323270,12.37,2,1,13.2,10,1,12.23,100,1,13.21,100,1,12.22,100,1,13.3,10,1,11.97,100,1,13.43,10,1,11.92,100,1,13.46,2,1,11.9,700,1,13.8,100,1,11.85,700,1,13.99,100,1,11.82,700,1,14.01,700,1,11.79,700,1,14.05,700,1,11.76,300,3,14.08,100,1,ARL,495591557
2661,2025-07-17T18:31:38.282176392Z,2025-07-17T18:31:38.282176392Z,10,2,1108,A,A,5,13.47,100,130,165193,404323275,12.37,2,1,13.2,10,1,12.23,100,1,13.21,100,1,12.22,100,1,13.3,10,1,11.97,100,1,13.43,10,1,11.92,100,1,13.46,2,1,11.9,700,1,13.47,100,1,11.85,700,1,13.8,100,1,11.82,700,1,13.99,100,1,11.79,700,1,14.01,700,1,11.76,300,3,14.05,700,1,ARL,496049717
2662,2025-07-17T18:33:10.293168017Z,2025-07-17T18:33:10.293168017Z,10,2,1108,C,A,4,13.46,2,0,165572,405729195,12.37,2,1,13.2,10,1,12.23,100,1,13.21,100,1,12.22,100,1,13.3,10,1,11.97,100,1,13.43,10,1,11.92,100,1,13.47,100,1,11.9,700,1,13.8,100,1,11.85,700,1,13.99,100,1,11.82,700,1,14.01,700,1,11.79,700,1,14.05,700,1,11.76,300,3,14.08,100,1,ARL,493814817
2663,2025-07-17T18:33:10.293168017Z,2025-07-17T18:33:10.293168017Z,10,2,1108,A,A,3,13.36,2,130,165572,405729195,12.37,2,1,13.2,10,1,12.23,100,1,13.21,100,1,12.22,100,1,13.3,10,1,11.97,100,1,13.36,2,1,11.92,100,1,13.43,10,1,11.9,700,1,13.47,100,1,11.85,700,1,13.8,100,1,11.82,700,1,13.99,100,1,11.79,700,1,14.01,700,1,11.76,300,3,14.05,700,1,ARL,497826957
2664,2025-07-17T18:42:38.188245549Z,2025-07-17T18:42:38.188245549Z,10,2,1108,C,A,0,13.2,10,130,166147,412912499,12.37,2,1,13.21,100,1,12.23,100,1,13.3,10,1,12.22,100,1,13.36,2,1,11.97,100,1,13.43,10,1,11.92,100,1,13.47,100,1,11.9,700,1,13.8,100,1,11.85,700,1,13.99,100,1,11.82,700,1,14.01,700,1,11.79,700,1,14.05,700,1,11.76,300,3,14.08,100,1,ARL,495283297
2665,2025-07-17T18:42:51.095805585Z,2025-07-17T18:42:51.095805585Z,10,2,1108,A,A,0,13.2,10,130,165912,413090740,12.37,2,1,13.2,10,1,12.23,100,1,13.21,100,1,12.22,100,1,13.3,10,1,11.97,100,1,13.36,2,1,11.92,100,1,13.43,10,1,11.9,700,1,13.47,100,1,11.85,700,1,13.8,100,1,11.82,700,1,13.99,100,1,11.79,700,1,14.01,700,1,11.76,300,3,14.05,700,1,ARL,507825893
2666,2025-07-17T18:47:44.409417489Z,2025-07-17T18:47:44.409417489Z,10,2,1108,C,A,1,13.21,100,130,165368,416595696,12.37,2,1,13.2,10,1,12.23,100,1,13.3,10,1,12.22,100,1,13.36,2,1,11.97,100,1,13.43,10,1,11.92,100,1,13.47,100,1,11.9,700,1,13.8,100,1,11.85,700,1,13.99,100,1,11.82,700,1,14.01,700,1,11.79,700,1,14.05,700,1,11.76,300,3,14.08,100,1,ARL,496049113
2667,2025-07-17T18:47:44.410039297Z,2025-07-17T18:47:44.410039297Z,10,2,1108,A,A,3,13.43,300,130,165387,416595714,12.37,2,1,13.2,10,1,12.23,100,1,13.3,10,1,12.22,100,1,13.36,2,1,11.97,100,1,13.43,310,2,11.92,100,1,13.47,100,1,11.9,700,1,13.8,100,1,11.85,700,1,13.99,100,1,11.82,700,1,14.01,700,1,11.79,700,1,14.05,700,1,11.76,300,3,14.08,100,1,ARL,512646381
2668,2025-07-17T18:47:44.410163484Z,2025-07-17T18:47:44.410163484Z,10,2,1108,C,A,5,13.8,100,130,165360,416595715,12.37,2,1,13.2,10,1,12.23,100,1,13.3,10,1,12.22,100,1,13.36,2,1,11.97,100,1,13.43,310,2,11.92,100,1,13.47,100,1,11.9,700,1,13.99,100,1,11.85,700,1,14.01,700,1,11.82,700,1,14.05,700,1,11.79,700,1,14.08,100,1,11.76,300,3,14.14,700,1,ARL,496049157
2669,2025-07-17T18:47:44.410487597Z,2025-07-17T18:47:44.410487597Z,10,2,1108,A,A,3,13.37,100,130,165548,416595724,12.37,2,1,13.2,10,1,12.23,100,1,13.3,10,1,12.22,100,1,13.36,2,1,11.97,100,1,13.37,100,1,11.92,100,1,13.43,310,2,11.9,700,1,13.47,100,1,11.85,700,1,13.99,100,1,11.82,700,1,14.01,700,1,11.79,700,1,14.05,700,1,11.76,300,3,14.08,100,1,ARL,512646401
2670,2025-07-17T18:47:44.410520514Z,2025-07-17T18:47:44.410520514Z,10,2,1108,A,A,8,14.03,100,130,165078,416595727,12.37,2,1,13.2,10,1,12.23,100,1,13.3,10,1,12.22,100,1,13.36,2,1,11.97,100,1,13.37,100,1,11.92,100,1,13.43,310,2,11.9,700,1,13.47,100,1,11.85,700,1,13.99,100,1,11.82,700,1,14.01,700,1,11.79,700,1,14.03,100,1,11.76,300,3,14.05,700,1,ARL,512646409
2671,2025-07-17T18:47:44.414893347Z,2025-07-17T18:47:44.414893347Z,10,2,1108,C,A,5,13.47,100,130,165477,416595818,12.37,2,1,13.2,10,1,12.23,100,1,13.3,10,1,12.22,100,1,13.36,2,1,11.97,100,1,13.37,100,1,11.92,100,1,13.43,310,2,11.9,700,1,13.99,100,1,11.85,700,1,14.01,700,1,11.82,700,1,14.03,100,1,11.79,700,1,14.05,700,1,11.76,300,3,14.08,100,1,ARL,496049717
2672,2025-07-17T18:47:44.414944605Z,2025-07-17T18:47:44.414944605Z,10,2,1108,A,A,5,13.7,100,130,165312,416595819,12.37,2,1,13.2,10,1,12.23,100,1,13.3,10,1,12.22,100,1,13.36,2,1,11.97,100,1,13.37,100,1,11.92,100,1,13.43,310,2,11.9,700,1,13.7,100,1,11.85,700,1,13.99,100,1,11.82,700,1,14.01,700,1,11.79,700,1,14.03,100,1,11.76,300,3,14.05,700,1,ARL,512646529
2673,2025-07-17T18:47:44.460561500Z,2025-07-17T18:47:44.460561500Z,10,2,1108,C,A,3,13.37,100,0,165503,416596245,12.37,2,1,13.2,10,1,12.23,100,1,13.3,10,1,12.22,100,1,13.36,2,1,11.97,100,1,13.43,310,2,11.92,100,1,13.7,100,1,11.9,700,1,13.99,100,1,11.85,700,1,14.01,700,1,11.82,700,1,14.03,100,1,11.79,700,1,14.05,700,1,11.76,300,3,14.08,100,1,ARL,512646401
2674,2025-07-17T18:47:44.460561500Z,2025-07-17T18:47:44.460561500Z,10,2,1108,A,A,2,13.31,100,130,165503,416596245,12.37,2,1,13.2,10,1,12.23,100,1,13.3,10,1,12.22,100,1,13.31,100,1,11.97,100,1,13.36,2,1,11.92,100,1,13.43,310,2,11.9,700,1,13.7,100,1,11.85,700,1,13.99,100,1,11.82,700,1,14.01,700,1,11.79,700,1,14.03,100,1,11.76,300,3,14.05,700,1,ARL,512647197
2675,2025-07-17T18:47:44.472937055Z,2025-07-17T18:47:44.472937055Z,10,2,1108,C,A,5,13.7,100,130,165185,416596348,12.37,2,1,13.2,10,1,12.23,100,1,13.3,10,1,12.22,100,1,13.31,100,1,11.97,100,1,13.36,2,1,11.92,100,1,13.43,310,2,11.9,700,1,13.99,100,1,11.85,700,1,14.01,700,1,11.82,700,1,14.03,100,1,11.79,700,1,14.05,700,1,11.76,300,3,14.08,100,1,ARL,512646529
2676,2025-07-17T18:47:44.472987065Z,2025-07-17T18:47:44.472987065Z,10,2,1108,A,A,5,13.58,100,130,165551,416596351,12.37,2,1,13.2,10,1,12.23,100,1,13.3,10,1,12.22,100,1,13.31,100,1,11.97,100,1,13.36,2,1,11.92,100,1,13.43,310,2,11.9,700,1,13.58,100,1,11.85,700,1,13.99,100,1,11.82,700,1,14.01,700,1,11.79,700,1,14.03,100,1,11.76,300,3,14.05,700,1,ARL,512647317
2677,2025-07-17T18:47:44.509953470Z,2025-07-17T18:47:44.509953470Z,10,2,1108,C,A,4,13.43,300,130,165007,416597259,12.37,2,1,13.2,10,1,12.23,100,1,13.3,10,1,12.22,100,1,13.31,100,1,11.97,100,1,13.36,2,1,11.92,100,1,13.43,10,1,11.9,700,1,13.58,100,1,11.85,700,1,13.99,100,1,11.82,700,1,14.01,700,1,11.79,700,1,14.03,100,1,11.76,300,3,14.05,700,1,ARL,512646381
2678,2025-07-17T18:47:46.003722156Z,2025-07-17T18:47:46.003722156Z,10,2,1108,C,A,0,13.2,10,130,165287,416619928,12.37,2,1,13.3,10,1,12.23,100,1,13.31,100,1,12.22,100,1,13.36,2,1,11.97,100,1,13.43,10,1,11.92,100,1,13.58,100,1,11.9,700,1,13.99,100,1,11.85,700,1,14.01,700,1,11.82,700,1,14.03,100,1,11.79,700,1,14.05,700,1,11.76,300,3,14.08,100,1,ARL,507825893
2679,2025-07-17T18:48:18.518346148Z,2025-07-17T18:48:18.518346148Z,10,2,1108,A,A,0,13.2,10,130,165430,417114155,12.37,2,1,13.2,10,1,12.23,100,1,13.3,10,1,12.22,100,1,13.31,100,1,11.97,100,1,13.36,2,1,11.92,100,1,13.43,10,1,11.9,700,1,13.58,100,1,11.85,700,1,13.99,100,1,11.82,700,1,14.01,700,1,11.79,700,1,14.03,100,1,11.76,300,3,14.05,700,1,ARL,513368973
2680,2025-07-17T18:48:22.752250033Z,2025-07-17T18:48:22.752250033Z,10,2,1108,C,A,2,13.31,100,0,167396,417170969,12.37,2,1,13.2,10,1,12.23,100,1,13.3,10,1,12.22,100,1,13.36,2,1,11.97,100,1,13.43,10,1,11.92,100,1,13.58,100,1,11.9,700,1,13.99,100,1,11.85,700,1,14.01,700,1,11.82,700,1,14.03,100,1,11.79,700,1,14.05,700,1,11.76,300,3,14.08,100,1,ARL,512647197
2681,2025-07-17T18:48:22.752250033Z,2025-07-17T18:48:22.752250033Z,10,2,1108,A,A,1,13.21,100,128,167396,417170969,12.37,2,1,13.2,10,1,12.23,100,1,13.21,100,1,12.22,100,1,13.3,10,1,11.97,100,1,13.36,2,1,11.92,100,1,13.43,10,1,11.9,700,1,13.58,100,1,11.85,700,1,13.99,100,1,11.82,700,1,14.01,700,1,11.79,700,1,14.03,100,1,11.76,300,3,14.05,700,1,ARL,513444357
2682,2025-07-17T18:48:22.752993351Z,2025-07-17T18:48:22.752993351Z,10,2,1108,C,A,8,14.03,100,130,165348,417170991,12.37,2,1,13.2,10,1,12.23,100,1,13.21,100,1,12.22,100,1,13.3,10,1,11.97,100,1,13.36,2,1,11.92,100,1,13.43,10,1,11.9,700,1,13.58,100,1,11.85,700,1,13.99,100,1,11.82,700,1,14.01,700,1,11.79,700,1,14.05,700,1,11.76,300,3,14.08,100,1,ARL,512646409
2683,2025-07-17T18:48:22.753347230Z,2025-07-17T18:48:22.753347230Z,10,2,1108,A,A,6,13.8,100,130,165384,417170996,12.37,2,1,13.2,10,1,12.23,100,1,13.21,100,1,12.22,100,1,13.3,10,1,11.97,100,1,13.36,2,1,11.92,100,1,13.43,10,1,11.9,700,1,13.58,100,1,11.85,700,1,13.8,100,1,11.82,700,1,13.99,100,1,11.79,700,1,14.01,700,1,11.76,300,3,14.05,700,1,ARL,513444445
2684,2025-07-17T18:48:22.760743413Z,2025-07-17T18:48:22.760743413Z,10,2,1108,C,A,5,13.58,100,130,165241,417171054,12.37,2,1,13.2,10,1,12.23,100,1,13.21,100,1,12.22,100,1,13.3,10,1,11.97,100,1,13.36,2,1,11.92,100,1,13.43,10,1,11.9,700,1,13.8,100,1,11.85,700,1,13.99,100,1,11.82,700,1,14.01,700,1,11.79,700,1,14.05,700,1,11.76,300,3,14.08,100,1,ARL,512647317
2685,2025-07-17T18:48:22.760792943Z,2025-07-17T18:48:22.760792943Z,10,2,1108,A,A,5,13.47,100,130,165858,417171055,12.37,2,1,13.2,10,1,12.23,100,1,13.21,100,1,12.22,100,1,13.3,10,1,11.97,100,1,13.36,2,1,11.92,100,1,13.43,10,1,11.9,700,1,13.47,100,1,11.85,700,1,13.8,100,1,11.82,700,1,13.99,100,1,11.79,700,1,14.01,700,1,11.76,300,3,14.05,700,1,ARL,513444541
2686,2025-07-17T18:48:32.006449877Z,2025-07-17T18:48:32.006449877Z,10,2,1108,C,A,0,13.2,10,128,169997,417302677,12.37,2,1,13.21,100,1,12.23,100,1,13.3,10,1,12.22,100,1,13.36,2,1,11.97,100,1,13.43,10,1,11.92,100,1,13.47,100,1,11.9,700,1,13.8,100,1,11.85,700,1,13.99,100,1,11.82,700,1,14.01,700,1,11.79,700,1,14.05,700,1,11.76,300,3,14.08,100,1,ARL,513368973
2687,2025-07-17T18:48:33.040500129Z,2025-07-17T18:48:33.040500129Z,10,2,1108,A,A,0,13.2,10,130,165455,417334278,12.37,2,1,13.2,10,1,12.23,100,1,13.21,100,1,12.22,100,1,13.3,10,1,11.97,100,1,13.36,2,1,11.92,100,1,13.43,10,1,11.9,700,1,13.47,100,1,11.85,700,1,13.8,100,1,11.82,700,1,13.99,100,1,11.79,700,1,14.01,700,1,11.76,300,3,14.05,700,1,ARL,513666941
2688,2025-07-17T18:54:52.580591801Z,2025-07-17T18:54:52.580591801Z,10,2,1108,C,A,0,13.2,10,130,167211,422382187,12.37,2,1,13.21,100,1,12.23,100,1,13.3,10,1,12.22,100,1,13.36,2,1,11.97,100,1,13.43,10,1,11.92,100,1,13.47,100,1,11.9,700,1,13.8,100,1,11.85,700,1,13.99,100,1,11.82,700,1,14.01,700,1,11.79,700,1,14.05,700,1,11.76,300,3,14.08,100,1,ARL,513666941
2689,2025-07-17T18:54:52.599100960Z,2025-07-17T18:54:52.599100960Z,10,2,1108,C,A,1,13.3,10,130,165396,422384976,12.37,2,1,13.21,100,1,12.23,100,1,13.36,2,1,12.22,100,1,13.43,10,1,11.97,100,1,13.47,100,1,11.92,100,1,13.8,100,1,11.9,700,1,13.99,100,1,11.85,700,1,14.01,700,1,11.82,700,1,14.05,700,1,11.79,700,1,14.08,100,1,11.76,300,3,14.14,700,1,ARL,493143705
2690,2025-07-17T18:55:23.117820595Z,2025-07-17T18:55:23.117820595Z,10,2,1108,A,A,0,13.2,10,130,166437,422794447,12.37,2,1,13.2,10,1,12.23,100,1,13.21,100,1,12.22,100,1,13.36,2,1,11.97,100,1,13.43,10,1,11.92,100,1,13.47,100,1,11.9,700,1,13.8,100,1,11.85,700,1,13.99,100,1,11.82,700,1,14.01,700,1,11.79,700,1,14.05,700,1,11.76,300,3,14.08,100,1,ARL,521140661
2691,2025-07-17T18:55:27.117762741Z,2025-07-17T18:55:27.117762741Z,10,2,1108,C,A,0,13.2,10,130,165059,422859047,12.37,2,1,13.21,100,1,12.23,100,1,13.36,2,1,12.22,100,1,13.43,10,1,11.97,100,1,13.47,100,1,11.92,100,1,13.8,100,1,11.9,700,1,13.99,100,1,11.85,700,1,14.01,700,1,11.82,700,1,14.05,700,1,11.79,700,1,14.08,100,1,11.76,300,3,14.14,700,1,ARL,521140661
2692,2025-07-17T18:55:33.117796133Z,2025-07-17T18:55:33.117796133Z,10,2,1108,A,A,0,13.2,10,130,165720,422923576,12.37,2,1,13.2,10,1,12.23,100,1,13.21,100,1,12.22,100,1,13.36,2,1,11.97,100,1,13.43,10,1,11.92,100,1,13.47,100,1,11.9,700,1,13.8,100,1,11.85,700,1,13.99,100,1,11.82,700,1,14.01,700,1,11.79,700,1,14.05,700,1,11.76,300,3,14.08,100,1,ARL,521320541
2693,2025-07-17T18:56:11.119572528Z,2025-07-17T18:56:11.119572528Z,10,2,1108,C,A,0,13.2,10,130,165268,423716324,12.37,2,1,13.21,100,1,12.23,100,1,13.36,2,1,12.22,100,1,13.43,10,1,11.97,100,1,13.47,100,1,11.92,100,1,13.8,100,1,11.9,700,1,13.99,100,1,11.85,700,1,14.01,700,1,11.82,700,1,14.05,700,1,11.79,700,1,14.08,100,1,11.76,300,3,14.14,700,1,ARL,521320541
2694,2025-07-17T18:56:22.613573157Z,2025-07-17T18:56:22.613573157Z,10,2,1108,A,A,0,13.2,10,128,166558,423872398,12.37,2,1,13.2,10,1,12.23,100,1,13.21,100,1,12.22,100,1,13.36,2,1,11.97,100,1,13.43,10,1,11.92,100,1,13.47,100,1,11.9,700,1,13.8,100,1,11.85,700,1,13.99,100,1,11.82,700,1,14.01,700,1,11.79,700,1,14.05,700,1,11.76,300,3,14.08,100,1,ARL,522522877
2695,2025-07-17T18:57:24.765037036Z,2025-07-17T18:57:24.765037036Z,10,2,1108,C,A,0,13.2,10,128,166145,424631076,12.37,2,1,13.21,100,1,12.23,100,1,13.36,2,1,12.22,100,1,13.43,10,1,11.97,100,1,13.47,100,1,11.92,100,1,13.8,100,1,11.9,700,1,13.99,100,1,11.85,700,1,14.01,700,1,11.82,700,1,14.05,700,1,11.79,700,1,14.08,100,1,11.76,300,3,14.14,700,1,ARL,522522877
2696,2025-07-17T18:57:26.698960413Z,2025-07-17T18:57:26.698960413Z,10,2,1108,A,A,0,13.2,10,130,165668,424654833,12.37,2,1,13.2,10,1,12.23,100,1,13.21,100,1,12.22,100,1,13.36,2,1,11.97,100,1,13.43,10,1,11.92,100,1,13.47,100,1,11.9,700,1,13.8,100,1,11.85,700,1,13.99,100,1,11.82,700,1,14.01,700,1,11.79,700,1,14.05,700,1,11.76,300,3,14.08,100,1,ARL,523629125
2697,2025-07-17T18:57:29.121156200Z,2025-07-17T18:57:29.121156200Z,10,2,1108,C,A,0,13.2,10,130,164930,424685743,12.37,2,1,13.21,100,1,12.23,100,1,13.36,2,1,12.22,100,1,13.43,10,1,11.97,100,1,13.47,100,1,11.92,100,1,13.8,100,1,11.9,700,1,13.99,100,1,11.85,700,1,14.01,700,1,11.82,700,1,14.05,700,1,11.79,700,1,14.08,100,1,11.76,300,3,14.14,700,1,ARL,523629125
2698,2025-07-17T18:57:37.122322879Z,2025-07-17T18:57:37.122322879Z,10,2,1108,A,A,0,13.2,10,130,167079,424777217,12.37,2,1,13.2,10,1,12.23,100,1,13.21,100,1,12.22,100,1,13.36,2,1,11.97,100,1,13.43,10,1,11.92,100,1,13.47,100,1,11.9,700,1,13.8,100,1,11.85,700,1,13.99,100,1,11.82,700,1,14.01,700,1,11.79,700,1,14.05,700,1,11.76,300,3,14.08,100,1,ARL,523807409
2699,2025-07-17T18:57:51.122390835Z,2025-07-17T18:57:51.122390835Z,10,2,1108,C,A,0,13.2,10,130,165518,424936427,12.37,2,1,13.21,100,1,12.23,100,1,13.36,2,1,12.22,100,1,13.43,10,1,11.97,100,1,13.47,100,1,11.92,100,1,13.8,100,1,11.9,700,1,13.99,100,1,11.85,700,1,14.01,700,1,11.82,700,1,14.05,700,1,11.79,700,1,14.08,100,1,11.76,300,3,14.14,700,1,ARL,523807409
2700,2025-07-17T18:58:19.123780547Z,2025-07-17T18:58:19.123780547Z,10,2,1108,A,A,0,13.2,10,130,166544,425305802,12.37,2,1,13.2,10,1,12.23,100,1,13.21,100,1,12.22,100,1,13.36,2,1,11.97,100,1,13.43,10,1,11.92,100,1,13.47,100,1,11.9,700,1,13.8,100,1,11.85,700,1,13.99,100,1,11.82,700,1,14.01,700,1,11.79,700,1,14.05,700,1,11.76,300,3,14.08,100,1,ARL,524562765
2701,2025-07-17T19:00:11.126903508Z,2025-07-17T19:00:11.126903508Z,10,2,1108,C,A,0,13.2,10,130,165250,426882928,12.37,2,1,13.21,100,1,12.23,100,1,13.36,2,1,12.22,100,1,13.43,10,1,11.97,100,1,13.47,100,1,11.92,100,1,13.8,100,1,11.9,700,1,13.99,100,1,11.85,700,1,14.01,700,1,11.82,700,1,14.05,700,1,11.79,700,1,14.08,100,1,11.76,300,3,14.14,700,1,ARL,524562765
2702,2025-07-17T19:00:15.127103749Z,2025-07-17T19:00:15.127103749Z,10,2,1108,A,A,0,13.2,10,130,165396,426940295,12.37,2,1,13.2,10,1,12.23,100,1,13.21,100,1,12.22,100,1,13.36,2,1,11.97,100,1,13.43,10,1,11.92,100,1,13.47,100,1,11.9,700,1,13.8,100,1,11.85,700,1,13.99,100,1,11.82,700,1,14.01,700,1,11.79,700,1,14.05,700,1,11.76,300,3,14.08,100,1,ARL,526812109
2703,2025-07-17T19:00:41.126732212Z,2025-07-17T19:00:41.126732212Z,10,2,1108,C,A,0,13.2,10,130,165307,427390755,12.37,2,1,13.21,100,1,12.23,100,1,13.36,2,1,12.22,100,1,13.43,10,1,11.97,100,1,13.47,100,1,11.92,100,1,13.8,100,1,11.9,700,1,13.99,100,1,11.85,700,1,14.01,700,1,11.82,700,1,14.05,700,1,11.79,700,1,14.08,100,1,11.76,300,3,14.14,700,1,ARL,526812109
2704,2025-07-17T19:00:45.127520095Z,2025-07-17T19:00:45.127520095Z,10,2,1108,A,A,0,13.2,15,130,165139,427449676,12.37,2,1,13.2,15,1,12.23,100,1,13.21,100,1,12.22,100,1,13.36,2,1,11.97,100,1,13.43,10,1,11.92,100,1,13.47,100,1,11.9,700,1,13.8,100,1,11.85,700,1,13.99,100,1,11.82,700,1,14.01,700,1,11.79,700,1,14.05,700,1,11.76,300,3,14.08,100,1,ARL,527449669
2705,2025-07-17T19:01:15.127644617Z,2025-07-17T19:01:15.127644617Z,10,2,1108,C,A,0,13.2,15,130,165144,427952728,12.37,2,1,13.21,100,1,12.23,100,1,13.36,2,1,12.22,100,1,13.43,10,1,11.97,100,1,13.47,100,1,11.92,100,1,13.8,100,1,11.9,700,1,13.99,100,1,11.85,700,1,14.01,700,1,11.82,700,1,14.05,700,1,11.79,700,1,14.08,100,1,11.76,300,3,14.14,700,1,ARL,527449669
2706,2025-07-17T19:01:25.128266056Z,2025-07-17T19:01:25.128266056Z,10,2,1108,A,A,0,13.2,15,130,165346,428129329,12.37,2,1,13.2,15,1,12.23,100,1,13.21,100,1,12.22,100,1,13.36,2,1,11.97,100,1,13.43,10,1,11.92,100,1,13.47,100,1,11.9,700,1,13.8,100,1,11.85,700,1,13.99,100,1,11.82,700,1,14.01,700,1,11.79,700,1,14.05,700,1,11.76,300,3,14.08,100,1,ARL,528323525
2707,2025-07-17T19:01:29.127781872Z,2025-07-17T19:01:29.127781872Z,10,2,1108,C,A,0,13.2,15,130,165681,428202369,12.37,2,1,13.21,100,1,12.23,100,1,13.36,2,1,12.22,100,1,13.43,10,1,11.97,100,1,13.47,100,1,11.92,100,1,13.8,100,1,11.9,700,1,13.99,100,1,11.85,700,1,14.01,700,1,11.82,700,1,14.05,700,1,11.79,700,1,14.08,100,1,11.76,300,3,14.14,700,1,ARL,528323525
2708,2025-07-17T19:01:41.128877897Z,2025-07-17T19:01:41.128877897Z,10,2,1108,A,A,0,13.2,15,130,166616,428387724,12.37,2,1,13.2,15,1,12.23,100,1,13.21,100,1,12.22,100,1,13.36,2,1,11.97,100,1,13.43,10,1,11.92,100,1,13.47,100,1,11.9,700,1,13.8,100,1,11.85,700,1,13.99,100,1,11.82,700,1,14.01,700,1,11.79,700,1,14.05,700,1,11.76,300,3,14.08,100,1,ARL,528659397
2709,2025-07-17T19:02:20.273220580Z,2025-07-17T19:02:20.273220580Z,10,2,1108,C,A,0,13.2,15,130,165293,428975261,12.37,2,1,13.21,100,1,12.23,100,1,13.36,2,1,12.22,100,1,13.43,10,1,11.97,100,1,13.47,100,1,11.92,100,1,13.8,100,1,11.9,700,1,13.99,100,1,11.85,700,1,14.01,700,1,11.82,700,1,14.05,700,1,11.79,700,1,14.08,100,1,11.76,300,3,14.14,700,1,ARL,528659397
2710,2025-07-17T19:02:47.131763765Z,2025-07-17T19:02:47.131763765Z,10,2,1108,A,A,0,13.2,20,130,166061,429403279,12.37,2,1,13.2,20,1,12.23,100,1,13.21,100,1,12.22,100,1,13.36,2,1,11.97,100,1,13.43,10,1,11.92,100,1,13.47,100,1,11.9,700,1,13.8,100,1,11.85,700,1,13.99,100,1,11.82,700,1,14.01,700,1,11.79,700,1,14.05,700,1,11.76,300,3,14.08,100,1,ARL,529963793
2711,2025-07-17T19:03:07.231009247Z,2025-07-17T19:03:07.231009247Z,10,2,1108,C,A,1,13.21,100,130,165389,429695185,12.37,2,1,13.2,20,1,12.23,100,1,13.36,2,1,12.22,100,1,13.43,10,1,11.97,100,1,13.47,100,1,11.92,100,1,13.8,100,1,11.9,700,1,13.99,100,1,11.85,700,1,14.01,700,1,11.82,700,1,14.05,700,1,11.79,700,1,14.08,100,1,11.76,300,3,14.14,700,1,ARL,513444357
2712,2025-07-17T19:03:07.231035191Z,2025-07-17T19:03:07.231035191Z,10,2,1108,C,A,0,13.2,20,130,165568,429695186,12.37,2,1,13.36,2,1,12.23,100,1,13.43,10,1,12.22,100,1,13.47,100,1,11.97,100,1,13.8,100,1,11.92,100,1,13.99,100,1,11.9,700,1,14.01,700,1,11.85,700,1,14.05,700,1,11.82,700,1,14.08,100,1,11.79,700,1,14.14,700,1,11.76,300,3,14.17,200,2,ARL,529963793
2713,2025-07-17T19:03:07.231749145Z,2025-07-17T19:03:07.231749145Z,10,2,1108,C,A,3,13.8,100,130,165535,429695213,12.37,2,1,13.36,2,1,12.23,100,1,13.43,10,1,12.22,100,1,13.47,100,1,11.97,100,1,13.99,100,1,11.92,100,1,14.01,700,1,11.9,700,1,14.05,700,1,11.85,700,1,14.08,100,1,11.82,700,1,14.14,700,1,11.79,700,1,14.17,200,2,11.76,300,3,14.2,700,1,ARL,513444445
2714,2025-07-17T19:03:07.232104524Z,2025-07-17T19:03:07.232104524Z,10,2,1108,A,A,5,14.03,100,130,165257,429695218,12.37,2,1,13.36,2,1,12.23,100,1,13.43,10,1,12.22,100,1,13.47,100,1,11.97,100,1,13.99,100,1,11.92,100,1,14.01,700,1,11.9,700,1,14.03,100,1,11.85,700,1,14.05,700,1,11.82,700,1,14.08,100,1,11.79,700,1,14.14,700,1,11.76,300,3,14.17,200,2,ARL,530358577
2715,2025-07-17T19:03:07.232358705Z,2025-07-17T19:03:07.232358705Z,10,2,1108,A,A,1,13.37,100,130,164959,429695223,12.37,2,1,13.36,2,1,12.23,100,1,13.37,100,1,12.22,100,1,13.43,10,1,11.97,100,1,13.47,100,1,11.92,100,1,13.99,100,1,11.9,700,1,14.01,700,1,11.85,700,1,14.03,100,1,11.82,700,1,14.05,700,1,11.79,700,1,14.08,100,1,11.76,300,3,14.14,700,1,ARL,530358593
2716,2025-07-17T19:03:07.232947082Z,2025-07-17T19:03:07.232947082Z,10,2,1108,A,A,4,13.67,4,130,165298,429695237,12.37,2,1,13.36,2,1,12.23,100,1,13.37,100,1,12.22,100,1,13.43,10,1,11.97,100,1,13.47,100,1,11.92,100,1,13.67,4,1,11.9,700,1,13.99,100,1,11.85,700,1,14.01,700,1,11.82,700,1,14.03,100,1,11.79,700,1,14.05,700,1,11.76,300,3,14.08,100,1,ARL,530358621
2717,2025-07-17T19:03:07.235178727Z,2025-07-17T19:03:07.235178727Z,10,2,1108,C,A,3,13.47,100,130,165556,429695263,12.37,2,1,13.36,2,1,12.23,100,1,13.37,100,1,12.22,100,1,13.43,10,1,11.97,100,1,13.67,4,1,11.92,100,1,13.99,100,1,11.9,700,1,14.01,700,1,11.85,700,1,14.03,100,1,11.82,700,1,14.05,700,1,11.79,700,1,14.08,100,1,11.76,300,3,14.14,700,1,ARL,513444541
2718,2025-07-17T19:03:07.235232133Z,2025-07-17T19:03:07.235232133Z,10,2,1108,A,A,4,13.7,100,130,165108,429695266,12.37,2,1,13.36,2,1,12.23,100,1,13.37,100,1,12.22,100,1,13.43,10,1,11.97,100,1,13.67,4,1,11.92,100,1,13.7,100,1,11.9,700,1,13.99,100,1,11.85,700,1,14.01,700,1,11.82,700,1,14.03,100,1,11.79,700,1,14.05,700,1,11.76,300,3,14.08,100,1,ARL,530358641
2719,2025-07-17T19:03:08.232573880Z,2025-07-17T19:03:08.232573880Z,10,2,1108,A,A,0,13.2,20,130,165403,429707298,12.37,2,1,13.2,20,1,12.23,100,1,13.36,2,1,12.22,100,1,13.37,100,1,11.97,100,1,13.43,10,1,11.92,100,1,13.67,4,1,11.9,700,1,13.7,100,1,11.85,700,1,13.99,100,1,11.82,700,1,14.01,700,1,11.79,700,1,14.03,100,1,11.76,300,3,14.05,700,1,ARL,530370329
2720,2025-07-17T19:03:23.022174752Z,2025-07-17T19:03:23.022174752Z,10,2,1108,C,A,0,13.2,20,128,168852,430007742,12.37,2,1,13.36,2,1,12.23,100,1,13.37,100,1,12.22,100,1,13.43,10,1,11.97,100,1,13.67,4,1,11.92,100,1,13.7,100,1,11.9,700,1,13.99,100,1,11.85,700,1,14.01,700,1,11.82,700,1,14.03,100,1,11.79,700,1,14.05,700,1,11.76,300,3,14.08,100,1,ARL,530370329
2721,2025-07-17T19:03:24.035491679Z,2025-07-17T19:03:24.035491679Z,10,2,1108,A,A,0,13.2,20,128,166271,430039870,12.37,2,1,13.2,20,1,12.23,100,1,13.36,2,1,12.22,100,1,13.37,100,1,11.97,100,1,13.43,10,1,11.92,100,1,13.67,4,1,11.9,700,1,13.7,100,1,11.85,700,1,13.99,100,1,11.82,700,1,14.01,700,1,11.79,700,1,14.03,100,1,11.76,300,3,14.05,700,1,ARL,530738113
2722,2025-07-17T19:03:33.073574792Z,2025-07-17T19:03:33.073574792Z,10,2,1108,C,A,0,13.2,20,130,165321,430200670,12.37,2,1,13.36,2,1,12.23,100,1,13.37,100,1,12.22,100,1,13.43,10,1,11.97,100,1,13.67,4,1,11.92,100,1,13.7,100,1,11.9,700,1,13.99,100,1,11.85,700,1,14.01,700,1,11.82,700,1,14.03,100,1,11.79,700,1,14.05,700,1,11.76,300,3,14.08,100,1,ARL,530738113
2723,2025-07-17T19:03:35.131933163Z,2025-07-17T19:03:35.131933163Z,10,2,1108,A,A,0,13.2,20,130,165171,430223490,12.37,2,1,13.2,20,1,12.23,100,1,13.36,2,1,12.22,100,1,13.37,100,1,11.97,100,1,13.43,10,1,11.92,100,1,13.67,4,1,11.9,700,1,13.7,100,1,11.85,700,1,13.99,100,1,11.82,700,1,14.01,700,1,11.79,700,1,14.03,100,1,11.76,300,3,14.05,700,1,ARL,530957373
2724,2025-07-17T19:03:50.939515051Z,2025-07-17T19:03:50.939515051Z,10,2,1108,C,A,2,13.37,100,0,165695,430428556,12.37,2,1,13.2,20,1,12.23,100,1,13.36,2,1,12.22,100,1,13.43,10,1,11.97,100,1,13.67,4,1,11.92,100,1,13.7,100,1,11.9,700,1,13.99,100,1,11.85,700,1,14.01,700,1,11.82,700,1,14.03,100,1,11.79,700,1,14.05,700,1,11.76,300,3,14.08,100,1,ARL,530358593
2725,2025-07-17T19:03:50.939515051Z,2025-07-17T19:03:50.939515051Z,10,2,1108,A,A,1,13.21,100,130,165695,430428556,12.37,2,1,13.2,20,1,12.23,100,1,13.21,100,1,12.22,100,1,13.36,2,1,11.97,100,1,13.43,10,1,11.92,100,1,13.67,4,1,11.9,700,1,13.7,100,1,11.85,700,1,13.99,100,1,11.82,700,1,14.01,700,1,11.79,700,1,14.03,100,1,11.76,300,3,14.05,700,1,ARL,531237357
2726,2025-07-17T19:03:50.940111057Z,2025-07-17T19:03:50.940111057Z,10,2,1108,C,A,4,13.67,4,130,165439,430428562,12.37,2,1,13.2,20,1,12.23,100,1,13.21,100,1,12.22,100,1,13.36,2,1,11.97,100,1,13.43,10,1,11.92,100,1,13.7,100,1,11.9,700,1,13.99,100,1,11.85,700,1,14.01,700,1,11.82,700,1,14.03,100,1,11.79,700,1,14.05,700,1,11.76,300,3,14.08,100,1,ARL,530358621
2727,2025-07-17T19:03:50.940258752Z,2025-07-17T19:03:50.940258752Z,10,2,1108,C,A,7,14.03,100,130,165620,430428565,12.37,2,1,13.2,20,1,12.23,100,1,13.21,100,1,12.22,100,1,13.36,2,1,11.97,100,1,13.43,10,1,11.92,100,1,13.7,100,1,11.9,700,1,13.99,100,1,11.85,700,1,14.01,700,1,11.82,700,1,14.05,700,1,11.79,700,1,14.08,100,1,11.76,300,3,14.14,700,1,ARL,530358577
2728,2025-07-17T19:03:50.940574838Z,2025-07-17T19:03:50.940574838Z,10,2,1108,A,A,4,13.56,4,130,165565,430428568,12.37,2,1,13.2,20,1,12.23,100,1,13.21,100,1,12.22,100,1,13.36,2,1,11.97,100,1,13.43,10,1,11.92,100,1,13.56,4,1,11.9,700,1,13.7,100,1,11.85,700,1,13.99,100,1,11.82,700,1,14.01,700,1,11.79,700,1,14.05,700,1,11.76,300,3,14.08,100,1,ARL,531237401
2729,2025-07-17T19:03:50.940630497Z,2025-07-17T19:03:50.940630497Z,10,2,1108,A,A,6,13.8,100,130,165222,430428570,12.37,2,1,13.2,20,1,12.23,100,1,13.21,100,1,12.22,100,1,13.36,2,1,11.97,100,1,13.43,10,1,11.92,100,1,13.56,4,1,11.9,700,1,13.7,100,1,11.85,700,1,13.8,100,1,11.82,700,1,13.99,100,1,11.79,700,1,14.01,700,1,11.76,300,3,14.05,700,1,ARL,531237405
2730,2025-07-17T19:03:50.958810519Z,2025-07-17T19:03:50.958810519Z,10,2,1108,C,A,5,13.7,100,130,165643,430428654,12.37,2,1,13.2,20,1,12.23,100,1,13.21,100,1,12.22,100,1,13.36,2,1,11.97,100,1,13.43,10,1,11.92,100,1,13.56,4,1,11.9,700,1,13.8,100,1,11.85,700,1,13.99,100,1,11.82,700,1,14.01,700,1,11.79,700,1,14.05,700,1,11.76,300,3,14.08,100,1,ARL,530358641
2731,2025-07-17T19:03:50.958868081Z,2025-07-17T19:03:50.958868081Z,10,2,1108,A,A,4,13.47,100,130,165497,430428655,12.37,2,1,13.2,20,1,12.23,100,1,13.21,100,1,12.22,100,1,13.36,2,1,11.97,100,1,13.43,10,1,11.92,100,1,13.47,100,1,11.9,700,1,13.56,4,1,11.85,700,1,13.8,100,1,11.82,700,1,13.99,100,1,11.79,700,1,14.01,700,1,11.76,300,3,14.05,700,1,ARL,531237541
2732,2025-07-17T19:05:00.005324582Z,2025-07-17T19:05:00.005324582Z,10,2,1108,C,A,1,13.21,100,130,165351,431494207,12.37,2,1,13.2,20,1,12.23,100,1,13.36,2,1,12.22,100,1,13.43,10,1,11.97,100,1,13.47,100,1,11.92,100,1,13.56,4,1,11.9,700,1,13.8,100,1,11.85,700,1,13.99,100,1,11.82,700,1,14.01,700,1,11.79,700,1,14.05,700,1,11.76,300,3,14.08,100,1,ARL,531237357
2733,2025-07-17T19:05:00.006114147Z,2025-07-17T19:05:00.006114147Z,10,2,1108,C,A,5,13.8,100,130,165159,431494366,12.37,2,1,13.2,20,1,12.23,100,1,13.36,2,1,12.22,100,1,13.43,10,1,11.97,100,1,13.47,100,1,11.92,100,1,13.56,4,1,11.9,700,1,13.99,100,1,11.85,700,1,14.01,700,1,11.82,700,1,14.05,700,1,11.79,700,1,14.08,100,1,11.76,300,3,14.14,700,1,ARL,531237405
2734,2025-07-17T19:05:00.006430459Z,2025-07-17T19:05:00.006430459Z,10,2,1108,A,A,2,13.37,100,130,168533,431494446,12.37,2,1,13.2,20,1,12.23,100,1,13.36,2,1,12.22,100,1,13.37,100,1,11.97,100,1,13.43,10,1,11.92,100,1,13.47,100,1,11.9,700,1,13.56,4,1,11.85,700,1,13.99,100,1,11.82,700,1,14.01,700,1,11.79,700,1,14.05,700,1,11.76,300,3,14.08,100,1,ARL,532642849
2735,2025-07-17T19:05:00.006469178Z,2025-07-17T19:05:00.006469178Z,10,2,1108,A,A,8,14.03,100,130,165880,431494467,12.37,2,1,13.2,20,1,12.23,100,1,13.36,2,1,12.22,100,1,13.37,100,1,11.97,100,1,13.43,10,1,11.92,100,1,13.47,100,1,11.9,700,1,13.56,4,1,11.85,700,1,13.99,100,1,11.82,700,1,14.01,700,1,11.79,700,1,14.03,100,1,11.76,300,3,14.05,700,1,ARL,532642873
2736,2025-07-17T19:05:00.020216145Z,2025-07-17T19:05:00.020216145Z,10,2,1108,C,A,4,13.47,100,128,166442,431496558,12.37,2,1,13.2,20,1,12.23,100,1,13.36,2,1,12.22,100,1,13.37,100,1,11.97,100,1,13.43,10,1,11.92,100,1,13.56,4,1,11.9,700,1,13.99,100,1,11.85,700,1,14.01,700,1,11.82,700,1,14.03,100,1,11.79,700,1,14.05,700,1,11.76,300,3,14.08,100,1,ARL,531237541
2737,2025-07-17T19:05:00.032957026Z,2025-07-17T19:05:00.032957026Z,10,2,1108,A,A,5,13.7,100,130,165282,431499419,12.37,2,1,13.2,20,1,12.23,100,1,13.36,2,1,12.22,100,1,13.37,100,1,11.97,100,1,13.43,10,1,11.92,100,1,13.56,4,1,11.9,700,1,13.7,100,1,11.85,700,1,13.99,100,1,11.82,700,1,14.01,700,1,11.79,700,1,14.03,100,1,11.76,300,3,14.05,700,1,ARL,532648605
2738,2025-07-17T19:06:17.158374865Z,2025-07-17T19:06:17.158374865Z,10,2,1108,C,A,0,13.2,20,128,168986,432681396,12.37,2,1,13.36,2,1,12.23,100,1,13.37,100,1,12.22,100,1,13.43,10,1,11.97,100,1,13.56,4,1,11.92,100,1,13.7,100,1,11.9,700,1,13.99,100,1,11.85,700,1,14.01,700,1,11.82,700,1,14.03,100,1,11.79,700,1,14.05,700,1,11.76,300,3,14.08,100,1,ARL,530957373
2739,2025-07-17T19:06:19.729130876Z,2025-07-17T19:06:19.729130876Z,10,2,1108,A,A,0,13.2,20,130,165551,432714266,12.37,2,1,13.2,20,1,12.23,100,1,13.36,2,1,12.22,100,1,13.37,100,1,11.97,100,1,13.43,10,1,11.92,100,1,13.56,4,1,11.9,700,1,13.7,100,1,11.85,700,1,13.99,100,1,11.82,700,1,14.01,700,1,11.79,700,1,14.03,100,1,11.76,300,3,14.05,700,1,ARL,534257581
2740,2025-07-17T19:06:21.135605827Z,2025-07-17T19:06:21.135605827Z,10,2,1108,C,A,0,13.2,20,130,165397,432732480,12.37,2,1,13.36,2,1,12.23,100,1,13.37,100,1,12.22,100,1,13.43,10,1,11.97,100,1,13.56,4,1,11.92,100,1,13.7,100,1,11.9,700,1,13.99,100,1,11.85,700,1,14.01,700,1,11.82,700,1,14.03,100,1,11.79,700,1,14.05,700,1,11.76,300,3,14.08,100,1,ARL,534257581
2741,2025-07-17T19:06:29.624126771Z,2025-07-17T19:06:29.624126771Z,10,2,1108,A,B,0,12.9,6,130,165382,432852171,12.9,6,1,13.36,2,1,12.37,2,1,13.37,100,1,12.23,100,1,13.43,10,1,12.22,100,1,13.56,4,1,11.97,100,1,13.7,100,1,11.92,100,1,13.99,100,1,11.9,700,1,14.01,700,1,11.85,700,1,14.03,100,1,11.82,700,1,14.05,700,1,11.79,700,1,14.08,100,1,ARL,534450577
2742,2025-07-17T19:06:29.624774932Z,2025-07-17T19:06:29.624774932Z,10,2,1108,C,A,2,13.43,10,130,165444,432852175,12.9,6,1,13.36,2,1,12.37,2,1,13.37,100,1,12.23,100,1,13.56,4,1,12.22,100,1,13.7,100,1,11.97,100,1,13.99,100,1,11.92,100,1,14.01,700,1,11.9,700,1,14.03,100,1,11.85,700,1,14.05,700,1,11.82,700,1,14.08,100,1,11.79,700,1,14.14,700,1,ARL,466717245
2743,2025-07-17T19:06:29.626262538Z,2025-07-17T19:06:29.626262538Z,10,2,1108,A,A,0,13.36,10,130,165523,432852181,12.9,6,1,13.36,12,2,12.37,2,1,13.37,100,1,12.23,100,1,13.56,4,1,12.22,100,1,13.7,100,1,11.97,100,1,13.99,100,1,11.92,100,1,14.01,700,1,11.9,700,1,14.03,100,1,11.85,700,1,14.05,700,1,11.82,700,1,14.08,100,1,11.79,700,1,14.14,700,1,ARL,534450593
2744,2025-07-17T19:06:43.240494223Z,2025-07-17T19:06:43.240494223Z,10,2,1108,C,B,1,12.37,2,0,165622,433017098,12.9,6,1,13.36,12,2,12.23,100,1,13.37,100,1,12.22,100,1,13.56,4,1,11.97,100,1,13.7,100,1,11.92,100,1,13.99,100,1,11.9,700,1,14.01,700,1,11.85,700,1,14.03,100,1,11.82,700,1,14.05,700,1,11.79,700,1,14.08,100,1,11.76,300,3,14.14,700,1,ARL,484764453
2745,2025-07-17T19:06:43.240494223Z,2025-07-17T19:06:43.240494223Z,10,2,1108,A,B,1,12.46,2,130,165622,433017098,12.9,6,1,13.36,12,2,12.46,2,1,13.37,100,1,12.23,100,1,13.56,4,1,12.22,100,1,13.7,100,1,11.97,100,1,13.99,100,1,11.92,100,1,14.01,700,1,11.9,700,1,14.03,100,1,11.85,700,1,14.05,700,1,11.82,700,1,14.08,100,1,11.79,700,1,14.14,700,1,ARL,534686481
2746,2025-07-17T19:06:47.629124110Z,2025-07-17T19:06:47.629124110Z,10,2,1108,C,B,0,12.9,6,130,165418,433068855,12.46,2,1,13.36,12,2,12.23,100,1,13.37,100,1,12.22,100,1,13.56,4,1,11.97,100,1,13.7,100,1,11.92,100,1,13.99,100,1,11.9,700,1,14.01,700,1,11.85,700,1,14.03,100,1,11.82,700,1,14.05,700,1,11.79,700,1,14.08,100,1,11.76,300,3,14.14,700,1,ARL,534450577
2747,2025-07-17T19:07:26.509622485Z,2025-07-17T19:07:26.509622485Z,10,2,1108,A,A,0,13.2,20,130,165369,433772332,12.46,2,1,13.2,20,1,12.23,100,1,13.36,12,2,12.22,100,1,13.37,100,1,11.97,100,1,13.56,4,1,11.92,100,1,13.7,100,1,11.9,700,1,13.99,100,1,11.85,700,1,14.01,700,1,11.82,700,1,14.03,100,1,11.79,700,1,14.05,700,1,11.76,300,3,14.08,100,1,ARL,535660121
2748,2025-07-17T19:08:12.317095966Z,2025-07-17T19:08:12.317095966Z,10,2,1108,C,A,2,13.37,100,0,165518,434334782,12.46,2,1,13.2,20,1,12.23,100,1,13.36,12,2,12.22,100,1,13.56,4,1,11.97,100,1,13.7,100,1,11.92,100,1,13.99,100,1,11.9,700,1,14.01,700,1,11.85,700,1,14.03,100,1,11.82,700,1,14.05,700,1,11.79,700,1,14.08,100,1,11.76,300,3,14.14,700,1,ARL,532642849
2749,2025-07-17T19:08:12.317095966Z,2025-07-17T19:08:12.317095966Z,10,2,1108,A,A,1,13.21,100,130,165518,434334782,12.46,2,1,13.2,20,1,12.23,100,1,13.21,100,1,12.22,100,1,13.36,12,2,11.97,100,1,13.56,4,1,11.92,100,1,13.7,100,1,11.9,700,1,13.99,100,1,11.85,700,1,14.01,700,1,11.82,700,1,14.03,100,1,11.79,700,1,14.05,700,1,11.76,300,3,14.08,100,1,ARL,536453453
2750,2025-07-17T19:08:12.317837168Z,2025-07-17T19:08:12.317837168Z,10,2,1108,C,A,7,14.03,100,130,165180,434334801,12.46,2,1,13.2,20,1,12.23,100,1,13.21,100,1,12.22,100,1,13.36,12,2,11.97,100,1,13.56,4,1,11.92,100,1,13.7,100,1,11.9,700,1,13.99,100,1,11.85,700,1,14.01,700,1,11.82,700,1,14.05,700,1,11.79,700,1,14.08,100,1,11.76,300,3,14.14,700,1,ARL,532642873
2751,2025-07-17T19:08:12.318200088Z,2025-07-17T19:08:12.318200088Z,10,2,1108,A,A,5,13.8,100,130,165598,434334812,12.46,2,1,13.2,20,1,12.23,100,1,13.21,100,1,12.22,100,1,13.36,12,2,11.97,100,1,13.56,4,1,11.92,100,1,13.7,100,1,11.9,700,1,13.8,100,1,11.85,700,1,13.99,100,1,11.82,700,1,14.01,700,1,11.79,700,1,14.05,700,1,11.76,300,3,14.08,100,1,ARL,536453493
2752,2025-07-17T19:08:12.325092441Z,2025-07-17T19:08:12.325092441Z,10,2,1108,C,A,4,13.7,100,130,165419,434334892,12.46,2,1,13.2,20,1,12.23,100,1,13.21,100,1,12.22,100,1,13.36,12,2,11.97,100,1,13.56,4,1,11.92,100,1,13.8,100,1,11.9,700,1,13.99,100,1,11.85,700,1,14.01,700,1,11.82,700,1,14.05,700,1,11.79,700,1,14.08,100,1,11.76,300,3,14.14,700,1,ARL,532648605
2753,2025-07-17T19:08:12.325143575Z,2025-07-17T19:08:12.325143575Z,10,2,1108,A,A,3,13.47,100,130,165226,434334893,12.46,2,1,13.2,20,1,12.23,100,1,13.21,100,1,12.22,100,1,13.36,12,2,11.97,100,1,13.47,100,1,11.92,100,1,13.56,4,1,11.9,700,1,13.8,100,1,11.85,700,1,13.99,100,1,11.82,700,1,14.01,700,1,11.79,700,1,14.05,700,1,11.76,300,3,14.08,100,1,ARL,536453649
2754,2025-07-17T19:08:23.131633514Z,2025-07-17T19:08:23.131633514Z,10,2,1108,C,A,0,13.2,20,130,165088,434494111,12.46,2,1,13.21,100,1,12.23,100,1,13.36,12,2,12.22,100,1,13.47,100,1,11.97,100,1,13.56,4,1,11.92,100,1,13.8,100,1,11.9,700,1,13.99,100,1,11.85,700,1,14.01,700,1,11.82,700,1,14.05,700,1,11.79,700,1,14.08,100,1,11.76,300,3,14.14,700,1,ARL,535660121
2755,2025-07-17T19:08:35.141192039Z,2025-07-17T19:08:35.141192039Z,10,2,1108,A,A,0,13.2,20,130,165439,434634064,12.46,2,1,13.2,20,1,12.23,100,1,13.21,100,1,12.22,100,1,13.36,12,2,11.97,100,1,13.47,100,1,11.92,100,1,13.56,4,1,11.9,700,1,13.8,100,1,11.85,700,1,13.99,100,1,11.82,700,1,14.01,700,1,11.79,700,1,14.05,700,1,11.76,300,3,14.08,100,1,ARL,536837401
2756,2025-07-17T19:08:36.317369559Z,2025-07-17T19:08:36.317369559Z,10,2,1108,C,A,1,13.21,100,130,165311,434643748,12.46,2,1,13.2,20,1,12.23,100,1,13.36,12,2,12.22,100,1,13.47,100,1,11.97,100,1,13.56,4,1,11.92,100,1,13.8,100,1,11.9,700,1,13.99,100,1,11.85,700,1,14.01,700,1,11.82,700,1,14.05,700,1,11.79,700,1,14.08,100,1,11.76,300,3,14.14,700,1,ARL,536453453
2757,2025-07-17T19:08:36.318114205Z,2025-07-17T19:08:36.318114205Z,10,2,1108,C,A,4,13.8,100,130,165346,434643764,12.46,2,1,13.2,20,1,12.23,100,1,13.36,12,2,12.22,100,1,13.47,100,1,11.97,100,1,13.56,4,1,11.92,100,1,13.99,100,1,11.9,700,1,14.01,700,1,11.85,700,1,14.05,700,1,11.82,700,1,14.08,100,1,11.79,700,1,14.14,700,1,11.76,300,3,14.17,200,2,ARL,536453493
2758,2025-07-17T19:08:36.318467774Z,2025-07-17T19:08:36.318467774Z,10,2,1108,A,A,6,14.03,100,130,165956,434643768,12.46,2,1,13.2,20,1,12.23,100,1,13.36,12,2,12.22,100,1,13.47,100,1,11.97,100,1,13.56,4,1,11.92,100,1,13.99,100,1,11.9,700,1,14.01,700,1,11.85,700,1,14.03,100,1,11.82,700,1,14.05,700,1,11.79,700,1,14.08,100,1,11.76,300,3,14.14,700,1,ARL,536853765
2759,2025-07-17T19:08:36.318723492Z,2025-07-17T19:08:36.318723492Z,10,2,1108,A,A,2,13.37,100,130,165316,434643769,12.46,2,1,13.2,20,1,12.23,100,1,13.36,12,2,12.22,100,1,13.37,100,1,11.97,100,1,13.47,100,1,11.92,100,1,13.56,4,1,11.9,700,1,13.99,100,1,11.85,700,1,14.01,700,1,11.82,700,1,14.03,100,1,11.79,700,1,14.05,700,1,11.76,300,3,14.08,100,1,ARL,536853773
2760,2025-07-17T19:08:36.340119702Z,2025-07-17T19:08:36.340119702Z,10,2,1108,C,A,3,13.47,100,130,165500,434644003,12.46,2,1,13.2,20,1,12.23,100,1,13.36,12,2,12.22,100,1,13.37,100,1,11.97,100,1,13.56,4,1,11.92,100,1,13.99,100,1,11.9,700,1,14.01,700,1,11.85,700,1,14.03,100,1,11.82,700,1,14.05,700,1,11.79,700,1,14.08,100,1,11.76,300,3,14.14,700,1,ARL,536453649
2761,2025-07-17T19:08:36.340171938Z,2025-07-17T19:08:36.340171938Z,10,2,1108,A,A,4,13.7,100,130,165204,434644005,12.46,2,1,13.2,20,1,12.23,100,1,13.36,12,2,12.22,100,1,13.37,100,1,11.97,100,1,13.56,4,1,11.92,100,1,13.7,100,1,11.9,700,1,13.99,100,1,11.85,700,1,14.01,700,1,11.82,700,1,14.03,100,1,11.79,700,1,14.05,700,1,11.76,300,3,14.08,100,1,ARL,536854185
2762,2025-07-17T19:09:01.965900623Z,2025-07-17T19:09:01.965900623Z,10,2,1108,C,A,0,13.2,20,128,165922,434982398,12.46,2,1,13.36,12,2,12.23,100,1,13.37,100,1,12.22,100,1,13.56,4,1,11.97,100,1,13.7,100,1,11.92,100,1,13.99,100,1,11.9,700,1,14.01,700,1,11.85,700,1,14.03,100,1,11.82,700,1,14.05,700,1,11.79,700,1,14.08,100,1,11.76,300,3,14.14,700,1,ARL,536837401
2763,2025-07-17T19:09:04.829463480Z,2025-07-17T19:09:04.829463480Z,10,2,1108,A,A,0,13.2,20,130,165450,435044415,12.46,2,1,13.2,20,1,12.23,100,1,13.36,12,2,12.22,100,1,13.37,100,1,11.97,100,1,13.56,4,1,11.92,100,1,13.7,100,1,11.9,700,1,13.99,100,1,11.85,700,1,14.01,700,1,11.82,700,1,14.03,100,1,11.79,700,1,14.05,700,1,11.76,300,3,14.08,100,1,ARL,537343337
2764,2025-07-17T19:09:05.141608027Z,2025-07-17T19:09:05.141608027Z,10,2,1108,C,A,0,13.2,20,130,166048,435059282,12.46,2,1,13.36,12,2,12.23,100,1,13.37,100,1,12.22,100,1,13.56,4,1,11.97,100,1,13.7,100,1,11.92,100,1,13.99,100,1,11.9,700,1,14.01,700,1,11.85,700,1,14.03,100,1,11.82,700,1,14.05,700,1,11.79,700,1,14.08,100,1,11.76,300,3,14.14,700,1,ARL,537343337
2765,2025-07-17T19:09:59.143319421Z,2025-07-17T19:09:59.143319421Z,10,2,1108,A,A,0,13.2,20,130,165517,435890835,12.46,2,1,13.2,20,1,12.23,100,1,13.36,12,2,12.22,100,1,13.37,100,1,11.97,100,1,13.56,4,1,11.92,100,1,13.7,100,1,11.9,700,1,13.99,100,1,11.85,700,1,14.01,700,1,11.82,700,1,14.03,100,1,11.79,700,1,14.05,700,1,11.76,300,3,14.08,100,1,ARL,538429009
2766,2025-07-17T19:11:25.144320018Z,2025-07-17T19:11:25.144320018Z,10,2,1108,C,A,0,13.2,20,130,165388,437111216,12.46,2,1,13.36,12,2,12.23,100,1,13.37,100,1,12.22,100,1,13.56,4,1,11.97,100,1,13.7,100,1,11.92,100,1,13.99,100,1,11.9,700,1,14.01,700,1,11.85,700,1,14.03,100,1,11.82,700,1,14.05,700,1,11.79,700,1,14.08,100,1,11.76,300,3,14.14,700,1,ARL,538429009
2767,2025-07-17T19:11:25.144376407Z,2025-07-17T19:11:25.144376407Z,10,2,1108,C,A,1,13.37,100,130,166101,437111221,12.46,2,1,13.36,12,2,12.23,100,1,13.56,4,1,12.22,100,1,13.7,100,1,11.97,100,1,13.99,100,1,11.92,100,1,14.01,700,1,11.9,700,1,14.03,100,1,11.85,700,1,14.05,700,1,11.82,700,1,14.08,100,1,11.79,700,1,14.14,700,1,11.76,300,3,14.17,200,2,ARL,536853773
2768,2025-07-17T19:11:25.145917704Z,2025-07-17T19:11:25.145917704Z,10,2,1108,A,A,2,13.57,100,130,166468,437111261,12.46,2,1,13.36,12,2,12.23,100,1,13.56,4,1,12.22,100,1,13.57,100,1,11.97,100,1,13.7,100,1,11.92,100,1,13.99,100,1,11.9,700,1,14.01,700,1,11.85,700,1,14.03,100,1,11.82,700,1,14.05,700,1,11.79,700,1,14.08,100,1,11.76,300,3,14.14,700,1,ARL,540040205
2769,2025-07-17T19:11:25.333066776Z,2025-07-17T19:11:25.333066776Z,10,2,1108,C,A,8,14.08,100,130,165191,437113702,12.46,2,1,13.36,12,2,12.23,100,1,13.56,4,1,12.22,100,1,13.57,100,1,11.97,100,1,13.7,100,1,11.92,100,1,13.99,100,1,11.9,700,1,14.01,700,1,11.85,700,1,14.03,100,1,11.82,700,1,14.05,700,1,11.79,700,1,14.14,700,1,11.76,300,3,14.17,200,2,ARL,493167537
2770,2025-07-17T19:11:29.146552554Z,2025-07-17T19:11:29.146552554Z,10,2,1108,A,A,0,13.26,20,130,165373,437167301,12.46,2,1,13.26,20,1,12.23,100,1,13.36,12,2,12.22,100,1,13.56,4,1,11.97,100,1,13.57,100,1,11.92,100,1,13.7,100,1,11.9,700,1,13.99,100,1,11.85,700,1,14.01,700,1,11.82,700,1,14.03,100,1,11.79,700,1,14.05,700,1,11.76,300,3,14.14,700,1,ARL,540120857
2771,2025-07-17T19:11:29.146687361Z,2025-07-17T19:11:29.146687361Z,10,2,1108,C,A,3,13.57,100,0,165735,437167310,12.46,2,1,13.26,20,1,12.23,100,1,13.36,12,2,12.22,100,1,13.56,4,1,11.97,100,1,13.7,100,1,11.92,100,1,13.99,100,1,11.9,700,1,14.01,700,1,11.85,700,1,14.03,100,1,11.82,700,1,14.05,700,1,11.79,700,1,14.14,700,1,11.76,300,3,14.17,200,2,ARL,540040205
2772,2025-07-17T19:11:29.146687361Z,2025-07-17T19:11:29.146687361Z,10,2,1108,A,A,2,13.37,100,130,165735,437167310,12.46,2,1,13.26,20,1,12.23,100,1,13.36,12,2,12.22,100,1,13.37,100,1,11.97,100,1,13.56,4,1,11.92,100,1,13.7,100,1,11.9,700,1,13.99,100,1,11.85,700,1,14.01,700,1,11.82,700,1,14.03,100,1,11.79,700,1,14.05,700,1,11.76,300,3,14.14,700,1,ARL,540120893
2773,2025-07-17T19:11:40.886053211Z,2025-07-17T19:11:40.886053211Z,10,2,1108,C,A,0,13.26,20,130,165511,437286913,12.46,2,1,13.36,12,2,12.23,100,1,13.37,100,1,12.22,100,1,13.56,4,1,11.97,100,1,13.7,100,1,11.92,100,1,13.99,100,1,11.9,700,1,14.01,700,1,11.85,700,1,14.03,100,1,11.82,700,1,14.05,700,1,11.79,700,1,14.14,700,1,11.76,300,3,14.17,200,2,ARL,540120857
2774,2025-07-17T19:11:40.886102783Z,2025-07-17T19:11:40.886102783Z,10,2,1108,C,A,1,13.37,100,130,165393,437286924,12.46,2,1,13.36,12,2,12.23,100,1,13.56,4,1,12.22,100,1,13.7,100,1,11.97,100,1,13.99,100,1,11.92,100,1,14.01,700,1,11.9,700,1,14.03,100,1,11.85,700,1,14.05,700,1,11.82,700,1,14.14,700,1,11.79,700,1,14.17,200,2,11.76,300,3,14.2,700,1,ARL,540120893
2775,2025-07-17T19:11:40.887400928Z,2025-07-17T19:11:40.887400928Z,10,2,1108,A,A,2,13.57,100,130,165392,437286956,12.46,2,1,13.36,12,2,12.23,100,1,13.56,4,1,12.22,100,1,13.57,100,1,11.97,100,1,13.7,100,1,11.92,100,1,13.99,100,1,11.9,700,1,14.01,700,1,11.85,700,1,14.03,100,1,11.82,700,1,14.05,700,1,11.79,700,1,14.14,700,1,11.76,300,3,14.17,200,2,ARL,540293801
2776,2025-07-17T19:12:12.786299693Z,2025-07-17T19:12:12.786299693Z,10,2,1108,C,A,2,13.57,100,0,165801,437719795,12.46,2,1,13.36,12,2,12.23,100,1,13.56,4,1,12.22,100,1,13.7,100,1,11.97,100,1,13.99,100,1,11.92,100,1,14.01,700,1,11.9,700,1,14.03,100,1,11.85,700,1,14.05,700,1,11.82,700,1,14.14,700,1,11.79,700,1,14.17,200,2,11.76,300,3,14.2,700,1,ARL,540293801
2777,2025-07-17T19:12:12.786299693Z,2025-07-17T19:12:12.786299693Z,10,2,1108,A,A,1,13.37,100,130,165801,437719795,12.46,2,1,13.36,12,2,12.23,100,1,13.37,100,1,12.22,100,1,13.56,4,1,11.97,100,1,13.7,100,1,11.92,100,1,13.99,100,1,11.9,700,1,14.01,700,1,11.85,700,1,14.03,100,1,11.82,700,1,14.05,700,1,11.79,700,1,14.14,700,1,11.76,300,3,14.17,200,2,ARL,540867849
2778,2025-07-17T19:12:21.147604655Z,2025-07-17T19:12:21.147604655Z,10,2,1108,A,A,0,13.35,20,130,165271,437842024,12.46,2,1,13.35,20,1,12.23,100,1,13.36,12,2,12.22,100,1,13.37,100,1,11.97,100,1,13.56,4,1,11.92,100,1,13.7,100,1,11.9,700,1,13.99,100,1,11.85,700,1,14.01,700,1,11.82,700,1,14.03,100,1,11.79,700,1,14.05,700,1,11.76,300,3,14.14,700,1,ARL,541034433
2779,2025-07-17T19:12:26.453458790Z,2025-07-17T19:12:26.453458790Z,10,2,1108,C,A,0,13.35,20,130,165559,437907389,12.46,2,1,13.36,12,2,12.23,100,1,13.37,100,1,12.22,100,1,13.56,4,1,11.97,100,1,13.7,100,1,11.92,100,1,13.99,100,1,11.9,700,1,14.01,700,1,11.85,700,1,14.03,100,1,11.82,700,1,14.05,700,1,11.79,700,1,14.14,700,1,11.76,300,3,14.17,200,2,ARL,541034433
2780,2025-07-17T19:12:27.532971742Z,2025-07-17T19:12:27.532971742Z,10,2,1108,A,A,0,13.35,20,130,165176,437920337,12.46,2,1,13.35,20,1,12.23,100,1,13.36,12,2,12.22,100,1,13.37,100,1,11.97,100,1,13.56,4,1,11.92,100,1,13.7,100,1,11.9,700,1,13.99,100,1,11.85,700,1,14.01,700,1,11.82,700,1,14.03,100,1,11.79,700,1,14.05,700,1,11.76,300,3,14.14,700,1,ARL,541140113
2781,2025-07-17T19:12:31.147108251Z,2025-07-17T19:12:31.147108251Z,10,2,1108,C,A,0,13.35,20,128,167561,437959561,12.46,2,1,13.36,12,2,12.23,100,1,13.37,100,1,12.22,100,1,13.56,4,1,11.97,100,1,13.7,100,1,11.92,100,1,13.99,100,1,11.9,700,1,14.01,700,1,11.85,700,1,14.03,100,1,11.82,700,1,14.05,700,1,11.79,700,1,14.14,700,1,11.76,300,3,14.17,200,2,ARL,541140113
2782,2025-07-17T19:12:53.148337019Z,2025-07-17T19:12:53.148337019Z,10,2,1108,A,A,0,13.35,20,130,165242,438232627,12.46,2,1,13.35,20,1,12.23,100,1,13.36,12,2,12.22,100,1,13.37,100,1,11.97,100,1,13.56,4,1,11.92,100,1,13.7,100,1,11.9,700,1,13.99,100,1,11.85,700,1,14.01,700,1,11.82,700,1,14.03,100,1,11.79,700,1,14.05,700,1,11.76,300,3,14.14,700,1,ARL,541617377
2783,2025-07-17T19:13:05.147989872Z,2025-07-17T19:13:05.147989872Z,10,2,1108,C,A,0,13.35,20,130,165509,438405929,12.46,2,1,13.36,12,2,12.23,100,1,13.37,100,1,12.22,100,1,13.56,4,1,11.97,100,1,13.7,100,1,11.92,100,1,13.99,100,1,11.9,700,1,14.01,700,1,11.85,700,1,14.03,100,1,11.82,700,1,14.05,700,1,11.79,700,1,14.14,700,1,11.76,300,3,14.17,200,2,ARL,541617377
2784,2025-07-17T19:13:22.769401356Z,2025-07-17T19:13:22.769401356Z,10,2,1108,A,A,0,13.35,20,130,165352,438689104,12.46,2,1,13.35,20,1,12.23,100,1,13.36,12,2,12.22,100,1,13.37,100,1,11.97,100,1,13.56,4,1,11.92,100,1,13.7,100,1,11.9,700,1,13.99,100,1,11.85,700,1,14.01,700,1,11.82,700,1,14.03,100,1,11.79,700,1,14.05,700,1,11.76,300,3,14.14,700,1,ARL,542223213
2785,2025-07-17T19:14:25.086477280Z,2025-07-17T19:14:25.086477280Z,10,2,1108,A,A,0,13.33,20,130,165430,439596575,12.46,2,1,13.33,20,1,12.23,100,1,13.35,20,1,12.22,100,1,13.36,12,2,11.97,100,1,13.37,100,1,11.92,100,1,13.56,4,1,11.9,700,1,13.7,100,1,11.85,700,1,13.99,100,1,11.82,700,1,14.01,700,1,11.79,700,1,14.03,100,1,11.76,300,3,14.05,700,1,ARL,543458993
2786,2025-07-17T19:14:27.899173490Z,2025-07-17T19:14:27.899173490Z,10,2,1108,C,A,3,13.37,100,0,167752,439732239,12.46,2,1,13.33,20,1,12.23,100,1,13.35,20,1,12.22,100,1,13.36,12,2,11.97,100,1,13.56,4,1,11.92,100,1,13.7,100,1,11.9,700,1,13.99,100,1,11.85,700,1,14.01,700,1,11.82,700,1,14.03,100,1,11.79,700,1,14.05,700,1,11.76,300,3,14.14,700,1,ARL,540867849
2787,2025-07-17T19:14:27.899173490Z,2025-07-17T19:14:27.899173490Z,10,2,1108,A,A,1,13.34,100,130,167752,439732239,12.46,2,1,13.33,20,1,12.23,100,1,13.34,100,1,12.22,100,1,13.35,20,1,11.97,100,1,13.36,12,2,11.92,100,1,13.56,4,1,11.9,700,1,13.7,100,1,11.85,700,1,13.99,100,1,11.82,700,1,14.01,700,1,11.79,700,1,14.03,100,1,11.76,300,3,14.05,700,1,ARL,543611309
2788,2025-07-17T19:14:27.919719845Z,2025-07-17T19:14:27.919719845Z,10,2,1108,C,A,5,13.7,100,130,165245,439735680,12.46,2,1,13.33,20,1,12.23,100,1,13.34,100,1,12.22,100,1,13.35,20,1,11.97,100,1,13.36,12,2,11.92,100,1,13.56,4,1,11.9,700,1,13.99,100,1,11.85,700,1,14.01,700,1,11.82,700,1,14.03,100,1,11.79,700,1,14.05,700,1,11.76,300,3,14.14,700,1,ARL,536854185
2789,2025-07-17T19:14:27.919785290Z,2025-07-17T19:14:27.919785290Z,10,2,1108,A,A,5,13.61,100,130,165405,439735682,12.46,2,1,13.33,20,1,12.23,100,1,13.34,100,1,12.22,100,1,13.35,20,1,11.97,100,1,13.36,12,2,11.92,100,1,13.56,4,1,11.9,700,1,13.61,100,1,11.85,700,1,13.99,100,1,11.82,700,1,14.01,700,1,11.79,700,1,14.03,100,1,11.76,300,3,14.05,700,1,ARL,543615245
2790,2025-07-17T19:14:38.697777950Z,2025-07-17T19:14:38.697777950Z,10,2,1108,C,A,1,13.34,100,130,165416,439915119,12.46,2,1,13.33,20,1,12.23,100,1,13.35,20,1,12.22,100,1,13.36,12,2,11.97,100,1,13.56,4,1,11.92,100,1,13.61,100,1,11.9,700,1,13.99,100,1,11.85,700,1,14.01,700,1,11.82,700,1,14.03,100,1,11.79,700,1,14.05,700,1,11.76,300,3,14.14,700,1,ARL,543611309
2791,2025-07-17T19:14:38.699211049Z,2025-07-17T19:14:38.699211049Z,10,2,1108,A,A,1,13.34,100,130,165397,439915126,12.46,2,1,13.33,20,1,12.23,100,1,13.34,100,1,12.22,100,1,13.35,20,1,11.97,100,1,13.36,12,2,11.92,100,1,13.56,4,1,11.9,700,1,13.61,100,1,11.85,700,1,13.99,100,1,11.82,700,1,14.01,700,1,11.79,700,1,14.03,100,1,11.76,300,3,14.05,700,1,ARL,543831665
2792,2025-07-17T19:14:38.712829740Z,2025-07-17T19:14:38.712829740Z,10,2,1108,C,A,5,13.61,100,130,165588,439915408,12.46,2,1,13.33,20,1,12.23,100,1,13.34,100,1,12.22,100,1,13.35,20,1,11.97,100,1,13.36,12,2,11.92,100,1,13.56,4,1,11.9,700,1,13.99,100,1,11.85,700,1,14.01,700,1,11.82,700,1,14.03,100,1,11.79,700,1,14.05,700,1,11.76,300,3,14.14,700,1,ARL,543615245
2793,2025-07-17T19:14:38.712884712Z,2025-07-17T19:14:38.712884712Z,10,2,1108,A,A,5,13.71,100,130,165252,439915411,12.46,2,1,13.33,20,1,12.23,100,1,13.34,100,1,12.22,100,1,13.35,20,1,11.97,100,1,13.36,12,2,11.92,100,1,13.56,4,1,11.9,700,1,13.71,100,1,11.85,700,1,13.99,100,1,11.82,700,1,14.01,700,1,11.79,700,1,14.03,100,1,11.76,300,3,14.05,700,1,ARL,543831809
2794,2025-07-17T19:14:38.713715129Z,2025-07-17T19:14:38.713715129Z,10,2,1108,C,A,5,13.71,100,130,165094,439915413,12.46,2,1,13.33,20,1,12.23,100,1,13.34,100,1,12.22,100,1,13.35,20,1,11.97,100,1,13.36,12,2,11.92,100,1,13.56,4,1,11.9,700,1,13.99,100,1,11.85,700,1,14.01,700,1,11.82,700,1,14.03,100,1,11.79,700,1,14.05,700,1,11.76,300,3,14.14,700,1,ARL,543831809
2795,2025-07-17T19:14:38.713760756Z,2025-07-17T19:14:38.713760756Z,10,2,1108,A,A,5,13.61,100,130,165242,439915414,12.46,2,1,13.33,20,1,12.23,100,1,13.34,100,1,12.22,100,1,13.35,20,1,11.97,100,1,13.36,12,2,11.92,100,1,13.56,4,1,11.9,700,1,13.61,100,1,11.85,700,1,13.99,100,1,11.82,700,1,14.01,700,1,11.79,700,1,14.03,100,1,11.76,300,3,14.05,700,1,ARL,543831813
2796,2025-07-17T19:14:49.150392448Z,2025-07-17T19:14:49.150392448Z,10,2,1108,C,A,2,13.35,20,130,165572,440024917,12.46,2,1,13.33,20,1,12.23,100,1,13.34,100,1,12.22,100,1,13.36,12,2,11.97,100,1,13.56,4,1,11.92,100,1,13.61,100,1,11.9,700,1,13.99,100,1,11.85,700,1,14.01,700,1,11.82,700,1,14.03,100,1,11.79,700,1,14.05,700,1,11.76,300,3,14.14,700,1,ARL,542223213
2797,2025-07-17T19:14:55.889985497Z,2025-07-17T19:14:55.889985497Z,10,2,1108,A,A,0,13.27,20,130,165317,440115580,12.46,2,1,13.27,20,1,12.23,100,1,13.33,20,1,12.22,100,1,13.34,100,1,11.97,100,1,13.36,12,2,11.92,100,1,13.56,4,1,11.9,700,1,13.61,100,1,11.85,700,1,13.99,100,1,11.82,700,1,14.01,700,1,11.79,700,1,14.03,100,1,11.76,300,3,14.05,700,1,ARL,544118533
2798,2025-07-17T19:15:11.079485714Z,2025-07-17T19:15:11.079485714Z,10,2,1108,C,A,2,13.34,100,0,165596,440323818,12.46,2,1,13.27,20,1,12.23,100,1,13.33,20,1,12.22,100,1,13.36,12,2,11.97,100,1,13.56,4,1,11.92,100,1,13.61,100,1,11.9,700,1,13.99,100,1,11.85,700,1,14.01,700,1,11.82,700,1,14.03,100,1,11.79,700,1,14.05,700,1,11.76,300,3,14.14,700,1,ARL,543831665
2799,2025-07-17T19:15:11.079485714Z,2025-07-17T19:15:11.079485714Z,10,2,1108,A,A,1,13.28,100,130,165596,440323818,12.46,2,1,13.27,20,1,12.23,100,1,13.28,100,1,12.22,100,1,13.33,20,1,11.97,100,1,13.36,12,2,11.92,100,1,13.56,4,1,11.9,700,1,13.61,100,1,11.85,700,1,13.99,100,1,11.82,700,1,14.01,700,1,11.79,700,1,14.03,100,1,11.76,300,3,14.05,700,1,ARL,544417113
2800,2025-07-17T19:15:11.082596540Z,2025-07-17T19:15:11.082596540Z,10,2,1108,A,A,9,14.05,100,130,165652,440323906,12.46,2,1,13.27,20,1,12.23,100,1,13.28,100,1,12.22,100,1,13.33,20,1,11.97,100,1,13.36,12,2,11.92,100,1,13.56,4,1,11.9,700,1,13.61,100,1,11.85,700,1,13.99,100,1,11.82,700,1,14.01,700,1,11.79,700,1,14.03,100,1,11.76,300,3,14.05,800,2,ARL,544417169
2801,2025-07-17T19:15:22.262048952Z,2025-07-17T19:15:22.262048952Z,10,2,1108,C,A,2,13.33,20,130,165365,440490553,12.46,2,1,13.27,20,1,12.23,100,1,13.28,100,1,12.22,100,1,13.36,12,2,11.97,100,1,13.56,4,1,11.92,100,1,13.61,100,1,11.9,700,1,13.99,100,1,11.85,700,1,14.01,700,1,11.82,700,1,14.03,100,1,11.79,700,1,14.05,800,2,11.76,300,3,14.14,700,1,ARL,543458993
2802,2025-07-17T19:15:23.267242349Z,2025-07-17T19:15:23.267242349Z,10,2,1108,A,A,0,13.25,20,130,165271,440513445,12.46,2,1,13.25,20,1,12.23,100,1,13.27,20,1,12.22,100,1,13.28,100,1,11.97,100,1,13.36,12,2,11.92,100,1,13.56,4,1,11.9,700,1,13.61,100,1,11.85,700,1,13.99,100,1,11.82,700,1,14.01,700,1,11.79,700,1,14.03,100,1,11.76,300,3,14.05,800,2,ARL,544664281
